Workbook

Sheet History of changes
E1: ESTIMATION | J1: No: BM-2-901-22
J2: Version: 1.5
J3: Issue Date: 10/03/2026
A4: SUN ASTERISK VIETNAM CO., LTD | J4: ISO/IEC 27001:2022 & ISO 9001:2015
A6: HISTORY OF CHANGES
A7: No | B7: Change Item | E7: Description of changes | J7: Change Date | L7: Version
A8: 1 | E8: Update format | J8: 44320
A9: 2 | B9: Sheet Note-Coeficient | E9: Change Working hours in a day from 8 hour to 7 hour | J9: 14/04/2023
A10: 3 | B10: Techical Suggestion | E10: Add new sheet about Technical Suggestion | J10: 28/06/2023
A11: 4 | B11: Sheet 00_Summary | E11: Update nội dung mục Assumptions | J11: 26/11/2024
A12: 5 | B12: Security Requirement | E12: Update thêm mục Security Requirement ở sheet 00_Summary Add new sheet about Security Requirement & Security Requirement (Recommendation) | J12: 45455
A13: 6 | B13: Sheet Summary | E13: Thay đổi Project Role theo thay đổi cơ cấu mới của tổ chức - PSM -> Project Leader | J13: 23/12/2024
A14: 7 | B14: Remove | E14: Remove 2 sheet: 04_Security Requirement và 04_Security Requirement (Recommendation) | J14: 45694
A15: 8 | B15: Add new | E15: Bổ sung sheet 04_Infrastructure for AWS dành cho hoạt động estimation liên quan đến AWS | J15: 21/11/2025
A16: 9 | B16: 00_Summary | E16: Bổ sung mục III. Documents List tại sheet 00_Summary | J16: 06/02/2026 | L16: v1.4
A17: 10 | B17: 00_Summary | E17: Tại sheet 00_Summary: - Đổi tên mục III. Documents List thành mục IV. Documents List - Thêm mới mục III. Deliveriable List: liệt kê danh sách các output cần bàn giao cho Khách hàng dựa trên sự thống nhất giữa Sun* và Khách hàng. | J17: 10/03/2026 | L17: v1.5
A18: 11 | B18: Add new | E18: Thêm mới sheet 05_Resource Plan: nhằm cung cấp cái nhìn tổng thể về kế hoạch phân bổ nguồn lực theo từng vai trò và theo từng giai đoạn/thời gian phát triển của dự án. | J18: 10/03/2026 | L18: v1.5

Sheet Technical Suggestion
B1: ESTIMATION | F1: No: BM-2-901-22
F2: Version: 1.5
F3: Issue Date: 10/03/2026
A4: SUN ASTERISK VIETNAM CO., LTD | F4: ISO/IEC 27001:2022 & ISO 9001:2015
A6: Reference document tại đây
A8: ■ Development strategy: | C8: MVP / POC
A9: ■ Type of service: | C9: Web
A10: ■ Programming language:
A11: ■ Framework:
A12: ■ Server or serverless: | C12: Server
A13: ■ Infrastructure diagram: | C13: Link to diagram
A14: ■ Infrastructure cost: | C14: Link to AWS/GCP... calculator
A15: ■ Use IaC (infrastructure as code) tool to build environment: | C15: Terraform
A16: ■ Web rendering method: | C16: Server Side Redering (SSR)
A17: ■ Use admin template tool: | C17: LaravelAdmin
A18: ■ Apply performance test: | C18: Yes
A19: ■ Suggest services for specific modules/functions:

Sheet 00_Summary
D1: ESTIMATION | K1: No: BM-2-901-22
K2: Version: 1.5
K3: Issue Date: 10/03/2026
A4: SUN ASTERISK VIETNAM CO., LTD | K4: ISO/IEC 27001:2022 & ISO 9001:2015
B6: I. Effort
B7: No. | C7: Role | D7: Total Effort (MM) | E7: Note
B8: 1 | C8: Backend
B9: 2 | C9: Frontend
B10: 3 | C10: Native App
B11: 4 | C11: QA
B12: 5 | C12: AI
B13: 6 | C13: Infrastructure
B14: 7 | C14: Design UI/UX
B15: 8 | C15: Specification
C16: Total
B19: II. Scope & Assumptions
B21: 1. In Scope
B22: The scope for estimate does include the following items:
B23: # | C23: Item | D23: Description | E23: Note
B24: 1
B25: 2
B27: 2. Out of Scope
B28: The estimation does not include the following items:
B29: # | C29: Item | D29: Description | E29: Note
B30: 1
B31: 2
B33: 3. Assumptions
B34: 3-1. Overall Assumptions | K34: → Japanese Translation 日本語訳（自動翻訳）
B35: # | C35: Item | E35: Applicable degree | F35: Assumptions | H35: Reason for not applicable | K35: # | L35: =IFERROR(__xludf.DUMMYFUNCTION("GOOGLETRANSLATE(C35,""en"",""ja"")"),"アイテム") -> アイテム | N35: =IFERROR(__xludf.DUMMYFUNCTION("GOOGLETRANSLATE(E35,""en"",""ja"")"),"該当する学位") -> 該当する学位 | O35: =IFERROR(__xludf.DUMMYFUNCTION("GOOGLETRANSLATE(F35,""en"",""ja"")"),"前提条件") -> 前提条件 | Q35: =IFERROR(__xludf.DUMMYFUNCTION("GOOGLETRANSLATE(H35,""en"",""ja"")"),"該当しない理由") -> 該当しない理由
B36: 1 | C36: Accuracy of this estimation | E36: Super Rough | K36: 1 | L36: 見積もりの精度 | N36: Super Rough
B37: 2 | C37: Roles and expected outputs of each role (What tasks will each role be responsible for, and what will they output?) Ref: Responsibility of each role: [JP] Onboarding for JPPM | D37: PSM | E37: TRUE | K37: 2 | L37: 各役割の役割と期待される成果 （各役割はどのようなタスクを担当し、どのような成果を出すのか？） 参考：各役割の責任：[JP] Onboarding for JPPM | M37: PSM | N37: TRUE
D38: BrSE | E38: TRUE | M38: BrSE | N38: TRUE
D39: Communicator | E39: TRUE | M39: Communicator | N39: TRUE
B40: 3 | C40: Roles and expected output from JP members (What are you expecting to get from JP side?) | E40: TRUE | K40: 3 | L40: JPメンバーの役割と期待される成果 （JP側から何を期待していますか？） | N40: TRUE
B41: 4 | C41: Schedule and expected inputs and outputs at each milestone (When and what will be output during the project period? When are dependent inputs expected to be completed/received?) Example: timeline for receiving existing database structure from customer and timeline for starting development | E41: Must have | K41: 4 | L41: 各マイルストーンにおけるスケジュールと予想される入出力 (プロジェクト期間中にいつ、どのような出力が行われるか？依存する入出力はいつ完了／受領される予定か？) 例: 顧客から既存のデータベース構造を受け取るまでのタイムラインと開発開始までのタイムライン | N41: Must have
B42: 5 | C42: Number of screens | E42: Must have | K42: 5 | L42: スクリーン数 | N42: Must have
B43: 6 | C43: Number of APIs per screen | E43: TRUE | K43: 6 | L43: 画面あたりのAPI数 | N43: TRUE
B44: 7 | C44: Interfaces | E44: TRUE | K44: 7 | L44: インターフェース | N44: TRUE
B45: 8 | C45: Forms ("Cho-hyo" in Japanese) | E45: TRUE | K45: 8 | L45: 帳簿（ちょうひょう） | N45: TRUE
B46: 9 | C46: System scale (How do you envision the number of users and infrastructure configuration? *If specified by the customer, attach a link to the customer request.) | E46: TRUE | K46: 9 | L46: システム規模 （ユーザー数とインフラ構成はどのように想定されていますか？ *お客様からご指定がある場合は、お客様リクエストへのリンクを添付してください。） | N46: TRUE
...

Sheet 01_Server
E1: ESTIMATION | K1: No: BM-2-901-22
K2: Version: 1.5
K3: Issue Date: 10/03/2026
B4: SUN ASTERISK VIETNAM CO., LTD | K4: ISO/IEC 27001:2022 & ISO 9001:2015
B6: Server
B8: Total (MM) | F8: =SUM(F13:F205)*(1+Appendix!$B$8)/Appendix!$B$13 -> 8.06 | G8: =SUM(G13:G205)*(1+Appendix!$B$8)/Appendix!$B$13 -> 2.418 | H8: =SUM(H13:H205)*(1+Appendix!$B$8)/Appendix!$B$13 -> 5.642 | I8: =SUM(I13:I205)*(1+Appendix!$B$8)/Appendix!$B$13 -> 0.585 | J8: =SUM(J13:J205)*(1+Appendix!$B$8)/Appendix!$B$13 -> 0.1755 | K8: =SUM(K13:K205)*(1+Appendix!$B$8)/Appendix!$B$13 -> 0.4095 | L8: =SUM(L13:L205)*(1+Appendix!$B$8)/Appendix!$B$13 -> 0.585
B10: No | C10: Category | D10: Screen・Feature | E10: Task | F10: Effort（Man-days） | M10: Note
F11: Backend | I11: Frontend | L11: DesignUX/UI
F12: Implement | G12: FixBug | H12: Unit Test | I12: Implement | J12: FixBug | K12: Unit Test
B13: 1 | C13: 共通 | D13: ログイン・ログアウト | F13: 2 | G13: =F13*Appendix!$B$11 -> 0.6 | H13: =F13*Appendix!$B$9 -> 1.4 | I13: 1 | J13: =I13*Appendix!$B$11 -> 0.3 | K13: =I13*Appendix!$B$9 -> 0.7 | L13: 1
B14: 2 | D14: WF再発行 メール送信 | F14: 1.5 | G14: =F14*Appendix!$B$11 -> 0.45 | H14: =F14*Appendix!$B$9 -> 1.05 | I14: 1 | J14: =I14*Appendix!$B$11 -> 0.3 | K14: =I14*Appendix!$B$9 -> 0.7 | L14: 1
B15: 3 | D15: WF再設定 | F15: 1.5 | G15: =F15*Appendix!$B$11 -> 0.45 | H15: =F15*Appendix!$B$9 -> 1.05 | I15: 1 | J15: =I15*Appendix!$B$11 -> 0.3 | K15: =I15*Appendix!$B$9 -> 0.7 | L15: 1
B16: 4 | C16: Contractor | D16: 契約者情報登録 | F16: 3 | G16: =F16*Appendix!$B$11 -> 0.9 | H16: =F16*Appendix!$B$9 -> 2.1 | I16: 1 | J16: =I16*Appendix!$B$11 -> 0.3 | K16: =I16*Appendix!$B$9 -> 0.7 | L16: 1
B17: 5 | D17: 契約情報登録 | F17: 3 | G17: =F17*Appendix!$B$11 -> 0.9 | H17: =F17*Appendix!$B$9 -> 2.1 | I17: 1 | J17: =I17*Appendix!$B$11 -> 0.3 | K17: =I17*Appendix!$B$9 -> 0.7 | L17: 1
B18: 6 | D18: 決済情報登録 | F18: 3 | G18: =F18*Appendix!$B$11 -> 0.9 | H18: =F18*Appendix!$B$9 -> 2.1 | I18: 0 | J18: =I18*Appendix!$B$11 -> 0 | K18: =I18*Appendix!$B$9 -> 0 | L18: 0
B19: 7 | D19: トップ | F19: 2 | G19: =F19*Appendix!$B$11 -> 0.6 | H19: =F19*Appendix!$B$9 -> 1.4 | I19: 0 | J19: =I19*Appendix!$B$11 -> 0 | K19: =I19*Appendix!$B$9 -> 0 | L19: 0
B20: 8 | D20: Manager一覧 | F20: 3 | G20: =F20*Appendix!$B$11 -> 0.9 | H20: =F20*Appendix!$B$9 -> 2.1 | I20: 0 | J20: =I20*Appendix!$B$11 -> 0 | K20: =I20*Appendix!$B$9 -> 0 | L20: 0
B21: 9 | D21: Manager登録・編集・削除 | F21: 3 | G21: =F21*Appendix!$B$11 -> 0.9 | H21: =F21*Appendix!$B$9 -> 2.1 | I21: 0 | J21: =I21*Appendix!$B$11 -> 0 | K21: =I21*Appendix!$B$9 -> 0 | L21: 0
B22: 10 | C22: Manager | D22: アカウント登録 | F22: 3 | G22: =F22*Appendix!$B$11 -> 0.9 | H22: =F22*Appendix!$B$9 -> 2.1 | I22: 0 | J22: =I22*Appendix!$B$11 -> 0 | K22: =I22*Appendix!$B$9 -> 0 | L22: 0
B23: 11 | D23: Manager一覧 | F23: 2 | G23: =F23*Appendix!$B$11 -> 0.6 | H23: =F23*Appendix!$B$9 -> 1.4 | I23: 0 | J23: =I23*Appendix!$B$11 -> 0 | K23: =I23*Appendix!$B$9 -> 0 | L23: 0
B24: 12 | D24: Manager登録・編集・削除 | F24: 3 | G24: =F24*Appendix!$B$11 -> 0.9 | H24: =F24*Appendix!$B$9 -> 2.1 | I24: 0 | J24: =I24*Appendix!$B$11 -> 0 | K24: =I24*Appendix!$B$9 -> 0 | L24: 0
B25: 13 | D25: グループ一覧 | F25: 2 | G25: =F25*Appendix!$B$11 -> 0.6 | H25: =F25*Appendix!$B$9 -> 1.4 | I25: 0 | J25: =I25*Appendix!$B$11 -> 0 | K25: =I25*Appendix!$B$9 -> 0 | L25: 0
B26: 14 | D26: グループ登録・編集・削除 | F26: 3 | G26: =F26*Appendix!$B$11 -> 0.9 | H26: =F26*Appendix!$B$9 -> 2.1 | I26: 0 | J26: =I26*Appendix!$B$11 -> 0 | K26: =I26*Appendix!$B$9 -> 0 | L26: 0
B27: 15 | D27: Managerカレンダー | F27: 5 | G27: =F27*Appendix!$B$11 -> 1.5 | H27: =F27*Appendix!$B$9 -> 3.5 | I27: 0 | J27: =I27*Appendix!$B$11 -> 0 | K27: =I27*Appendix!$B$9 -> 0 | L27: 0
B28: 16 | D28: トレーニング登録・編集 | F28: 3 | G28: =F28*Appendix!$B$11 -> 0.9 | H28: =F28*Appendix!$B$9 -> 2.1 | I28: 0 | J28: =I28*Appendix!$B$11 -> 0 | K28: =I28*Appendix!$B$9 -> 0 | L28: 0
B29: 17 | D29: イベント登録・編集 | F29: 3 | G29: =F29*Appendix!$B$11 -> 0.9 | H29: =F29*Appendix!$B$9 -> 2.1 | I29: 0 | J29: =I29*Appendix!$B$11 -> 0 | K29: =I29*Appendix!$B$9 -> 0 | L29: 0
B30: 18 | D30: トレーニングアイテム一覧 | F30: 2 | G30: =F30*Appendix!$B$11 -> 0.6 | H30: =F30*Appendix!$B$9 -> 1.4 | I30: 0 | J30: =I30*Appendix!$B$11 -> 0 | K30: =I30*Appendix!$B$9 -> 0 | L30: 0
B31: 19 | D31: トレーニングアイテム登録・編集・削除 | F31: 2 | G31: =F31*Appendix!$B$11 -> 0.6 | H31: =F31*Appendix!$B$9 -> 1.4 | I31: 0 | J31: =I31*Appendix!$B$11 -> 0 | K31: =I31*Appendix!$B$9 -> 0 | L31: 0
B32: 20 | D32: Athlete一覧 | F32: 2 | G32: =F32*Appendix!$B$11 -> 0.6 | H32: =F32*Appendix!$B$9 -> 1.4 | I32: 0 | J32: =I32*Appendix!$B$11 -> 0 | K32: =I32*Appendix!$B$9 -> 0 | L32: 0
B33: 21 | D33: Athlete登録・削除 | F33: 3 | G33: =F33*Appendix!$B$11 -> 0.9 | H33: =F33*Appendix!$B$9 -> 2.1 | I33: 0 | J33: =I33*Appendix!$B$11 -> 0 | K33: =I33*Appendix!$B$9 -> 0 | L33: 0
B34: 22 | D34: 各種情報推移 | F34: 7 | G34: =F34*Appendix!$B$11 -> 2.1 | H34: =F34*Appendix!$B$9 -> 4.9 | I34: 0 | J34: =I34*Appendix!$B$11 -> 0 | K34: =I34*Appendix!$B$9 -> 0 | L34: 0
... B40: 34 | D40: 退会 | F40: 1 | G40: =F40*Appendix!$B$11 -> 0.3 | H40: =F40*Appendix!$B$9 -> 0.7 | I40: 0 | J40: =I40*Appendix!$B$11 -> 0 | K40: =I40*Appendix!$B$9 -> 0 | L40: 0
B41: 23 | C41: Admin | D41: 加盟コントラクター承認 | F41: 3 | G41: =F41*Appendix!$B$11 -> 0.9 | H41: =F41*Appendix!$B$9 -> 2.1 | I41: 1 | J41: =I41*Appendix!$B$11 -> 0.3 | K41: =I41*Appendix!$B$9 -> 0.7 | L41: 1
B42: 24 | D42: 競技団体告知登録 | F42: 2 | G42: =F42*Appendix!$B$11 -> 0.6 | H42: =F42*Appendix!$B$9 -> 1.4 | I42: 1 | J42: =I42*Appendix!$B$11 -> 0.3 | K42: =I42*Appendix!$B$9 -> 0.7 | L42: 1
B43: 25 | D43: 問い合わせ対応 | F43: 6.5 | G43: =F43*Appendix!$B$11 -> 1.95 | H43: =F43*Appendix!$B$9 -> 4.55 | I43: 1 | J43: =I43*Appendix!$B$11 -> 0.3 | K43: =I43*Appendix!$B$9 -> 0.7 | L43: 1
B44: 26 | D44: ユーザー情報管理 | F44: 4.5 | G44: =F44*Appendix!$B$11 -> 1.35 | H44: =F44*Appendix!$B$9 -> 3.15 | I44: 1 | J44: =I44*Appendix!$B$11 -> 0.3 | K44: =I44*Appendix!$B$9 -> 0.7 | L44: 1
B45: 27 | D45: 契約情報管理 | F45: 4.5 | G45: =F45*Appendix!$B$11 -> 1.35 | H45: =F45*Appendix!$B$9 -> 3.15 | I45: 0 | J45: =I45*Appendix!$B$11 -> 0 | K45: =I45*Appendix!$B$9 -> 0 | L45: 0
B46: 28 | D46: 請求情報管理 | F46: 3.5 | G46: =F46*Appendix!$B$11 -> 1.05 | H46: =F46*Appendix!$B$9 -> 2.45 | I46: 0 | J46: =I46*Appendix!$B$11 -> 0 | K46: =I46*Appendix!$B$9 -> 0 | L46: 0
B47: 29 | D47: お知らせ登録 | F47: 3.5 | G47: =F47*Appendix!$B$11 -> 1.05 | H47: =F47*Appendix!$B$9 -> 2.45 | I47: 0 | J47: =I47*Appendix!$B$11 -> 0 | K47: =I47*Appendix!$B$9 -> 0 | L47: 0
B48: 30 | D48: マスタデータ登録 | F48: 3.5 | G48: =F48*Appendix!$B$11 -> 1.05 | H48: =F48*Appendix!$B$9 -> 2.45 | I48: 0 | J48: =I48*Appendix!$B$11 -> 0 | K48: =I48*Appendix!$B$9 -> 0 | L48: 0
...

Sheet 02_Native App
E1: ESTIMATION | L1: No: BM-2-901-22
L2: Version: 1.5
L3: Issue Date: 10/03/2026
B4: SUN ASTERISK VIETNAM CO., LTD | L4: ISO/IEC 27001:2022 & ISO 9001:2015
B6: Native(iOS/Android)
B8: Total (MM) | F8: =SUM(F13:F204)*(1+Appendix!$B$8)/Appendix!$B$13 -> 5.785 | G8: =SUM(G13:G204)*(1+Appendix!$B$8)/Appendix!$B$13 -> 1.7355 | H8: =SUM(H13:H204)*(1+Appendix!$B$8)/Appendix!$B$13 -> 4.0495 | I8: =SUM(I13:I204)*(1+Appendix!$B$8)/Appendix!$B$13 -> 5.85 | J8: =SUM(J13:J204)*(1+Appendix!$B$8)/Appendix!$B$13 -> 1.755 | K8: =SUM(K13:K204)*(1+Appendix!$B$8)/Appendix!$B$13 -> 4.095 | L8: =SUM(L13:L204)*(1+Appendix!$B$8)/Appendix!$B$13 -> 2.6
B10: No | C10: Category | D10: Screen・Feature | E10: Task | F10: Effort（Man-days） | M10: Note
F11: iOS | I11: Android | L11: DesignUX/UI
F12: Implement | G12: FixBug | H12: Unit Test | I12: Implement | J12: FixBug | K12: Unit Test
B13: 1 | C13: アカウント | D13: A0001 ログイン | F13: 2 | G13: =F13*Appendix!$B$11 -> 0.6 | H13: =F13*Appendix!$B$9 -> 1.4 | I13: 3 | J13: =I13*Appendix!$B$11 -> 0.9 | K13: =I13*Appendix!$B$9 -> 2.1 | L13: 1
B14: 2 | D14: A0005 アカウント新規登録 | F14: 4 | G14: =F14*Appendix!$B$11 -> 1.2 | H14: =F14*Appendix!$B$9 -> 2.8 | I14: 4 | J14: =I14*Appendix!$B$11 -> 1.2 | K14: =I14*Appendix!$B$9 -> 2.8 | L14: 2
B15: 3 | D15: A0002 PW再発行 | F15: 1 | G15: =F15*Appendix!$B$11 -> 0.3 | H15: =F15*Appendix!$B$9 -> 0.7 | I15: 1 | J15: =I15*Appendix!$B$11 -> 0.3 | K15: =I15*Appendix!$B$9 -> 0.7 | L15: 0
B16: 4 | D16: A0003 PW再設定 | F16: 1 | G16: =F16*Appendix!$B$11 -> 0.3 | H16: =F16*Appendix!$B$9 -> 0.7 | I16: 1 | J16: =I16*Appendix!$B$11 -> 0.3 | K16: =I16*Appendix!$B$9 -> 0.7 | L16: 0
B17: 5 | C17: 情報推移 | D17: A0011 各種情報推移 | F17: 14 | G17: =F17*Appendix!$B$11 -> 4.2 | H17: =F17*Appendix!$B$9 -> 9.8 | I17: 14 | J17: =I17*Appendix!$B$11 -> 4.2 | K17: =I17*Appendix!$B$9 -> 9.8 | L17: 0
B18: 6 | C18: メニュー | D18: A0009 メニュー検索 (popup) | F18: 2 | G18: =F18*Appendix!$B$11 -> 0.6 | H18: =F18*Appendix!$B$9 -> 1.4 | I18: 2 | J18: =I18*Appendix!$B$11 -> 0.6 | K18: =I18*Appendix!$B$9 -> 1.4 | L18: 5
B19: 7 | D19: A0009 メニュー登録・修正 | F19: 3 | G19: =F19*Appendix!$B$11 -> 0.9 | H19: =F19*Appendix!$B$9 -> 2.1 | I19: 3 | J19: =I19*Appendix!$B$11 -> 0.9 | K19: =I19*Appendix!$B$9 -> 2.1 | L19: 0
B20: 9 | C20: カレンダー | D20: A0012 アスリートカレンダー | F20: 9 | G20: =F20*Appendix!$B$11 -> 2.7 | H20: =F20*Appendix!$B$9 -> 6.3 | I20: 9 | J20: =I20*Appendix!$B$11 -> 2.7 | K20: =I20*Appendix!$B$9 -> 6.3 | L20: 0
B21: 10 | D21: A0007トレーニング状況登録 | F21: 4 | G21: =F21*Appendix!$B$11 -> 1.2 | H21: =F21*Appendix!$B$9 -> 2.8 | I21: 4 | J21: =I21*Appendix!$B$11 -> 1.2 | K21: =I21*Appendix!$B$9 -> 2.8 | L21: 0
B22: 11 | D22: A0010 栄養パランス | F22: 9 | G22: =F22*Appendix!$B$11 -> 2.7 | H22: =F22*Appendix!$B$9 -> 6.3 | I22: 9 | J22: =I22*Appendix!$B$11 -> 2.7 | K22: =I22*Appendix!$B$9 -> 6.3 | L22: 5
B23: 13 | D23: A0012 シーズン修正 (popup) | F23: 2 | G23: =F23*Appendix!$B$11 -> 0.6 | H23: =F23*Appendix!$B$9 -> 1.4 | I23: 2 | J23: =I23*Appendix!$B$11 -> 0.6 | K23: =I23*Appendix!$B$9 -> 1.4 | L23: 0
B24: 14 | C24: 目標 | D24: A0006 目標登録 | F24: 3 | G24: =F24*Appendix!$B$11 -> 0.9 | H24: =F24*Appendix!$B$9 -> 2.1 | I24: 3 | J24: =I24*Appendix!$B$11 -> 0.9 | K24: =I24*Appendix!$B$9 -> 2.1 | L24: 0
B25: 15 | C25: 身体状況 | D25: A0008 身体状況登録 | F25: 3 | G25: =F25*Appendix!$B$11 -> 0.9 | H25: =F25*Appendix!$B$9 -> 2.1 | I25: 3 | J25: =I25*Appendix!$B$11 -> 0.9 | K25: =I25*Appendix!$B$9 -> 2.1 | L25: 5
B26: 15 | D26: 体重計からBluetooth取り込む | F26: 5 | G26: =F26*Appendix!$B$11 -> 1.5 | H26: =F26*Appendix!$B$9 -> 3.5 | I26: 5 | J26: =I26*Appendix!$B$11 -> 1.5 | K26: =I26*Appendix!$B$9 -> 3.5 | L26: 5
B27: 16 | C27: メッセージ | D27: A0013 グループメッセージ | F27: 5 | G27: =F27*Appendix!$B$11 -> 1.5 | H27: =F27*Appendix!$B$9 -> 3.5 | I27: 5 | J27: =I27*Appendix!$B$11 -> 1.5 | K27: =I27*Appendix!$B$9 -> 3.5 | L27: 5
B28: 17 | D28: A0016 グループメッセージ詳細 | F28: 4 | G28: =F28*Appendix!$B$11 -> 1.2 | H28: =F28*Appendix!$B$9 -> 2.8 | I28: 4 | J28: =I28*Appendix!$B$11 -> 1.2 | K28: =I28*Appendix!$B$9 -> 2.8 | L28: 0
B29: 18 | C29: Myページ | D29: A0004 Myページ | F29: 5 | G29: =F29*Appendix!$B$11 -> 1.5 | H29: =F29*Appendix!$B$9 -> 3.5 | I29: 5 | J29: =I29*Appendix!$B$11 -> 1.5 | K29: =I29*Appendix!$B$9 -> 3.5 | L29: 0
B30: 19 | D30: 退会 Deactive | F30: 1 | G30: =F30*Appendix!$B$11 -> 0.3 | H30: =F30*Appendix!$B$9 -> 0.7 | I30: 1 | J30: =I30*Appendix!$B$11 -> 0.3 | K30: =I30*Appendix!$B$9 -> 0.7 | L30: 0
B31: 20 | D31: A0005 基本情報登録 | F31: 4 | G31: =F31*Appendix!$B$11 -> 1.2 | H31: =F31*Appendix!$B$9 -> 2.8 | I31: 4 | J31: =I31*Appendix!$B$11 -> 1.2 | K31: =I31*Appendix!$B$9 -> 2.8 | L31: 0
B32: 21 | D32: Create Material themes for App | F32: 4 | G32: =F32*Appendix!$B$11 -> 1.2 | H32: =F32*Appendix!$B$9 -> 2.8 | I32: 4 | J32: =I32*Appendix!$B$11 -> 1.2 | K32: =I32*Appendix!$B$9 -> 2.8 | L32: 6
B33: 22 | D33: Base Application + Setup API | F33: 4 | G33: =F33*Appendix!$B$11 -> 1.2 | H33: =F33*Appendix!$B$9 -> 2.8 | I33: 4 | J33: =I33*Appendix!$B$11 -> 1.2 | K33: =I33*Appendix!$B$9 -> 2.8 | L33: 6

Sheet 03_Infrastructure
E1: ESTIMATION | H1: No: BM-2-901-22
H2: Version: 1.5
H3: Issue Date: 10/03/2026
B4: SUN ASTERISK VIETNAM CO., LTD | H4: ISO/IEC 27001:2022 & ISO 9001:2015
B6: Infrastructure
B8: Total (MM) | F8: =SUM(F13:F188)*(1+Appendix!$B$8)/Appendix!$B$13 -> 0.78 | G8: =SUM(G13:G188)*(1+Appendix!$B$8)/Appendix!$B$13 -> 0.234
B10: No | C10: Category | D10: Feature | E10: Task | F10: Effort（Man-days） | H10: Note
F11: Infrastructure
F12: Implement | G12: FixBug
B13: 1 | C13: アカウント | D13: A0001 ログイン | F13: 2 | G13: =F13*Appendix!$B$11 -> 0.6
B14: 2 | D14: A0005 アカウント新規登録 | F14: 1 | G14: =F14*Appendix!$B$11 -> 0.3
B15: 3 | D15: A0002 PW再発行 | F15: 3 | G15: =F15*Appendix!$B$11 -> 0.9
B16: 4 | D16: A0003 PW再設定 | F16: 4 | G16: =F16*Appendix!$B$11 -> 1.2
B17: 5 | C17: 情報推移 | D17: A0011 各種情報推移 | F17: 2 | G17: =F17*Appendix!$B$11 -> 0.6

Sheet 04_Infrastructure for AWS
C1: ESTIMATION FOR AWS | I1: No: BM-2-901-22
I2: Version: 1.5
I3: Issue Date: 10/03/2026
A4: SUN ASTERISK VIETNAM CO., LTD | I4: ISO/IEC 27001:2022 & ISO 9001:2015
A5: * Dữ liệu trong bảng chỉ mang tính chất tham khảo. | E5: DEVELOPMENT | G5: STAGING | I5: PRODUCTION
B6: Total (MM) | E6: =Round(SUM(E10:E153)*(1+Appendix!$B$8)/Appendix!$B$13/Appendix!$B$14,1) -> 2.7 | F6: =Round(SUM(F10:F153)*(1+Appendix!$B$8)/Appendix!$B$13/Appendix!$B$14,1) -> 0.8 | G6: =Round(SUM(G10:G153)*(1+Appendix!$B$8)/Appendix!$B$13/Appendix!$B$14,1) -> 0.9 | H6: =Round(SUM(H10:H153)*(1+Appendix!$B$8)/Appendix!$B$13/Appendix!$B$14,1) -> 0.6 | I6: =Round(SUM(I10:I153)*(1+Appendix!$B$8)/Appendix!$B$13/Appendix!$B$14,1) -> 0.9 | J6: =Round(SUM(J10:J153)*(1+Appendix!$B$8)/Appendix!$B$13/Appendix!$B$14,1) -> 0.6 | K6: Note
A8: No | B8: Category | C8: Feature | E8: Effort（Man-hours） | G8: Effort（Man-hours） | I8: Effort（Man-hours）
E9: Implement | F9: Test/Fix | G9: Implement | H9: Test/Fix | I9: Implement | J9: Test/Fix
A10: 1 | B10: Designing Infra | C10: Infrastructure architecture | E10: 2 | F10: =ROUND(E10*0.3,0.5) -> 1 | G10: 0 | H10: 0 | I10: 0 | J10: 0 | K10: Design + est cost infra
C11: Estimate infrastructure cost and performance system | E11: 2 | F11: =ROUND(E11*0.3,0.5) -> 1 | G11: 0 | H11: 0 | I11: 0 | J11: 0
A12: 2 | B12: Config AWS account | C12: Create & Config AWS Account with AWS Organization | E12: 2 | F12: =ROUND(E12*0.3,0.5) -> 1 | G12: 0 | H12: 0 | I12: 0 | J12: 0 | K12: Centrally manage and govern your environment
A13: 3 | B13: Domain | C13: Create domain on AWS or Create hosted zones and add NS record to Japan site for management | E13: 2 | F13: =ROUND(E13*0.3,0.5) -> 1 | G13: 0 | H13: 0 | I13: 0 | J13: 0 | K13: Manage dns
A14: 4 | B14: Building AWS Environment | C14: Network | D14: - VPC | E14: 6 | F14: =E14*0.3 -> 1.8 | G14: =E14*0.3 -> 1.8 | H14: =F14*0.8 -> 1.44 | I14: =E14*0.3 -> 1.8 | J14: =F14*0.8 -> 1.44 | K14: Network for AWS
D15: - Config Subnets (Private & Public)
D16: - ACL for Private & Public
D17: - VPC Endpoint
D18: - Setting EIPs
D19: - NAT gateway, Internet Gateway & Add Routing
C20: Route 53 | D20: - Create ACM/SSL | E20: 2 | F20: =E20*0.3 -> 0.6 | G20: =E20*0.3 -> 0.6 | H20: =F20*0.8 -> 0.48 | I20: =E20*0.3 -> 0.6 | J20: =F20*0.8 -> 0.48 | K20: Manage customer's domain
D21: - Create records/sub domain
C22: IAM User | D22: - IAM-User | E22: 4 | F22: =E22*0.3 -> 1.2 | G22: =E22*0.3 -> 1.2 | H22: =F22*0.8 -> 0.96 | I22: =E22*0.3 -> 1.2 | J22: =F22*0.8 -> 0.96 | K22: Grant permission for user to access AWS console
D23: - IAM-Group (Readonly, Admin, Power, Development)
D24: - IAM-Policy for User & Group
C25: RDS Aurora | D25: - Create Security Group, Subnet group, Parameter group | E25: 3 | F25: =E25*0.3 -> 0.9 | G25: =E25*0.3 -> 0.9 | H25: =F25*0.8 -> 0.72 | I25: =E25*0.3 -> 0.9 | J25: =F25*0.8 -> 0.72 | K25: Database SQL
D26: - Create RDS Cluster
D27: - Create RDS Cluster Instance
D28: - Setting schedule backup database
C29: RDS | D29: - Create Security Group, Subnet group, Parameter group | E29: 3 | F29: =E29*0.3 -> 0.9 | G29: =E29*0.3 -> 0.9 | H29: =F29*0.8 -> 0.72 | I29: =E29*0.3 -> 0.9 | J29: =F29*0.8 -> 0.72 | K29: Database SQL
D30: - Create RDS Instance
D31: - Setting schedule backup database
C32: Dynamodb | D32: - Create table | E32: 3 | F32: =E32*0.3 -> 0.9 | G32: =E32*0.3 -> 0.9 | H32: =F32*0.8 -> 0.72 | I32: =E32*0.3 -> 0.9 | J32: =F32*0.8 -> 0.72 | K32: Database NoSQL
D33: - Create IAM role
C34: Elasticache | D34: - Create Security Group, Subnet group, Parameter group | E34: 3 | F34: =E34*0.3 -> 0.9 | G34: =E34*0.3 -> 0.9 | H34: =F34*0.8 -> 0.72 | I34: =E34*0.3 -> 0.9 | J34: =F34*0.8 -> 0.72 | K34: Redis
D35: - Create Cluster
D36: - Setting schedule backup redis
C37: Cognito | D37: - Create user pool | E37: 4 | F37: =E37*0.3 -> 1.2 | G37: =E37*0.3 -> 1.2 | H37: =F37*0.8 -> 0.96 | I37: =E37*0.3 -> 1.2 | J37: =F37*0.8 -> 0.96 | K37: Authentication - SSO
D38: - Sign in through external federated identity providers
C39: S3 for application | D39: - Create bucket and setting S3 policy | E39: 1 | F39: =E39*0.3 -> 0.3 | G39: =E39*0.3 -> 0.3 | H39: =F39*0.8 -> 0.24 | I39: =E39*0.3 -> 0.3 | J39: =F39*0.8 -> 0.24 | K39: Store static files of Application
D40: - S3 setting event
C41: S3 for log storage | D41: - Create bucket and setting S3 policy | E41: 1 | F41: =E41*0.3 -> 0.3 | G41: =E41*0.3 -> 0.3 | H41: =F41*0.8 -> 0.24 | I41: =E41*0.3 -> 0.3 | J41: =F41*0.8 -> 0.24 | K41: Store logs of ALB, CloudFront, and CloudTrail
...

Sheet 05_Resource plan
D1: ESTIMATION | S1: No: BM-2-901-22
S2: Version: 1.5
S3: Issue Date: 10/03/2026
A4: SUN ASTERISK VIETNAM CO., LTD | S4: ISO/IEC 27001:2013&ISO 9001:2015
B6: * Unit: Man-month
B7: Role | C7: Requirement Definition | F7: Basic Design | I7: Detail Design/Coding/Unit Test | Q7: Intergration Testing/System Test | U7: UAT | W7: Total
C8: 46023 | D8: 46054 | E8: 46082 | F8: 46113 | G8: 46143 | H8: 46174 | I8: 46204 | J8: 46235 | K8: 46266 | L8: 46296 | M8: 46327 | N8: 46357 | O8: 46388 | P8: 46419 | Q8: 46447 | R8: 46478 | S8: 46508 | T8: 46539 | U8: 46569 | V8: 46600
B9: 【SJP】Designer | W9: =sum(C9:V9) -> 0
B10: 【SVN】PL | W10: =sum(C10:V10) -> 0
B11: 【SVN】BrSE | W11: =sum(C11:V11) -> 0
B12: 【SVN】Backend Lead | W12: =sum(C12:V12) -> 0
B13: 【SVN】Backend | W13: =sum(C13:V13) -> 0
B14: 【SVN】Frontend Lead | W14: =sum(C14:V14) -> 0
B15: 【SVN】Frontend | W15: =sum(C15:V15) -> 0
B16: 【SVN】Native-app Lead | W16: =sum(C16:V16) -> 0
B17: 【SVN】Native-app | W17: =sum(C17:V17) -> 0
B18: 【SVN】QA Lead | W18: =sum(C18:V18) -> 0
B19: 【SVN】QA | W19: =sum(C19:V19) -> 0
B20: 【SVN】Infrastructure | W20: =sum(C20:V20) -> 0
... B22: 【SVN】Designer | W22: =sum(C22:V22) -> 0
B23: Total | C23: =SUM(C10:C22) -> 0 | D23: =SUM(D10:D22) -> 0 | E23: =SUM(E10:E22) -> 0 | F23: =SUM(F10:F22) -> 0 | G23: =SUM(G10:G22) -> 0 | H23: =SUM(H10:H22) -> 0 | I23: =SUM(I10:I22) -> 0 | J23: =SUM(J10:J22) -> 0 | ... W23: =SUM(W10:W22) -> 0
B24: Total phase | C24: =SUM(C23:E23) -> 0 | F24: =SUM(F23:H23) -> 0 | I24: =SUM(I23:P23) -> 0 | Q24: =SUM(Q23:T23) -> 0 | U24: =SUM(U23:V23) -> 0

Sheet Appendix
C1: ESTIMATION | E1: No: BM-2-901-22
E2: Version: 1.5
E3: Issue Date: 10/03/2026
A4: SUN ASTERISK VIETNAM CO., LTD | E4: ISO/IEC 27001:2022 & ISO 9001:2015
A7: Value | B7: Coefficient | C7: Note
A8: Buffer | B8: 0.3 | C8: 0.3
A9: Unit Test | B9: 0.7 | C9: Coefficient*Implement effort
A10: Unit Test (for AWS) | B10: 0.5 | C10: Coefficient*Implement effort
A11: Fixbug | B11: 0.3 | C11: Coefficient*Implement effort
A12: Management | B12: 0.2 | C12: Coefficient*Implement effort
A13: Working days in a month | B13: 20
A14: Working hours in a day | B14: 7
A15: * Have to estimate base on qualification of rank 3.5 developer
A16: * FrontEnd implement effort includes effort to integrate with backend and markup...etc...
A18: Development Strategy | B18: Type of service | C18: Web Rendering Method | E18: Admin template | F18: Server/Serverless | G18: IaC tool
A19: MVP / POC | B19: Web | C19: Server Side Redering (SSR) | E19: AdminLTE | F19: Server | G19: Terraform
A20: Full feature / MMP | B20: Mobile app | C20: Client Side Rendering (CSR) | E20: FilamentPHP | F20: Serverless | G20: CloudFormation
B21: PWA (Progressive Web App) | C21: Pre-Rendering: Server Side Rendering (Universal SSR) | E21: LaravelAdmin | G21: Bicep
C22: Pre-Rendering: Static Site Generation (SSG) | G22: Ansible
C23: Dynamic Rendering | G23: Chef
G24: Puppet
G25: CDK

Sheet Project Organization Structure 
L1: ESTIMATION | AJ1: No: BM-2-901-22
AJ2: Version: 1.5
AJ3: Issue Date: 10/03/2026
B4: SUN ASTERISK VIETNAM CO., LTD | AJ4: ISO/IEC 27001:2022 & ISO 9001:2015
