Workbook

Sheet History of changes
E1: WBS ESTIMATION | J1: No: BM-QT-1701-02
J2: Version: 1.3
J3: Issue Date: 22/09/2026
A4: SUN ASTERISK VIETNAM CO., LTD | J4: ISO/IEC 27001:2022 & ISO 9001:2015
A6: HISTORY OF CHANGES
A7: No | B7: Change Item | E7: Description of changes | J7: Change Date
A8: 1 | E8: Update format | J8: 44320
A9: 2 | E9: - Add sheet: + Guideline + Criteria for project complexity level selection + Appendix + Common function - Update sheet: + WBS Estimation_Test Cases Break | J9: 45967
A10: 3 | B10: All sheet | E10: Update mã biểu mẫu theo tiêu chuẩn ISO. | J10: 22/09/2026

Sheet Guideline
C1: WBS ESTIMATION | G1: No: BM-QT-1701-02
G2: Version: 1.3
G3: Issue Date: 22/09/2026
A4: SUN ASTERISK VIETNAM CO., LTD | G4: ISO/IEC 27001:2022 & ISO 9001:2015
A7: I. WBS_Overview
B8: Thể hiện tổng effort cần có cho dự án
B9: Cần điền đầy đủ các thông số về scope test, browser/ thiết bị test để làm căn cứ tiền đề estimate
A11: II. WBS Estimation_Test Cases Break
B12: - Đảm bảo Function list ở file này và của dự án phải giống nhau
B13: - Cột G_Link with common function: Lựa chọn function common có sẵn nếu function của hệ thống mapping được với function common đã có, các data về time create/ review/ execute sẽ auto fill (người est có thể sử dụng hoàn toàn hoặc chỉnh sửa tùy theo spec của hệ thống) + Có thể tham khảo testcase common đã viết, tùy theo độ phức tạp/ số component của function mà thay đổi hệ số tương ứng để ra effort cuối cùng + Nếu không mapping được với function đã có thì điền trực tiếp time estimate vào cột I, J, K
B14: - Cột H_Coefficient: Hệ số được tính cho toàn bộ dự án ở sheet Appendix Tùy theo mức độ phức tạp về function mà QA có thể thay đổi hệ số tương ứng hoặc sử dụng default hệ số được tính Tổng effort của 1 function = (thời gian create + review + execute TCs+ verify bug + final) * hệ số Coefficient
B15: - Thay đổi add/edit/delete column cho phù hợp với dự án
B16: NOTE: Thay đổi việc tính effort 1 function từ dựa vào số testcase bằng việc quy ra giờ cụ thể
A18: III. Criteria for project complexity level selection
B19: - Liệt kê các tiêu chí đánh giá complexity:
B20: + Đánh giá complexity về Quality Requiremen
B21: + Đánh giá complexity về Project
B22: - Từ complexity của 2 mục trên sẽ đánh giá Coefficient của dự án chi tiết ở sheet Appendix
B23: - Gợi ý 1 số lựa chọn về scope test phù hợp với dự án ở mục 3
A25: IV. Appendix
B26: Phụ lục bao gồm: - Lựa chọn coefficient cho dự án dựa trên các tiêu chí được mô tả ở sheet Criteria for project complexity level selection
B27: - Các tham số khác: Buffer, TVP, Review, Management, Working days in a month, Working hours in a day, Bug rate
B28: + Lưu ý: theo norm chung của công ty: ++ Bug rate = 5% ~ 7% test cases ++ Bug verification : 0.5 hour / 1 bug => Quy đổi tỉ lệ effort so với effort Execute Test case = 25% ~ 35%
A29: V. Common function
B30: Danh sách các function common hay gặp và thời gian create/ review/ execute TCs của function đó
B31: Có link refer testcase common đã viết để tham khảo

Sheet WBS_Overview
C1: WBS ESTIMATION | G1: No: BM-QT-1701-02
G2: Version: 1.3
G3: Issue Date: 22/09/2026
A4: SUN ASTERISK VIETNAM CO., LTD | G4: ISO/IEC 27001:2022 & ISO 9001:2015
A7: I. Estimation Effort
B8: Total Estimated Effort (hours) | D8: Total Estimated Effort (Man-day) | F8: Total Estimated Effort (Man-month)
B9: ='WBS Estimation_Test Cases Break'!J7 -> 29.1875 | D9: ='WBS Estimation_Test Cases Break'!K7 -> 4.17 | F9: ='WBS Estimation_Test Cases Break'!L7 -> 0.21
A12: II. Scope of Work
B13: 1. In Scope
B14: The scope for estimate does include the following items:
B15: # | C15: Item | E15: Description | G15: Note
B16: 1
B17: 2
B18: 3
B19: 4
B21: Test ‘Compatibility’ matrix
B22: # | C22: Type | D22: Item 1 | E22: Item 2 | F22: Item 3 | G22: Note
B23: 1 | C23: OS | D23: - | E23: - | F23: -
B24: 2 | C24: Browser | D24: - | E24: - | F24: -
B25: 3 | C25: Device | D25: - | E25: - | F25: -
B26: 4 | C26: Network | D26: - | E26: - | F26: -
B28: 2. Out of Scope
B29: The estimation does not include the following items:
B30: # | C30: Item | E30: Description | G30: Note
B31: 1
B32: 2
B33: 3
B34: 4
A37: III. Deliverable
B38: # | C38: Item | E38: Yes/No | G38: Note
B39: 1 | C39: Test Strategy | E39: N
B40: 2 | C40: Test Plan | E40: Y
B41: 3 | C41: Test Cases/Scripts | E41: Y
B42: 4 | C42: Test Data/Test Evidence | E42: N
B43: 5 | C43: Defect Report/Bug Report | E43: Y
B44: 6 | C44: Test Execution Report | E44: Y
B45: 7 | C45: Installation/configuration guide | E45: -
B46: 8 | C46: User guide | E46: -
B47: 9 | C47: Test status report | E47: -
A50: IV. Other
...

Sheet WBS Estimation_Test Cases Break
D1: WBS ESTIMATION | N1: No: BM-QT-1701-02
N2: Version: 1.3
N3: Issue Date: 22/09/2026
A4: SUN ASTERISK VIETNAM CO., LTD | N4: ISO/IEC 27001:2022 & ISO 9001:2015
A6: Project name | J6: Total Effort (Hours) | K6: Total Effort (Man-day) | L6: Total Effort (Man-month)
A7: Estimated by | E7: Date | F7: dd/mm/yyyy | I7: Total | J7: =N10 -> 29.1875 | K7: =round(J7/Appendix!B22,2) -> 4.17 | L7: =round(K7/20,2) -> 0.21
A8: Review by | E8: Date | F8: dd/mm/yyyy
A10: TOTAL (MH) | I10: =SUM(I12:I1022) -> 11.5 | J10: =SUM(J12:J1022) -> 0 | K10: =SUM(K12:K1022) -> 13 | L10: =SUM(L12:L1022) -> 1.95 | M10: =SUM(M12:M1022) -> 1.3 | N10: =SUM(N12:N1022) -> 29.1875
A11: # | B11: Feature | C11: Screen name | D11: Functions | E11: Sub Functions | F11: Detail | G11: Link with common function | H11: Coefficient | I11: Effort Create (Hour) | J11: Effort Review (Hour) | K11: Effort Execute (Hour) | L11: Effort Bug Verification (Hour) | M11: Effort final inspection before release (Hour) | N11: Total Effort (Hours) | O11: Note *List out the assumptions while estimating
A12: =row()-11 -> 1 | B12: System test/Final inspection test | I12: {=If($G12="","",INDEX('Common function'!$F$8:$F56, match($G12,'Common function'!$C$8:$C56,0)))} | J12: {=If($G12="","",INDEX('Common function'!$G$8:$G56, match($G12,'Common function'!$C$8:$C56,0)))} | K12: {=If($G12="","",INDEX('Common function'!$H$8:$H56, match($G12,'Common function'!$C$8:$C56,0)))} | L12: =If($K12="","",$K12*Appendix!$B$23) | M12: =If($K12="","",K12*0.1) | N12: =$H12*sum($I12:$M12) -> 0
A13: =row()-11 -> 2 | B13: Responsive (If any) | I13: {=If($G13="","",INDEX('Common function'!$F$8:$F56, match($G13,'Common function'!$C$8:$C56,0)))} | J13: {=If($G13="","",INDEX('Common function'!$G$8:$G56, match($G13,'Common function'!$C$8:$C56,0)))} | K13: {=If($G13="","",INDEX('Common function'!$H$8:$H56, match($G13,'Common function'!$C$8:$C56,0)))} | L13: =If($K13="","",$K13*Appendix!$B$23) | M13: =If($K13="","",K13*0.1) | N13: =$H13*sum($I13:$M13) -> 0
A14: =row()-11 -> 3 | B14: Multi language (If any) | I14: {=If($G14="","",INDEX('Common function'!$F$8:$F56, match($G14,'Common function'!$C$8:$C56,0)))} | J14: {=If($G14="","",INDEX('Common function'!$G$8:$G56, match($G14,'Common function'!$C$8:$C56,0)))} | K14: {=If($G14="","",INDEX('Common function'!$H$8:$H56, match($G14,'Common function'!$C$8:$C56,0)))} | L14: =If($K14="","",$K14*Appendix!$B$23) | M14: =If($K14="","",K14*0.1) | N14: =$H14*sum($I14:$M14) -> 0
A15: =row()-11 -> 4 | B15: Admin | C15: Screen 1 | D15: Task 1 | E15: Task 1 | G15: Login | H15: =Appendix!$B$13 -> 1 | I15: {=If($G15="","",INDEX('Common function'!$F$8:$F56, match($G15,'Common function'!$C$8:$C56,0)))} -> 2 | J15: {=If($G15="","",INDEX('Common function'!$G$8:$G56, match($G15,'Common function'!$C$8:$C56,0)))} -> 0 | K15: {=If($G15="","",INDEX('Common function'!$H$8:$H56, match($G15,'Common function'!$C$8:$C56,0)))} -> 2.5 | L15: =If($K15="","",$K15*Appendix!$B$23) -> 0.375 | M15: =If($K15="","",K15*0.1) -> 0.25 | N15: =$H15*sum($I15:$M15) -> 5.125
A16: =row()-11 -> 5 | C16: Screen 1 | D16: Task 2 | E16: Task 2 | G16: Login with SSO | H16: 1.5 | I16: {=If($G16="","",INDEX('Common function'!$F$8:$F56, match($G16,'Common function'!$C$8:$C56,0)))} -> 1 | J16: {=If($G16="","",INDEX('Common function'!$G$8:$G56, match($G16,'Common function'!$C$8:$C56,0)))} -> 0 | K16: {=If($G16="","",INDEX('Common function'!$H$8:$H56, match($G16,'Common function'!$C$8:$C56,0)))} -> 1.5 | L16: =If($K16="","",$K16*Appendix!$B$23) -> 0.225 | M16: =If($K16="","",K16*0.1) -> 0.15 | N16: =$H16*sum($I16:$M16) -> 4.3125
A17: =row()-11 -> 6 | C17: Screen 1 | D17: Task 3 | E17: Task 3 | G17: Logout | H17: =Appendix!$B$13 -> 1 | I17: {=If($G17="","",INDEX('Common function'!$F$8:$F56, match($G17,'Common function'!$C$8:$C56,0)))} -> 1 | J17: {=If($G17="","",INDEX('Common function'!$G$8:$G56, match($G17,'Common function'!$C$8:$C56,0)))} -> 0 | K17: {=If($G17="","",INDEX('Common function'!$H$8:$H56, match($G17,'Common function'!$C$8:$C56,0)))} -> 1 | L17: =If($K17="","",$K17*Appendix!$B$23) -> 0.15 | M17: =If($K17="","",K17*0.1) -> 0.1 | N17: =$H17*sum($I17:$M17) -> 2.25
A18: =row()-11 -> 7 | C18: Screen 1 | D18: Task 4 | E18: Task 4 | G18: Forgot Password | H18: =Appendix!$B$13 -> 1 | I18: {=If($G18="","",INDEX('Common function'!$F$8:$F56, match($G18,'Common function'!$C$8:$C56,0)))} -> 3 | J18: {=If($G18="","",INDEX('Common function'!$G$8:$G56, match($G18,'Common function'!$C$8:$C56,0)))} -> 0 | K18: {=If($G18="","",INDEX('Common function'!$H$8:$H56, match($G18,'Common function'!$C$8:$C56,0)))} -> 3 | L18: =If($K18="","",$K18*Appendix!$B$23) -> 0.45 | M18: =If($K18="","",K18*0.1) -> 0.3 | N18: =$H18*sum($I18:$M18) -> 6.75
A19: =row()-11 -> 8 | C19: Screen 1 | D19: Task 5 | E19: Task 5 | G19: Change password | H19: =Appendix!$B$13 -> 1 | I19: {=If($G19="","",INDEX('Common function'!$F$8:$F56, match($G19,'Common function'!$C$8:$C56,0)))} -> 2 | J19: {=If($G19="","",INDEX('Common function'!$G$8:$G56, match($G19,'Common function'!$C$8:$C56,0)))} -> 0 | K19: {=If($G19="","",INDEX('Common function'!$H$8:$H56, match($G19,'Common function'!$C$8:$C56,0)))} -> 2 | L19: =If($K19="","",$K19*Appendix!$B$23) -> 0.3 | M19: =If($K19="","",K19*0.1) -> 0.2 | N19: =$H19*sum($I19:$M19) -> 4.5
A20: =row()-11 -> 9 | C20: Screen 1 | D20: Task 6 | E20: Task 6 | G20: Login 2FA - Authenticatior | H20: =Appendix!$B$13 -> 1 | I20: {=If($G20="","",INDEX('Common function'!$F$8:$F56, match($G20,'Common function'!$C$8:$C56,0)))} -> 2.5 | J20: {=If($G20="","",INDEX('Common function'!$G$8:$G56, match($G20,'Common function'!$C$8:$C56,0)))} -> 0 | K20: {=If($G20="","",INDEX('Common function'!$H$8:$H56, match($G20,'Common function'!$C$8:$C56,0)))} -> 3 | L20: =If($K20="","",$K20*Appendix!$B$23) -> 0.45 | M20: =If($K20="","",K20*0.1) -> 0.3 | N20: =$H20*sum($I20:$M20) -> 6.25
A21: =row()-11 -> 10 | C21: Screen 1 | D21: Task 7 | E21: Task 7 | H21: =Appendix!$B$13 -> 1 | I21: {=If($G21="","",INDEX('Common function'!$F$8:$F56, match($G21,'Common function'!$C$8:$C56,0)))} | J21: {=If($G21="","",INDEX('Common function'!$G$8:$G56, match($G21,'Common function'!$C$8:$C56,0)))} | K21: {=If($G21="","",INDEX('Common function'!$H$8:$H56, match($G21,'Common function'!$C$8:$C56,0)))} | L21: =If($K21="","",$K21*Appendix!$B$23) | M21: =If($K21="","",K21*0.1) | N21: =$H21*sum($I21:$M21) -> 0
A22: =row()-11 -> 11 | C22: Screen 1 | D22: Task 8 | E22: Task 8 | H22: =Appendix!$B$13 -> 1 | I22: {=If($G22="","",INDEX('Common function'!$F$8:$F56, match($G22,'Common function'!$C$8:$C56,0)))} | J22: {=If($G22="","",INDEX('Common function'!$G$8:$G56, match($G22,'Common function'!$C$8:$C56,0)))} | K22: {=If($G22="","",INDEX('Common function'!$H$8:$H56, match($G22,'Common function'!$C$8:$C56,0)))} | L22: =If($K22="","",$K22*Appendix!$B$23) | M22: =If($K22="","",K22*0.1) | N22: =$H22*sum($I22:$M22) -> 0
A23: =row()-11 -> 12 | C23: Screen 1 | D23: Task 9 | E23: Task 9 | H23: =Appendix!$B$13 -> 1 | I23: {=If($G23="","",INDEX('Common function'!$F$8:$F56, match($G23,'Common function'!$C$8:$C56,0)))} | J23: {=If($G23="","",INDEX('Common function'!$G$8:$G56, match($G23,'Common function'!$C$8:$C56,0)))} | K23: {=If($G23="","",INDEX('Common function'!$H$8:$H56, match($G23,'Common function'!$C$8:$C56,0)))} | L23: =If($K23="","",$K23*Appendix!$B$23) | M23: =If($K23="","",K23*0.1) | N23: =$H23*sum($I23:$M23) -> 0
A24: =row()-11 -> 13 | C24: Screen 1 | D24: Task 10 | E24: Task 10 | H24: =Appendix!$B$13 -> 1 | I24: {=If($G24="","",INDEX('Common function'!$F$8:$F56, match($G24,'Common function'!$C$8:$C56,0)))} | J24: {=If($G24="","",INDEX('Common function'!$G$8:$G56, match($G24,'Common function'!$C$8:$C56,0)))} | K24: {=If($G24="","",INDEX('Common function'!$H$8:$H56, match($G24,'Common function'!$C$8:$C56,0)))} | L24: =If($K24="","",$K24*Appendix!$B$23) | M24: =If($K24="","",K24*0.1) | N24: =$H24*sum($I24:$M24) -> 0
A25: =row()-11 -> 14 | C25: Screen 2 | D25: Task 11 | E25: Task 11 | H25: =Appendix!$B$13 -> 1 | I25: {=If($G25="","",INDEX('Common function'!$F$8:$F56, match($G25,'Common function'!$C$8:$C56,0)))} | J25: {=If($G25="","",INDEX('Common function'!$G$8:$G56, match($G25,'Common function'!$C$8:$C56,0)))} | K25: {=If($G25="","",INDEX('Common function'!$H$8:$H56, match($G25,'Common function'!$C$8:$C56,0)))} | L25: =If($K25="","",$K25*Appendix!$B$23) | M25: =If($K25="","",K25*0.1) | N25: =$H25*sum($I25:$M25) -> 0
A26: =row()-11 -> 15 | C26: Screen 2 | D26: Task 12 | E26: Task 12 | H26: =Appendix!$B$13 -> 1 | I26: {=If($G26="","",INDEX('Common function'!$F$8:$F56, match($G26,'Common function'!$C$8:$C56,0)))} | J26: {=If($G26="","",INDEX('Common function'!$G$8:$G56, match($G26,'Common function'!$C$8:$C56,0)))} | K26: {=If($G26="","",INDEX('Common function'!$H$8:$H56, match($G26,'Common function'!$C$8:$C56,0)))} | L26: =If($K26="","",$K26*Appendix!$B$23) | M26: =If($K26="","",K26*0.1) | N26: =$H26*sum($I26:$M26) -> 0
A27: =row()-11 -> 16 | C27: Screen 2 | D27: Task 13 | E27: Task 13 | H27: =Appendix!$B$13 -> 1 | I27: {=If($G27="","",INDEX('Common function'!$F$8:$F56, match($G27,'Common function'!$C$8:$C56,0)))} | J27: {=If($G27="","",INDEX('Common function'!$G$8:$G56, match($G27,'Common function'!$C$8:$C56,0)))} | K27: {=If($G27="","",INDEX('Common function'!$H$8:$H56, match($G27,'Common function'!$C$8:$C56,0)))} | L27: =If($K27="","",$K27*Appendix!$B$23) | M27: =If($K27="","",K27*0.1) | N27: =$H27*sum($I27:$M27) -> 0
A28: =row()-11 -> 17 | C28: Screen 2 | D28: Task 14 | E28: Task 14 | H28: =Appendix!$B$13 -> 1 | I28: {=If($G28="","",INDEX('Common function'!$F$8:$F56, match($G28,'Common function'!$C$8:$C56,0)))} | J28: {=If($G28="","",INDEX('Common function'!$G$8:$G56, match($G28,'Common function'!$C$8:$C56,0)))} | K28: {=If($G28="","",INDEX('Common function'!$H$8:$H56, match($G28,'Common function'!$C$8:$C56,0)))} | L28: =If($K28="","",$K28*Appendix!$B$23) | M28: =If($K28="","",K28*0.1) | N28: =$H28*sum($I28:$M28) -> 0
A29: =row()-11 -> 18 | C29: Screen 2 | D29: Task 15 | E29: Task 15 | H29: =Appendix!$B$13 -> 1 | I29: {=If($G29="","",INDEX('Common function'!$F$8:$F56, match($G29,'Common function'!$C$8:$C56,0)))} | J29: {=If($G29="","",INDEX('Common function'!$G$8:$G56, match($G29,'Common function'!$C$8:$C56,0)))} | K29: {=If($G29="","",INDEX('Common function'!$H$8:$H56, match($G29,'Common function'!$C$8:$C56,0)))} | L29: =If($K29="","",$K29*Appendix!$B$23) | M29: =If($K29="","",K29*0.1) | N29: =$H29*sum($I29:$M29) -> 0
A30: =row()-11 -> 19 | C30: Screen 2 | D30: Task 16 | E30: Task 16 | H30: =Appendix!$B$13 -> 1 | I30: {=If($G30="","",INDEX('Common function'!$F$8:$F56, match($G30,'Common function'!$C$8:$C56,0)))} | J30: {=If($G30="","",INDEX('Common function'!$G$8:$G56, match($G30,'Common function'!$C$8:$C56,0)))} | K30: {=If($G30="","",INDEX('Common function'!$H$8:$H56, match($G30,'Common function'!$C$8:$C56,0)))} | L30: =If($K30="","",$K30*Appendix!$B$23) | M30: =If($K30="","",K30*0.1) | N30: =$H30*sum($I30:$M30) -> 0
A31: =row()-11 -> 20 | C31: Screen 2 | D31: Task 17 | E31: Task 17 | H31: =Appendix!$B$13 -> 1 | I31: {=If($G31="","",INDEX('Common function'!$F$8:$F56, match($G31,'Common function'!$C$8:$C56,0)))} | J31: {=If($G31="","",INDEX('Common function'!$G$8:$G56, match($G31,'Common function'!$C$8:$C56,0)))} | K31: {=If($G31="","",INDEX('Common function'!$H$8:$H56, match($G31,'Common function'!$C$8:$C56,0)))} | L31: =If($K31="","",$K31*Appendix!$B$23) | M31: =If($K31="","",K31*0.1) | N31: =$H31*sum($I31:$M31) -> 0
A32: =row()-11 -> 21 | C32: Screen 2 | D32: Task 18 | E32: Task 18 | H32: =Appendix!$B$13 -> 1 | I32: {=If($G32="","",INDEX('Common function'!$F$8:$F56, match($G32,'Common function'!$C$8:$C56,0)))} | J32: {=If($G32="","",INDEX('Common function'!$G$8:$G56, match($G32,'Common function'!$C$8:$C56,0)))} | K32: {=If($G32="","",INDEX('Common function'!$H$8:$H56, match($G32,'Common function'!$C$8:$C56,0)))} | L32: =If($K32="","",$K32*Appendix!$B$23) | M32: =If($K32="","",K32*0.1) | N32: =$H32*sum($I32:$M32) -> 0
A33: =row()-11 -> 22 | C33: Screen 2 | D33: Task 19 | E33: Task 19 | H33: =Appendix!$B$13 -> 1 | I33: {=If($G33="","",INDEX('Common function'!$F$8:$F56, match($G33,'Common function'!$C$8:$C56,0)))} | J33: {=If($G33="","",INDEX('Common function'!$G$8:$G56, match($G33,'Common function'!$C$8:$C56,0)))} | K33: {=If($G33="","",INDEX('Common function'!$H$8:$H56, match($G33,'Common function'!$C$8:$C56,0)))} | L33: =If($K33="","",$K33*Appendix!$B$23) | M33: =If($K33="","",K33*0.1) | N33: =$H33*sum($I33:$M33) -> 0
A34: =row()-11 -> 23 | C34: Screen 2 | D34: Task 20 | E34: Task 20 | H34: =Appendix!$B$13 -> 1 | I34: {=If($G34="","",INDEX('Common function'!$F$8:$F56, match($G34,'Common function'!$C$8:$C56,0)))} | J34: {=If($G34="","",INDEX('Common function'!$G$8:$G56, match($G34,'Common function'!$C$8:$C56,0)))} | K34: {=If($G34="","",INDEX('Common function'!$H$8:$H56, match($G34,'Common function'!$C$8:$C56,0)))} | L34: =If($K34="","",$K34*Appendix!$B$23) | M34: =If($K34="","",K34*0.1) | N34: =$H34*sum($I34:$M34) -> 0
A35: =row()-11 -> 24 | C35: Screen 2 | D35: Task 21 | E35: Task 21 | H35: =Appendix!$B$13 -> 1 | I35: {=If($G35="","",INDEX('Common function'!$F$8:$F56, match($G35,'Common function'!$C$8:$C56,0)))} | J35: {=If($G35="","",INDEX('Common function'!$G$8:$G56, match($G35,'Common function'!$C$8:$C56,0)))} | K35: {=If($G35="","",INDEX('Common function'!$H$8:$H56, match($G35,'Common function'!$C$8:$C56,0)))} | L35: =If($K35="","",$K35*Appendix!$B$23) | M35: =If($K35="","",K35*0.1) | N35: =$H35*sum($I35:$M35) -> 0
A36: =row()-11 -> 25 | C36: Screen 2 | D36: Task 22 | E36: Task 22 | H36: =Appendix!$B$13 -> 1 | I36: {=If($G36="","",INDEX('Common function'!$F$8:$F56, match($G36,'Common function'!$C$8:$C56,0)))} | J36: {=If($G36="","",INDEX('Common function'!$G$8:$G56, match($G36,'Common function'!$C$8:$C56,0)))} | K36: {=If($G36="","",INDEX('Common function'!$H$8:$H56, match($G36,'Common function'!$C$8:$C56,0)))} | L36: =If($K36="","",$K36*Appendix!$B$23) | M36: =If($K36="","",K36*0.1) | N36: =$H36*sum($I36:$M36) -> 0
A37: =row()-11 -> 26 | C37: Screen 2 | D37: Task 23 | E37: Task 23 | H37: =Appendix!$B$13 -> 1 | I37: {=If($G37="","",INDEX('Common function'!$F$8:$F56, match($G37,'Common function'!$C$8:$C56,0)))} | J37: {=If($G37="","",INDEX('Common function'!$G$8:$G56, match($G37,'Common function'!$C$8:$C56,0)))} | K37: {=If($G37="","",INDEX('Common function'!$H$8:$H56, match($G37,'Common function'!$C$8:$C56,0)))} | L37: =If($K37="","",$K37*Appendix!$B$23) | M37: =If($K37="","",K37*0.1) | N37: =$H37*sum($I37:$M37) -> 0
A38: =row()-11 -> 27 | C38: Screen 2 | D38: Task 24 | E38: Task 24 | H38: =Appendix!$B$13 -> 1 | I38: {=If($G38="","",INDEX('Common function'!$F$8:$F56, match($G38,'Common function'!$C$8:$C56,0)))} | J38: {=If($G38="","",INDEX('Common function'!$G$8:$G56, match($G38,'Common function'!$C$8:$C56,0)))} | K38: {=If($G38="","",INDEX('Common function'!$H$8:$H56, match($G38,'Common function'!$C$8:$C56,0)))} | L38: =If($K38="","",$K38*Appendix!$B$23) | M38: =If($K38="","",K38*0.1) | N38: =$H38*sum($I38:$M38) -> 0
A39: =row()-11 -> 28 | C39: Screen 2 | D39: Task 25 | E39: Task 25 | H39: =Appendix!$B$13 -> 1 | I39: {=If($G39="","",INDEX('Common function'!$F$8:$F56, match($G39,'Common function'!$C$8:$C56,0)))} | J39: {=If($G39="","",INDEX('Common function'!$G$8:$G56, match($G39,'Common function'!$C$8:$C56,0)))} | K39: {=If($G39="","",INDEX('Common function'!$H$8:$H56, match($G39,'Common function'!$C$8:$C56,0)))} | L39: =If($K39="","",$K39*Appendix!$B$23) | M39: =If($K39="","",K39*0.1) | N39: =$H39*sum($I39:$M39) -> 0
A40: =row()-11 -> 29 | C40: Screen 2 | D40: Task 26 | E40: Task 26 | H40: =Appendix!$B$13 -> 1 | I40: {=If($G40="","",INDEX('Common function'!$F$8:$F56, match($G40,'Common function'!$C$8:$C56,0)))} | J40: {=If($G40="","",INDEX('Common function'!$G$8:$G56, match($G40,'Common function'!$C$8:$C56,0)))} | K40: {=If($G40="","",INDEX('Common function'!$H$8:$H56, match($G40,'Common function'!$C$8:$C56,0)))} | L40: =If($K40="","",$K40*Appendix!$B$23) | M40: =If($K40="","",K40*0.1) | N40: =$H40*sum($I40:$M40) -> 0
A41: =row()-11 -> 30 | I41: {=If($G41="","",INDEX('Common function'!$F$8:$F56, match($G41,'Common function'!$C$8:$C56,0)))} | J41: {=If($G41="","",INDEX('Common function'!$G$8:$G56, match($G41,'Common function'!$C$8:$C56,0)))} | K41: {=If($G41="","",INDEX('Common function'!$H$8:$H56, match($G41,'Common function'!$C$8:$C56,0)))} | L41: =If($K41="","",$K41*Appendix!$B$23) | M41: =If($K41="","",K41*0.1) | N41: =$H41*sum($I41:$M41) -> 0
A42: =row()-11 -> 31 | I42: {=If($G42="","",INDEX('Common function'!$F$8:$F56, match($G42,'Common function'!$C$8:$C56,0)))} | J42: {=If($G42="","",INDEX('Common function'!$G$8:$G56, match($G42,'Common function'!$C$8:$C56,0)))} | K42: {=If($G42="","",INDEX('Common function'!$H$8:$H56, match($G42,'Common function'!$C$8:$C56,0)))} | L42: =If($K42="","",$K42*Appendix!$B$23) | M42: =If($K42="","",K42*0.1) | N42: =$H42*sum($I42:$M42) -> 0
...

Sheet Criteria for project complexity
B1: TIÊU CHÍ LỰA CHỌN HỆ SỐ COMPLEXITY CHO DỰ ÁN | AL1: No: BM-2-901-23
AL2: Version: 1.2
AL3: Issue Date: 06/11/2025
AL4: ISO/IEC 27001:2022 & ISO 9001:2015
A5: SUN ASTERISK VIETNAM CO., LTD
B7: 1. MỤC ĐÍCH CỦA VIỆC LỰA CHỌN HỆ SỐ CỦA DỰ ÁN
C8: - Hệ số được sử dụng để điều chỉnh các giá trị ước tính ban đầu do mỗi dự án sẽ có những yêu cầu khác nhau, có độ phức tạp khác nhau.
C9: - Mỗi dự án đều có các function common, từ hệ số dự án, có thể đưa luôn effort vào cho các function common đó.
C10: - Bên cạnh đó, dựa trên độ phức tạp của dự án + hệ số dự án, có thể đánh giá effort của các function không thuộc list common 1 cách hiệu quả.
C11: - Đánh giá độ phức tạp của dự án và hệ số của dự án là thực hiện cho toàn dự án, không cho từng function.
B13: 2. CÁC TIÊU CHÍ ĐÁNH GIÁ
C15: 2.1. Quality Requirement
C16: Lựa chọn | H16: Giải thích | T16: Tiêu chí
C17: High | H17: - Dự án có yêu cầu cao về mặt chất lượng | T17: - Ngoài mặt logic nghiệp vụ dự án, KH có thêm các yêu cầu: + Chất lượng test: Cần test đầy đủ các validate, validate theo từng items, UI cũng yêu cầu cao. Ngoài ra, cần test tương tác nhiều với các hệ thống bên ngoài, hoặc phần cứng của device/browser... + Chất lượng spec: Cần có những đóng góp thêm về spec, đóng góp thêm về validate cho các items, tính năng... + Chất lượng quản lý: Cần có sự qly chặt chẽ, có các báo cáo bài bản, tiêu chuẩn, thường xuyên + Chất lượng test: Cần có evidence đầy đủ cho mỗi case test ... - Hoặc có thể KH có riêng đội test --- Note: Tiêu chí chất lượng test là tiêu chí quan trọng nhất, các tiêu chí khác có thể bỏ qua
C18: Medium | H18: - Dự án có yêu cầu trung bình về mặt chất lượng | T18: - Ngoài mặt logic nghiệp vụ dự án, KH có thêm các yêu cầu: + Chất lượng test: Cần test đầy đủ các validate, validate theo từng items , tính năng. Tuy nhiên, k cần quá kỹ nếu là các site do bên KH quản lý. ... --- Note: Tiêu chí chất lượng test là tiêu chí quan trọng nhất, các tiêu chí khác có thể bỏ qua
C19: Low | H19: - Dự án có yêu cầu thấp về mặt chất lượng | T19: - Khách hàng không có yêu cầu cụ thể, chỉ cần có thể đảm bảo về mặt logic nghiệp vụ OK, luồng dự án chạy đúng
C21: 2.2. Project Complexity
C22: Tiêu chí | H22: Chi tiết tiêu chí đánh giá | O22: Lựa chọn
O23: High | Z23: Medium | AK23: Low
C24: Note: - Yếu tố nghiệp vụ + Kỹ thuật là bắt buộc phải đánh giá - Yếu tố khác là optional - Nếu 2/3 số tiêu chí thuộc loại nào thì độ phức tạp là loại đó - Nếu yếu tố ngân sách là chủ chốt thì từ đầu sẽ chốt luôn scope test với KH để tránh tăng effort về sau
C25: I. Nghiệp vụ * | H25: 1. Rõ ràng của Yêu cầu | O25: Yêu cầu không rõ ràng, thay đổi liên tục, mâu thuẫn lớn, cần rất nhiều thời gian để làm rõ. | Z25: Yêu cầu mơ hồ, nhiều điểm cần làm rõ, có thể có mâu thuẫn. | AK25: Yêu cầu khá rõ ràng, cần làm rõ thêm một vài điểm nhỏ.
H26: 2. Độ phức tạp của Logic & Quy tắc | O26: Rất nhiều quy tắc phức tạp, thay đổi thường xuyên, tương tác cực kỳ phức tạp giữa các quy tắc, rất nhiều ngoại lệ. | Z26: Nhiều quy tắc phức tạp, lồng ghép, nhiều điều kiện đặc biệt, luồng phi tuyến tính. | AK26: Khá nhiều quy tắc, một số điều kiện rẽ nhánh, vài luồng phụ.
H27: 3. Mức độ ràng buộc & Ảnh hưởng | O27: Ràng buộc cực kỳ phức tạp, ảnh hưởng toàn hệ thống, rủi ro cao về tính toàn vẹn và nghiệp vụ nếu sai. | Z27: Nhiều ràng buộc chéo, ảnh hưởng đến nhiều module/quy trình, tác động lớn đến dữ liệu. | AK27: Có một số ràng buộc, ảnh hưởng đến vài chức năng liên quan.
H28: 4. Độ nhạy cảm Dữ liệu / Tác động rủi ro | O28: Dữ liệu cực kỳ nhạy cảm (ngân hàng, y tế), lỗi gây thiệt hại nghiêm trọng (mất tiền lớn, vi phạm pháp lý, ảnh hưởng tính mạng). | Z28: Dữ liệu nhạy cảm (cá nhân, tài chính), lỗi gây thiệt hại đáng kể (mất doanh thu nhỏ, mất uy tín). | AK28: Dữ liệu bình thường, lỗi có tác động trung bình (ví dụ: cần sửa thủ công, làm chậm process).
H29: 5. Tính đặc thù / Tính mới của chức năng | O29: Chức năng hoàn toàn mới, chưa từng làm, yêu cầu R&D sâu rộng, rủi ro cao về tính khả thi. | Z29: Chức năng rất đặc thù, ít kinh nghiệm, cần nghiên cứu sâu hoặc thuật toán phức tạp. | AK29: Chức năng tùy chỉnh một phần, có yếu tố đặc thù nhưng dựa trên cơ sở quen thuộc.
H30: 6. Tần suất thay đổi Yêu cầu (CR) | O30: Yêu cầu thay đổi liên tục, ảnh hưởng lớn đến thiết kế và tiến độ, gây rework đáng kể. | Z30: Yêu cầu thay đổi khá thường xuyên, đôi khi ảnh hưởng đến thiết kế. | AK30: Có thể có một vài thay đổi nhỏ, đã được lường trước.
C31: II. Kỹ thuật * | H31: 1. Độ lớn của Tính năng / Phạm vi ảnh hưởng Code | O31: Rất lớn, ảnh hưởng toàn bộ hệ thống, cần thay đổi kiến trúc cốt lõi, tiềm ẩn rủi ro regression lớn. | Z31: Lớn, ảnh hưởng nhiều module, cần thay đổi kiến trúc nhỏ. | AK31: Trung bình, ảnh hưởng vài file/màn hình, một module.
H32: 2. Phức tạp về Công nghệ / Kiến trúc -- Dev + QA | O32: Cần phát triển công nghệ lõi mới, chưa có tiền lệ, rủi ro cực cao về tính khả thi và ổn định. | Z32: Công nghệ/Kiến trúc hoàn toàn mới, cần R&D đáng kể, không có nhiều tài liệu/hỗ trợ. | AK32: Có sử dụng công nghệ/kiến trúc mới một phần, cần tìm hiểu thêm, có tài liệu hỗ trợ.
H33: 3. Ảnh hưởng đến Mã nguồn cũ (Legacy Code) | O33: Ảnh hưởng đến mã nguồn legacy cốt lõi, không có tài liệu, rất khó thay đổi mà không gây lỗi lan truyền toàn hệ thống. | Z33: Ảnh hưởng đến vùng mã nguồn cũ phức tạp, thiếu tài liệu, cần refactor lớn hoặc thay đổi cấu trúc đáng kể. | AK33: Ảnh hưởng một phần mã nguồn cũ, có tài liệu cơ bản, cần refactor nhỏ để tích hợp.
H34: 4. Tích hợp với hệ thống bên ngoài / API bên thứ 3 | O34: Tích hợp với các hệ thống legacy/đặc thù, không có tài liệu, đòi hỏi nhiều kỹ thuật kết nối đặc biệt, xử lý dữ liệu lớn, độ tin cậy thấp. | Z34: Tích hợp nhiều hệ thống/API phức tạp, tài liệu không đầy đủ, yêu cầu xử lý lỗi/kịch bản đặc biệt. | AK34: Tích hợp với 1-2 hệ thống/API ngoài, có tài liệu, cần một số điều chỉnh nhỏ.
H35: 5. Môi trường triển khai | O35: Triển khai trên môi trường không ổn định, nhiều ràng buộc về hạ tầng, yêu cầu xử lý các trường hợp thất bại phức tạp và khôi phục. | Z35: Triển khai trên môi trường mới/phức tạp (ví dụ: multi-cloud, on-premise), cần thiết lập nhiều. | AK35: Triển khai trên môi trường quen thuộc nhưng có một số tùy chỉnh, cần cấu hình thủ công.
C36: III. Quản lý & Nguồn lực | H36: 1. Thời gian / Ngân sách dự kiến | O36: Thời gian/Ngân sách không khả thi, đòi hỏi hy sinh chất lượng hoặc phạm vi lớn. | Z36: Thời gian/Ngân sách eo hẹp, gây áp lực lớn cho đội ngũ, tiềm ẩn rủi ro về chất lượng. | AK36: Thời gian/Ngân sách đủ dùng, có thể có chút áp lực.
H37: 2. Mức độ quen thuộc / Kỹ năng đội ngũ | O37: Đội ngũ không có ai đủ năng lực để thực hiện task, cần tuyển dụng mới hoặc học hỏi từ đầu, rất tốn thời gian. | Z37: Đội ngũ thiếu kinh nghiệm/kỹ năng cần thiết, cần đào tạo đáng kể hoặc sự hỗ trợ từ chuyên gia bên ngoài. | AK37: Đội ngũ có đủ kỹ năng, có thể cần học hỏi thêm một chút hoặc tìm hiểu tài liệu.
H38: 3. Phụ thuộc vào các bên / đội nhóm khác | O38: Phụ thuộc lẫn nhau phức tạp với nhiều đội/bên ngoài, rủi ro lớn về lịch trình và sự đồng bộ. | Z38: Phụ thuộc vào nhiều đội nhóm hoặc bên thứ ba, lịch trình chồng chéo, giao tiếp khó khăn. | AK38: Phụ thuộc vào 1-2 đội nhóm khác nhưng lịch trình rõ ràng, ít rủi ro.
B41: 3. MỘT SỐ GỢI Ý LỰA CHỌN HỆ SỐ CHO EXECUTE
B43: Các loại test | H43: Language code | O43: Hệ số (tham khảo)
B44: Trên nhiều device | H44: Native thuần | O44: - Android/iOS (Môi trường chính): 100% execute - Các môi trường phụ: 10-20% effort execute
H45: Flutter | O45: - Android (Môi trường chính): 100% execute - iOS (Môi trường chính): 20-70% execute tùy thuộc vào app - Các môi trường phụ: 10-20% effort execute
B46: Trên nhiều browser | H46: - | O46: - Môi trường chính: 100% execute - Các môi trường phụ: 10-20% effort execute
B47: Multi language | H47: - | O47: - Môi trường chính: 100% execute - Các môi trường phụ: 10-15% effort execute

Sheet Appendix
B1: WBS ESTIMATION | F1: No: BM-QT-1701-02
F2: Version: 1.3
F3: Issue Date: 22/09/2026
A4: SUN ASTERISK VIETNAM CO., LTD | F4: ISO/IEC 27001:2022 & ISO 9001:2015
A7: Lựa chọn coefficient của dự án
A8: Category | B8: Select value | C8: Coefficient | D8: Total Score
A9: Project Type | B9: POC/MVP | C9: =IFS(B9="POC/MVP", 1, B9="New Development - Small",1,B9="New Development - Medium",2,B9="New Development - Big",3, B9="Enhancement - Small",1,B9="Enhancement - Medium",2,B9="Enhancement - Big",3 ) -> 1 | D9: =SUM(C9:C11) -> 4
A10: Quality Requirement | B10: Low | C10: =IFS(B10="High",3, B10="Medium",2,B10="Low",1 ) -> 1
A11: Project Complexity | B11: Medium | C11: =IFS(B11="High",3, B11="Medium",2,B11="Low",1 ) -> 2
A12: Select Pattern | B12: =IFS( 4>=D9, "Pattern III – Lean QA", 7>=D9, "Pattern II – Balanced QA", TRUE, "Pattern I – Intensive QA" ) -> Pattern III – Lean QA | C12: - Refer table Pattern
A13: Coefficient | B13: =IFS(B12="Pattern I – Intensive QA",2,B12="Pattern II – Balanced QA",1.5, B12="Pattern III – Lean QA",1) -> 1 | C13: - QA có thể thay đổi coefficient của function estimate tùy theo yêu cầu
A15: Pattern name | B15: Total Score | C15: Coefficient | D15: Note
A16: Pattern I – Intensive QA | B16: < 4 | C16: 1
A17: Pattern II – Balanced QA | B17: 4~7 | C17: 1.5
A18: Pattern III – Lean QA | B18: >7 | C18: 2
A20: Value | B20: Coefficient | C20: Note
A21: Working days in a month | B21: 20
A22: Working hours in a day | B22: 7
A23: Bug rate | B23: 0.15 | C23: 25%~35% so với time execute testcase, tương ứng với 5%~7% nếu tính theo số testcase và time verify bug 0.5h/1 bug trước đây
A24: * Have to estimate base on qualification of rank 3.5 QA

Sheet Common function
C1: COMMON FUNCTION | F1: No: BM-QT-1701-02
F2: Version: 1.3
F3: Issue Date: 22/09/2026
A4: SUN ASTERISK VIETNAM CO., LTD | F4: ISO/IEC 27001:2022 & ISO 9001:2015
A6: No | B6: Feature | C6: Function name | D6: Detail | E6: Refer common testcase | F6: Effort (hour)
F7: Create | G7: Review | H7: Execute
A8: 1 | B8: Authentication & Authorization | C8: Login | D8: ID+ PW | E8: https://docs.google.com/spreadsheets/d/1lhm7pXbSCYciKSZGAbRZeaL-eJXuaKt4y2aa9AfQq9M/edit?gid=627680991#gid=627680991 | F8: 2 | G8: 0 | H8: 2.5
A9: 2 | C9: Login with SSO | D9: SSO - 1 method (Login with apple /gg/ facebook/...) | F9: 1 | G9: 0 | H9: 1.5
A10: 3 | C10: Login 2FA - Authenticatior | F10: 2.5 | G10: 0 | H10: 3
A11: 4 | C11: Login 2FA - SMS | F11: 2.5 | G11: 0 | H11: 3
A12: 5 | C12: Registration/Sign-up | D12: Include basic fields: - Full Name - Email - Password - Confirm Password - Phone Number - Register button - Cancel button | E12: https://docs.google.com/spreadsheets/d/1asmCpS5JjdFiGWfuhvWXQq0SosnxoPuDKnEnuk8v-vA/edit?gid=949616877#gid=949616877 | F12: 3 | G12: 0 | H12: 3
A13: 6 | C13: Logout | E13: https://docs.google.com/spreadsheets/d/1lhm7pXbSCYciKSZGAbRZeaL-eJXuaKt4y2aa9AfQq9M/edit?gid=1562053010#gid=1562053010 | F13: 1 | G13: 0 | H13: 1
A14: 7 | C14: Forgot Password | D14: - Input email - Send mail - Reset pw | E14: https://docs.google.com/spreadsheets/d/1FZNv6LmXWMwc54F7_M3HgodhXYMzBrxzKqaUpB6m7_U/edit?gid=543789658#gid=543789658 | F14: 3 | G14: 0 | H14: 3
A15: 8 | C15: Change password | D15: Include these fields: - Current pw - New pw - Re-enter New pw | E15: https://docs.google.com/spreadsheets/d/1yrlY6-UBByeZjo57Q6AiIvUEJrbQjTAZ496fVwUOmwI/edit?gid=782978744#gid=782978744 | F15: 2 | G15: 0 | H15: 2
A16: 9 | B16: CRUD Functionality | C16: List | D16: Basic, no search function | E16: https://docs.google.com/spreadsheets/d/1piJjiSb5HvAMLp4ATweMTtk_6pxmbUzJJuAGrWds-fc/edit?gid=1752790160#gid=1752790160 | F16: 2 | G16: 0 | H16: 3
A17: 10 | C17: List with search function | F17: 5 | G17: 1 | H17: 7
A18: 11 | C18: Create | D18: ~ 10 fields Tùy thuộc vào thuộc tính của đối tượng, giả định est với 10 field | E18: https://docs.google.com/spreadsheets/d/1YRHNPc3wiTuEX7sK6qwes-ROunIHqDjnQOBU7J2eOEw/edit?gid=280769628#gid=280769628 | F18: 5 | G18: 0 | H18: 6
A19: 12 | C19: Detail | E19: https://docs.google.com/spreadsheets/d/1M_9cQpWXNS89b7oa9OAElutO7YPolDFsw_Ds15Joq2k/edit?gid=1406801780#gid=1406801780 | F19: 1 | G19: 0 | H19: 2
A20: 13 | C20: Update | D20: The logic is the same as the create screen | E20: https://docs.google.com/spreadsheets/d/1_GaG9bVYeXsDRT2H4ht6Zwq24xQ4aeLLgeaLy8LbUv4/edit?gid=823311358#gid=823311358 | F20: 2 | G20: 0 | H20: 3
A21: 14 | C21: Delete | E21: https://docs.google.com/spreadsheets/d/1MlAjJvbtOsxWn4aof-dNM3tTO0YgZNi-tP9ReLSXgdM/edit?gid=975778227#gid=975778227 | F21: 1 | G21: 0 | H21: 1
A22: 15 | B22: E-Commerce Basics | C22: Add to Cart | D22: - Add to card only - Not include detail product | E22: https://docs.google.com/spreadsheets/d/168COdtJSr2eZeEmOQGCcVXZY22uTursdYcXEVTH3R0c/edit?gid=799253690#gid=799253690 | F22: 3 | G22: 0 | H22: 4
A23: 16 | C23: List cart | F23: 3 | G23: 0 | H23: 4
A24: 17 | C24: Payment - Credit card | D24: - Payment thông qua cổng thanh toán GMO/Stripe - Hệ thống sử dụng phương thức API (tự lựa chọn các phương thức thanh toán tại hệ thống của mình và gởi API qua GMO để lấy token) | F24: 10 | G24: 4 | H24: 16
A25: 18 | C25: Payment - PayEasy | F25: 4 | G25: 2 | H25: 6
A26: 19 | C26: Payment - Convenience store | F26: 4 | G26: 2 | H26: 6
A27: 20 | C27: Payment - PayPal | F27: 4 | G27: 2 | H27: 6
A28: 21 | C28: In-app Purchases (IAP) | D28: Buy premium features, remove ads
A29: 22 | C29: Payment Gateway Integration | D29: Apple Pay/ Google Pay
A30: 23 | C30: Subscription Management
A31: 24 | B31: File Handling | C31: Upload | E31: https://docs.google.com/spreadsheets/d/17If0wIjy6cqS-eXq7YyhMVf_0BTu6pPAQP5frmiTD8w/edit?gid=1255909033#gid=1255909033
A32: 25 | C32: Download | D32: ~ 5 params
A33: 26 | C33: Import | D33: ~ 5 params | E33: https://docs.google.com/spreadsheets/d/1sXTBqueRfxMXWxVloh9svaNu88rF7M75jg6AcurGdQg/edit?gid=79899913#gid=79899913
A34: 27 | C34: Export | D34: ~ 5 params | E34: https://docs.google.com/spreadsheets/d/1ygEBjXKMtq_909choT2TtnTle-7ugBcJMVi4S6I2LK4/edit?gid=1717995246#gid=1717995246
