Workbook

Sheet History of changes
E1: ESTIMATION | J1: No: BM-2-901-06
J2: Version: 2.2
J3: Issue Date: 23/12/2024
A4: SUN ASTERISK VIETNAM CO., LTD | J4: ISO/IEC 27001:2013&ISO 9001:2015
A6: HISTORY OF CHANGES
A7: No | B7: Change Item | E7: Description of changes | J7: Change Date
A8: 1 | E8: Update format | J8: 44320
A9: 2 | B9: Sheet Summary | E9: Update Summary sheet mục Assumptions | J9: 11//26/2024
A10: 3 | B10: Sheet Summary | E10: Thay đổi Project Role theo thay đổi cơ cấu mới của tổ chức - PSM -> Project Leader | J10: 23/12/2024

Sheet Summary
C1: ESTIMATION | E1: No: BM-2-901-06
E2: Version: 2.1
E3: Issue Date: 05/04/2021
A4: SUN ASTERISK VIETNAM CO., LTD | E4: ISO/IEC 27001:2013&ISO 9001:2015
B6: WBS Estimate for : (project/customer name....)
B8: I. Estimation
B10: Total Estimated Effort (hours) | C10: Total Esstimated Effort (Man-day) | D10: Total Esstimated Effort (Man-month)
B11: ='WBS Estimation'!B7 -> 357.2 | C11: =ROUNDUP(B11/8,2) -> 44.65 | D11: =ROUNDUP(C11/20,2) -> 2.24
B14: II. Scope & Assumptions
B16: 1. In Scope
B17: The scope for estimate does include the following items:
B18: # | C18: Item | D18: Description | E18: Note
B19: 1 | C19: - Develop new system
B20: 2 | C20: - Migrate data from old system
B21: 3 | C21: - User Manual
B24: 2. Out of Scope
B25: The estimation does not include the following items:
B26: # | C26: Item | D26: Description | E26: Note
B27: 1 | C27: - Setup system os on servers
B28: 2 | C28: - Onsite trainning for user
B32: 3. Assumptions
B33: 3-1. Overall Assumptions | K33: → Japanese Translation 日本語訳（自動翻訳）
B34: # | C34: Item | E34: Applicable degree | F34: Assumptions | H34: Reason for not applicable | K34: # | L34: =IFERROR(__xludf.DUMMYFUNCTION("GOOGLETRANSLATE(C34,""en"",""ja"")"),"アイテム") -> アイテム | N34: =IFERROR(__xludf.DUMMYFUNCTION("GOOGLETRANSLATE(E34,""en"",""ja"")"),"該当する学位") -> 該当する学位 | O34: =IFERROR(__xludf.DUMMYFUNCTION("GOOGLETRANSLATE(F34,""en"",""ja"")"),"前提条件") -> 前提条件 | Q34: =IFERROR(__xludf.DUMMYFUNCTION("GOOGLETRANSLATE(H34,""en"",""ja"")"),"該当しない理由") -> 該当しない理由
B35: 1 | C35: Accuracy of this estimation | E35: Super Rough | K35: 1 | L35: 見積もりの精度 | N35: Super Rough
B36: 2 | C36: Roles and expected outputs of each role (What tasks will each role be responsible for, and what will they output?) Ref: Responsibility of each role: [JP] Onboarding for JPPM | D36: PL | E36: TRUE | K36: 2 | L36: =IFERROR(__xludf.DUMMYFUNCTION("GOOGLETRANSLATE(C36,""en"",""ja"")"),"各役割の役割と期待される成果物 （各役割はどのようなタスクを担当し、どのような成果物を出すのか？） 参照：各役割の責任：[JP] JPPMオンボーディング") -> 各役割の役割と期待される成果物 （各役割はどのようなタスクを担当し、どのような成果物を出すのか？） 参照：各役割の責任：[JP] JPPMオンボーディング | M36: PL | N36: FALSE
D37: BrSE | E37: TRUE | M37: BrSE | N37: FALSE
D38: Communicator | E38: TRUE | M38: Communicator | N38: FALSE
B39: 3 | C39: Roles and expected output from JP members (What are you expecting to get from JP side?) | E39: TRUE | K39: 3 | L39: =IFERROR(__xludf.DUMMYFUNCTION("GOOGLETRANSLATE(C39,""en"",""ja"")"),"日本人メンバーの役割と期待される成果 （日本人メンバーにはどのような成果を期待していますか？）") -> 日本人メンバーの役割と期待される成果 （日本人メンバーにはどのような成果を期待していますか？） | N39: FALSE
B40: 4 | C40: Schedule and expected inputs and outputs at each milestone (When and what will be output during the project period? When are dependent inputs expected to be completed/received?) Example: timeline for receiving existing database structure from customer and timeline for starting development | E40: Must have | K40: 4 | L40: =IFERROR(__xludf.DUMMYFUNCTION("GOOGLETRANSLATE(C40,""en"",""ja"")"),"各マイルストーンにおけるスケジュールと想定されるインプットおよびアウトプット （プロジェクト期間中にいつ、どのようなアウトプットが得られるのか？依存するインプットはいつ完了／受領される予定か？）例：顧客から既存のデータベース構造を受け取るまでのタイムラインと、開発を開始するまでのタイムライン") -> 各マイルストーンにおけるスケジュールと想定されるインプットおよびアウトプット （プロジェクト期間中にいつ、どのようなアウトプットが得られるのか？依存するインプットはいつ完了／受領される予定か？）例：顧客から既存のデータベース構造を受け取るまでのタイムラインと、開発を開始するまでのタイムライン | N40: Must have
B41: 5 | C41: Number of screens | E41: Must have | K41: 5 | L41: =IFERROR(__xludf.DUMMYFUNCTION("GOOGLETRANSLATE(C41,""en"",""ja"")"),"画面数") -> 画面数 | N41: Must have
B42: 6 | C42: Number of APIs per screen | E42: TRUE | K42: 6 | L42: =IFERROR(__xludf.DUMMYFUNCTION("GOOGLETRANSLATE(C42,""en"",""ja"")"),"画面あたりのAPI数") -> 画面あたりのAPI数 | N42: FALSE
B43: 7 | C43: Interfaces | E43: TRUE | K43: 7 | L43: =IFERROR(__xludf.DUMMYFUNCTION("GOOGLETRANSLATE(C43,""en"",""ja"")"),"インターフェース") -> インターフェース | N43: FALSE
B44: 8 | C44: Forms ("Cho-hyo" in Japanese) | E44: TRUE | K44: 8 | L44: =IFERROR(__xludf.DUMMYFUNCTION("GOOGLETRANSLATE(C44,""en"",""ja"")"),"形態（日本語では「チョヒョ」）") -> 形態（日本語では「チョヒョ」） | N44: FALSE
B45: 9 | C45: System scale (How do you envision the number of users and infrastructure configuration? *If specified by the customer, attach a link to the customer request.) | E45: TRUE | K45: 9 | L45: =IFERROR(__xludf.DUMMYFUNCTION("GOOGLETRANSLATE(C45,""en"",""ja"")"),"システム規模 （ユーザー数とインフラ構成について、どのような想定をお持ちですか？※お客様から指定がある場合は、お客様からのご要望へのリンクを添付してください。）") -> システム規模 （ユーザー数とインフラ構成について、どのような想定をお持ちですか？※お客様から指定がある場合は、お客様からのご要望へのリンクを添付してください。） | N45: FALSE
B46: 10 | C46: Non-functional requirements (What do you envision for SLA and security requirements? *If specified by the customer, attach a link to the customer request.) | E46: TRUE | K46: 10 | L46: =IFERROR(__xludf.DUMMYFUNCTION("GOOGLETRANSLATE(C46,""en"",""ja"")"),"非機能要件 （SLAおよびセキュリティ要件について、どのような構想をお持ちですか？※お客様から指定がある場合は、お客様からのリクエストへのリンクを添付してください。）") -> 非機能要件 （SLAおよびセキュリティ要件について、どのような構想をお持ちですか？※お客様から指定がある場合は、お客様からのリクエストへのリンクを添付してください。） | N46: FALSE
B47: 11 | C47: Buffer rate (%) and its breakdown (Buffer for risk, such as change request, bugs and issue solving, technical difficulty only) | E47: Must have | K47: 11 | L47: =IFERROR(__xludf.DUMMYFUNCTION("GOOGLETRANSLATE(C47,""en"",""ja"")"),"バッファ率（％）とその内訳 （変更要求、バグや問題の解決、技術的な困難など、リスクに対するバッファのみ）") -> バッファ率（％）とその内訳 （変更要求、バグや問題の解決、技術的な困難など、リスクに対するバッファのみ） | N47: Must have
B49: 3-2. Detail Assumptions per each role | K49: → Japanese Translation 日本語訳（自動翻訳）
B50: Role | C50: Item | E50: Applicable degree | F50: Assumptions | H50: Reason for not applicable | K50: =IFERROR(__xludf.DUMMYFUNCTION("GOOGLETRANSLATE(B50,""en"",""ja"")"),"役割") -> 役割 | L50: =IFERROR(__xludf.DUMMYFUNCTION("GOOGLETRANSLATE(C50,""en"",""ja"")"),"アイテム") -> アイテム | N50: =IFERROR(__xludf.DUMMYFUNCTION("GOOGLETRANSLATE(E50,""en"",""ja"")"),"該当する学位") -> 該当する学位 | O50: =IFERROR(__xludf.DUMMYFUNCTION("GOOGLETRANSLATE(F50,""en"",""ja"")"),"前提条件") -> 前提条件 | Q50: =IFERROR(__xludf.DUMMYFUNCTION("GOOGLETRANSLATE(H50,""en"",""ja"")"),"該当しない理由") -> 該当しない理由
B51: Backend | C51: Develop new system or Develop in existing System? | E51: Must have | K51: Backend | L51: =IFERROR(__xludf.DUMMYFUNCTION("GOOGLETRANSLATE(C51,""en"",""ja"")"),"新規システムを開発するか、既存システム内で開発するか？") -> 新規システムを開発するか、既存システム内で開発するか？ | N51: Must have
C52: Architecture (microservices, monolithic, multitenant) | E52: TRUE | L52: =IFERROR(__xludf.DUMMYFUNCTION("GOOGLETRANSLATE(C52,""en"",""ja"")"),"アーキテクチャ（マイクロサービス、モノリシック、マルチテナント）") -> アーキテクチャ（マイクロサービス、モノリシック、マルチテナント） | N52: FALSE | O52: =IFERROR(__xludf.DUMMYFUNCTION("iferror(GOOGLETRANSLATE(F52,""en"",""ja""),"""")"),"")
...

Sheet WBS Estimation
B1: ESTIMATION | E1: No: BM-2-901-06
E2: Version: 2.1
E3: Issue Date: 05/04/2021
A4: SUN ASTERISK VIETNAM CO., LTD | E4: ISO/IEC 27001:2013&ISO 9001:2015
A6: Total Project Effort | B6: Man-hour(s) | C6: Man-day(s) | D6: Man-month(s)
B7: =SUM(J17:J32) -> 357.2 | C7: =ROUNDUP(B7/8,2) -> 44.65 | D7: =ROUNDUP(C7/20,2) -> 2.24
A9: Role | B9: Man-hour(s)
A10: PG | B10: =SUM(D17:D32)+SUM(E17:E32)+SUM(F17:F32) -> 267
A11: Infra | B11: =SUM(H17:H32) -> 22.7
A12: QA
A13: BrSE | B13: =SUM(G17:G32) -> 44.8
A14: PM | B14: =SUM(I17:I32) -> 22.7
A16: Feature | B16: Function | C16: Task Name | D16: Coding (hours) | E16: Unit test | F16: Fixbug (hours) | G16: Specs (hours) | H16: Infra (hours) | I16: Management (hours) | J16: Total (hours)
A17: Feature 1 | B17: Function 1.1 | C17: Task 1 | D17: 4 | E17: =ROUNDUP($D17*'Effort distribution'!$C$5/'Effort distribution'!$B$5,1) -> 2.7 | F17: =ROUNDUP($D17*'Effort distribution'!$D$5/'Effort distribution'!$B$5,1) -> 1.4 | G17: =ROUNDUP($D17*'Effort distribution'!$E$5/'Effort distribution'!$B$5,1) -> 1.4 | H17: =ROUNDUP($D17*'Effort distribution'!$F$5/'Effort distribution'!$B$5,1) -> 0.7 | I17: =ROUNDUP($D17*'Effort distribution'!$G$5/'Effort distribution'!$B$5,1) -> 0.7 | J17: =SUM(D17:I17) -> 10.9
A18: Feature 1 | B18: Function 1.1 | C18: Task 2 | D18: 4 | E18: =ROUNDUP($D18*'Effort distribution'!$C$5/'Effort distribution'!$B$5,1) -> 2.7 | F18: =ROUNDUP($D18*'Effort distribution'!$D$5/'Effort distribution'!$B$5,1) -> 1.4 | G18: =ROUNDUP($D18*'Effort distribution'!$E$5/'Effort distribution'!$B$5,1) -> 1.4 | H18: =ROUNDUP($D18*'Effort distribution'!$F$5/'Effort distribution'!$B$5,1) -> 0.7 | I18: =ROUNDUP($D18*'Effort distribution'!$G$5/'Effort distribution'!$B$5,1) -> 0.7 | J18: =SUM(D18:I18) -> 10.9
A19: Feature 1 | B19: Function 1.2 | C19: Task 1 | D19: 4 | E19: =ROUNDUP($D19*'Effort distribution'!$C$5/'Effort distribution'!$B$5,1) -> 2.7 | F19: =ROUNDUP($D19*'Effort distribution'!$D$5/'Effort distribution'!$B$5,1) -> 1.4 | G19: =ROUNDUP($D19*'Effort distribution'!$E$5/'Effort distribution'!$B$5,1) -> 1.4 | H19: =ROUNDUP($D19*'Effort distribution'!$F$5/'Effort distribution'!$B$5,1) -> 0.7 | I19: =ROUNDUP($D19*'Effort distribution'!$G$5/'Effort distribution'!$B$5,1) -> 0.7 | J19: =SUM(D19:I19) -> 10.9
A20: Feature 1 | B20: Function 1.2 | C20: Task 2 | D20: 4 | E20: =ROUNDUP($D20*'Effort distribution'!$C$5/'Effort distribution'!$B$5,1) -> 2.7 | F20: =ROUNDUP($D20*'Effort distribution'!$D$5/'Effort distribution'!$B$5,1) -> 1.4 | G20: =ROUNDUP($D20*'Effort distribution'!$E$5/'Effort distribution'!$B$5,1) -> 1.4 | H20: =ROUNDUP($D20*'Effort distribution'!$F$5/'Effort distribution'!$B$5,1) -> 0.7 | I20: =ROUNDUP($D20*'Effort distribution'!$G$5/'Effort distribution'!$B$5,1) -> 0.7 | J20: =SUM(D20:I20) -> 10.9
A21: Feature 2 | B21: Function 2.1 | C21: Task 1 | D21: 8 | E21: =ROUNDUP($D21*'Effort distribution'!$C$5/'Effort distribution'!$B$5,1) -> 5.4 | F21: =ROUNDUP($D21*'Effort distribution'!$D$5/'Effort distribution'!$B$5,1) -> 2.7 | G21: =ROUNDUP($D21*'Effort distribution'!$E$5/'Effort distribution'!$B$5,1) -> 2.7 | H21: =ROUNDUP($D21*'Effort distribution'!$F$5/'Effort distribution'!$B$5,1) -> 1.4 | I21: =ROUNDUP($D21*'Effort distribution'!$G$5/'Effort distribution'!$B$5,1) -> 1.4 | J21: =SUM(D21:I21) -> 21.6
A22: Feature 2 | B22: Function 2.1 | C22: Task 2 | D22: 5 | E22: =ROUNDUP($D22*'Effort distribution'!$C$5/'Effort distribution'!$B$5,1) -> 3.4 | F22: =ROUNDUP($D22*'Effort distribution'!$D$5/'Effort distribution'!$B$5,1) -> 1.7 | G22: =ROUNDUP($D22*'Effort distribution'!$E$5/'Effort distribution'!$B$5,1) -> 1.7 | H22: =ROUNDUP($D22*'Effort distribution'!$F$5/'Effort distribution'!$B$5,1) -> 0.9 | I22: =ROUNDUP($D22*'Effort distribution'!$G$5/'Effort distribution'!$B$5,1) -> 0.9 | J22: =SUM(D22:I22) -> 13.6
A23: Feature 2 | B23: Function 2.2 | C23: Task 1 | D23: 8 | E23: =ROUNDUP($D23*'Effort distribution'!$C$5/'Effort distribution'!$B$5,1) -> 5.4 | F23: =ROUNDUP($D23*'Effort distribution'!$D$5/'Effort distribution'!$B$5,1) -> 2.7 | G23: =ROUNDUP($D23*'Effort distribution'!$E$5/'Effort distribution'!$B$5,1) -> 2.7 | H23: =ROUNDUP($D23*'Effort distribution'!$F$5/'Effort distribution'!$B$5,1) -> 1.4 | I23: =ROUNDUP($D23*'Effort distribution'!$G$5/'Effort distribution'!$B$5,1) -> 1.4 | J23: =SUM(D23:I23) -> 21.6
A24: Feature 2 | B24: Function 2.2 | C24: Task 2 | D24: 8 | E24: =ROUNDUP($D24*'Effort distribution'!$C$5/'Effort distribution'!$B$5,1) -> 5.4 | F24: =ROUNDUP($D24*'Effort distribution'!$D$5/'Effort distribution'!$B$5,1) -> 2.7 | G24: =ROUNDUP($D24*'Effort distribution'!$E$5/'Effort distribution'!$B$5,1) -> 2.7 | H24: =ROUNDUP($D24*'Effort distribution'!$F$5/'Effort distribution'!$B$5,1) -> 1.4 | I24: =ROUNDUP($D24*'Effort distribution'!$G$5/'Effort distribution'!$B$5,1) -> 1.4 | J24: =SUM(D24:I24) -> 21.6
A25: Feature 3 | B25: Function 3.1 | C25: Task 1 | D25: 8 | E25: =ROUNDUP($D25*'Effort distribution'!$C$5/'Effort distribution'!$B$5,1) -> 5.4 | F25: =ROUNDUP($D25*'Effort distribution'!$D$5/'Effort distribution'!$B$5,1) -> 2.7 | G25: =ROUNDUP($D25*'Effort distribution'!$E$5/'Effort distribution'!$B$5,1) -> 2.7 | H25: =ROUNDUP($D25*'Effort distribution'!$F$5/'Effort distribution'!$B$5,1) -> 1.4 | I25: =ROUNDUP($D25*'Effort distribution'!$G$5/'Effort distribution'!$B$5,1) -> 1.4 | J25: =SUM(D25:I25) -> 21.6
A26: Feature 3 | B26: Function 3.1 | C26: Task 2 | D26: 8 | E26: =ROUNDUP($D26*'Effort distribution'!$C$5/'Effort distribution'!$B$5,1) -> 5.4 | F26: =ROUNDUP($D26*'Effort distribution'!$D$5/'Effort distribution'!$B$5,1) -> 2.7 | G26: =ROUNDUP($D26*'Effort distribution'!$E$5/'Effort distribution'!$B$5,1) -> 2.7 | H26: =ROUNDUP($D26*'Effort distribution'!$F$5/'Effort distribution'!$B$5,1) -> 1.4 | I26: =ROUNDUP($D26*'Effort distribution'!$G$5/'Effort distribution'!$B$5,1) -> 1.4 | J26: =SUM(D26:I26) -> 21.6
A27: Feature 3 | B27: Function 3.2 | C27: Task 1 | D27: 12 | E27: =ROUNDUP($D27*'Effort distribution'!$C$5/'Effort distribution'!$B$5,1) -> 8 | F27: =ROUNDUP($D27*'Effort distribution'!$D$5/'Effort distribution'!$B$5,1) -> 4 | G27: =ROUNDUP($D27*'Effort distribution'!$E$5/'Effort distribution'!$B$5,1) -> 4 | H27: =ROUNDUP($D27*'Effort distribution'!$F$5/'Effort distribution'!$B$5,1) -> 2 | I27: =ROUNDUP($D27*'Effort distribution'!$G$5/'Effort distribution'!$B$5,1) -> 2 | J27: =SUM(D27:I27) -> 32
A28: Feature 3 | B28: Function 3.2 | C28: Task 2 | D28: 12 | E28: =ROUNDUP($D28*'Effort distribution'!$C$5/'Effort distribution'!$B$5,1) -> 8 | F28: =ROUNDUP($D28*'Effort distribution'!$D$5/'Effort distribution'!$B$5,1) -> 4 | G28: =ROUNDUP($D28*'Effort distribution'!$E$5/'Effort distribution'!$B$5,1) -> 4 | H28: =ROUNDUP($D28*'Effort distribution'!$F$5/'Effort distribution'!$B$5,1) -> 2 | I28: =ROUNDUP($D28*'Effort distribution'!$G$5/'Effort distribution'!$B$5,1) -> 2 | J28: =SUM(D28:I28) -> 32
... A32: Feature 4 | B32: Function 4.2 | C32: Task 2 | D32: 12 | E32: =ROUNDUP($D32*'Effort distribution'!$C$5/'Effort distribution'!$B$5,1) -> 8 | F32: =ROUNDUP($D32*'Effort distribution'!$D$5/'Effort distribution'!$B$5,1) -> 4 | G32: =ROUNDUP($D32*'Effort distribution'!$E$5/'Effort distribution'!$B$5,1) -> 4 | H32: =ROUNDUP($D32*'Effort distribution'!$F$5/'Effort distribution'!$B$5,1) -> 2 | I32: =ROUNDUP($D32*'Effort distribution'!$G$5/'Effort distribution'!$B$5,1) -> 2 | J32: =SUM(D32:I32) -> 32
A33: Total | D33: =SUm(D17:D32) -> 133 | E33: =SUm(E17:E32) -> 89.2 | F33: =SUm(F17:F32) -> 44.8 | G33: =SUm(G17:G32) -> 44.8 | H33: =SUm(H17:H32) -> 22.7 | I33: =SUm(I17:I32) -> 22.7 | J33: =SUm(J17:J32) -> 357.2

Sheet Effort distribution
A1: Effort Distribution by process
A4: Process Name | B4: Coding | C4: Unit test | D4: Fixbug | E4: Specs | F4: Infra | G4: Management
A5: Distribution(%) | B5: 30 | C5: 20 | D5: 10 | E5: 10 | F5: 5 | G5: 5
