Workbook

Sheet History of changes
E1: PROJECT KPI DATA | J1: No: BM-QT-1706-01
J2: Version: 1.6
J3: Issue Date: 22/09/2026
A4: SUN ASTERISK VIETNAM CO., LTD | J4: ISO/IEC 27001:2013&ISO 9001:2015
A6: LỊCH SỬ THAY ĐỔI
A7: STT | B7: Mục thay đổi | E7: Nội dung | J7: Ngày thay đổi
A8: 1 | E8: Ban hành mới | J8: 15/05/2020
A9: 2 | E9: Sửa đổi: 2. Project information : thêm 2 trường Start date, End date 3. Weekly raw data: thêm 2 cột Start Phase, End Phase Thêm mới: 6. KPI analysis | J9: 31/8/2020
A10: 3 | E10: Sửa đổi: 1. Overview : Thay thế 7 chỉ số thành 6 chỉ số, điều chỉnh tiêu chuẩn của mỗi chỉ số 2. Weekly raw data: thêm mới tiêu chí :Spent time for fixing bug in a period of report (Hours) Quy đổi đơn vị tính effort từ manday thành man hour | J10: 44395
A11: 4 | E11: Update format | J11: 44320
A12: 5 | B12: Sheet Project Information | E12: Thay đổi Project Role theo thay đổi cơ cấu mới của tổ chức - Remove role SM, GL, PL - Add mới role PSM | J12: 44508
A13: 6 | B13: Overview Sheet | E13: Thay đổi công thức Estimation Accuracy - Modify (Total Actual Effort / Total Estimated Effort) * 100 | J13: 44580
A14: 7 | B14: Sheet Project Information Sheet Weekly raw data | E14: Sửa đổi: 2. Project information: thêm mới KPI Management Period. 3. Weekly raw data: thêm mới cột Phase dành cho những dự án quản lý KPI theo Phase. Thêm mới sheet: 4.2 Project Summary_By Phase: 5.2 Chart_By Phase | J14: 45614
A15: 8 | E15: Cập nhật Project role theo cơ cấu tổ chức mới của công ty: - PSM -> Project Leader (PL) - UM -> Software Delivery Manager (SDM) | J15: 19/12/2024
A16: 9 | B16: All sheet | E16: Update mã biểu mẫu theo tiêu chuẩn ISO. | J16: 22/09/2026

Sheet 1. Overview
C1: PROJECT KPI DATA | F1: No: BM-QT-1706-01
F2: Version: 1.6
F3: Issue Date: 22/09/2026
A4: SUN ASTERISK VIETNAM CO., LTD | F4: ISO/IEC 27001:2013&ISO 9001:2015
A6: I | B6: PURPOSE
A7: - | B7: Record KPI data of project.
A8: II | B8: SCOPE
B9: Apply to all of projects
A10: III | B10: REFERENCE MATERIAL
A11: ■ | B11: Sun* KPI System_Introduction
A13: IV | B13: CONTENT
A15: No. | B15: Metrics | C15: Calculation | D15: Unit | E15: Description | F15: Note
A16: 1 | B16: QA Bug Proportion (Q1) | C16: Internal Bug Count / Total Actual Effort [MH] | D16: Bug/Mh | E16: The bug implementation proportion before a delivery process comparing with the team's actual effort. Internal Bug Count: Bug count found by QAs in our test processes: Integration-test and System-test. Total Actual effort: Unit: Man-Hours Total spent time on some activities as below. UI Design System Design Implementation QA Testing Bug FixingRetestingetesthe t If teamRedminedmine (both old redmineRedminedmine Pherusa), the total actual effort is the sum of all spent time in the period of the report.
A17: 2 | B17: UAT Bug Rate (Q2) | C17: ( UAT Bug Count/ All Bug Count ) * 100 | D17: % | E17: The rate of bug in UAT comparing with all bugs found in some test processes: QA test and UAT test. UAT Bug Count: The bug count found in UAT phase. Usually this bugs are reported by our client. All Bug Count: Total bug count which involves QA bug and UAT bug.
A18: 3 | B18: Estimation Accuracy Rate (C1) | C18: ( Total Actual Effort / Total Estimated Effort ) * 100 | D18: % | E18: Show the deviation of the actual actual effort compared to the estimated effort. Based on which to evaluate the efficiency of resource use in the project. - The unit of effort is hour.
A19: 4 | B19: Bug Handling Cost Rate (C2) | C19: ( Total Bug Handling Effort / Total Actual Effort ) * 100 | D19: % | E19: Show how much effort was spent for bug fixing and re-testing. Total Bug Handling Effort: Unit: Hour Bug fixing effort [h] + QA Re-testing effort [h] Total Actual Effort: Unit: Hour Total spent time recorded as actual activity effort. Need to adjust activity expression to meet with other metrics' one.
A20: 5 | B20: Issue Closed Ratio (M1) | C20: (Closed Issue Count / All Issue Count)*100 | D20: %
A23: ■ | B23: Sheet [Project Information] Ghi nhận những thông tin chung của dự án vào Sheet Project Information. *Lưu ý: Nếu dự án Release theo từng Phase, PL cần cung cấp thông tin KPI Management Period: By Phase để các sheet (4.2 Project Summary_By Phase, 5.2 Chart_By Phase) lên dữ liệu đúng với đặc thù dự án.
A24: ■ | B24: Sheet [Weekly raw data sheet] - Hàng tuần, PL/BrSe/Teamleader dự án cập nhật raw data của dự án vào sheet này.
A25: ■ | B25: Sheet [Project Summary] - Từ dữ liệu được chủ động cập nhật trong [Weekly raw data] Sheet , các chỉ số sẽ được tự động ghi nhận vào [Project Summary] Sheet này theo công thức đã được định sẵn. - Đối với dự án quản lý Release theo Sprint. các chỉ số KPI sẽ tự động ghi nhận vào 4.1 Project Summary_Sprint. - Đối với dự án quản lý Release theo Phase, các chỉ số KPI sẽ tự động ghi nhận đồng thời tại 4.1 Project Summary_Sprint. và 4.2 Project Summary_By Phase.
A26: ■ | B26: Sheet [Chart] - Theo dõi xu hướng dự án theo các kỳ báo cáo để nhìn được những phản ánh từ data trong kỳ báo cáo đó. Gồm 5.1 Chart_By Sprint và 5.2 Chart_By Phase - Từ đó đưa ra giải pháp, hành động hoặc cần có sự tham gia các cấp lãnh đạo( trong trường hợp cần thiết)
B27: Chỉ số Upper Control Limit(UCL) và Lower Control Limit(LCL), Target đã được Công ty tính toán, thống kê, chọn lựa thông qua dữ liệu của năm 2020 - Data của các tuần nếu nằm ngoài dải UCL/LCL sẽ cần phân tích và đưa ra action phù hợp( Nếu có)
A28: No. | B28: KPI metric | C28: Unit | D28: UCL | E28: Target | F28: LCL
A29: 1 | B29: Q1 QA Bug Proportion | C29: Bug/Md | D29: 0.5 | E29: 0.05 | F29: 0
A30: 2 | B30: Q2 UAT Bug Rate | C30: % | D30: 20 | E30: 5 | F30: 0
A31: 3 | B31: C1 Estimation Accuracy Rate | C31: % | D31: 115 | E31: 100 | F31: 85
A32: 4 | B32: C2 Bug Handling Cost Rate | C32: % | D32: 20 | E32: 10 | F32: 5
A33: 5 | B33: M1 Issue Closed Ratio | C33: % | D33: 110 | E33: 100 | F33: 90

Sheet 2. Project information 
B1: PROJECT KPI DATA | G1: No: BM-QT-1706-01
G2: Version: 1.6
G3: Issue Date: 22/09/2026
A4: SUN ASTERISK VIETNAM CO., LTD | G4: ISO/IEC 27001:2013&ISO 9001:2015
A6: Project name
A7: CEV Center
A8: PL
A9: Team Leader
A10: Customer
A11: Status
A12: Category | B12: Development
A13: KPI Management Period | B13: By Phase
A14: Team Size
A15: Description
A16: Start Date
A17: End Date

Sheet 3. Weekly raw data
C1: PROJECT KPI DATA | M1: No: BM-QT-1706-01
M2: Version: 1.6
M3: Issue Date: 22/09/2026
A4: SUN ASTERISK VIETNAM CO., LTD | M4: ISO/IEC 27001:2013&ISO 9001:2015
A6: Phase | B6: Sprint | C6: Start date | D6: End date | E6: Q (Quality) Number of Internal QA bug in a period of report | F6: Q (Quality) Number of Bug found in UAT phase in a period of report | G6: C (Cost): Spent time in your project in a period of report (Hours) | H6: C (Cost): Estimated time in your project in a period of report (Hours) | I6: C (Cost) Spent time for fixing bug in a period of report (Hours) | J6: M(Management) Number of ticket closed in a period of report | K6: M(Management) Number of total ticket in a period of report | L6: Other: If your project want to measure 1 or more other KPIs instead of company required ones, please record your idea here. Then PEC team will contact you to make clear your idea. | M6: Which application do you report to? (Web, Mobile App, General) | N6: Note
C7: 7
A8: 1 | B8: 1 | C8: 45358 | D8: =C8+C7-1 -> 45364 | E8: 0 | F8: 0 | G8: 200 | H8: 200 | I8: 0 | J8: 7 | K8: 10 | M8: Web
A9: 2 | B9: 2 | C9: =$C8+$C$7 -> 45365 | D9: =D8+$C$7 -> 45371 | E9: 100 | F9: 0 | G9: 260 | H9: 260 | I9: 4 | J9: 21 | K9: 22
A10: 2 | B10: 3 | C10: =$C9+$C$7 -> 45372 | D10: =D9+$C$7 -> 45378 | E10: 1 | F10: 0 | G10: 320 | H10: 320 | I10: 120 | J10: 15 | K10: 17
A11: 2 | B11: 4 | C11: =$C10+$C$7 -> 45379 | D11: =D10+$C$7 -> 45385 | E11: 20 | F11: 0 | G11: 120 | H11: 100 | I11: 210 | J11: 26 | K11: 26
A12: 2 | B12: 5 | C12: =$C11+$C$7 -> 45386 | D12: =D11+$C$7 -> 45392 | E12: 1 | F12: 5 | G12: 11 | H12: 30 | I12: 111 | J12: 17 | K12: 18
A13: 2 | B13: 6 | C13: =$C12+$C$7 -> 45393 | D13: =D12+$C$7 -> 45399 | E13: 1 | F13: 10 | G13: 120 | H13: 150 | I13: 30 | J13: 20 | K13: 20
A14: 2 | B14: 7 | C14: =$C13+$C$7 -> 45400 | D14: =D13+$C$7 -> 45406 | E14: 1 | F14: 0 | G14: 29 | H14: 27 | I14: 0 | J14: 12 | K14: 12
A15: 2 | B15: 8 | C15: =$C14+$C$7 -> 45407 | D15: 45420 | E15: 0 | F15: 0 | G15: 33.5 | H15: 34.5 | I15: 0 | J15: 14 | K15: 15
A16: 2 | B16: 9 | C16: 45420 | D16: =D15+$C$7 -> 45427 | E16: 1 | F16: 0 | G16: 38.5 | H16: 34 | I16: 2 | J16: 14 | K16: 16
A17: 2 | B17: 10 | C17: =$C16+$C$7 -> 45427 | D17: =D16+$C$7 -> 45434 | E17: 0 | F17: 0 | G17: 34.5 | H17: 35.5 | I17: 0 | J17: 12 | K17: 12
A18: 2 | B18: 11 | C18: =$C17+$C$7 -> 45434 | D18: =D17+$C$7 -> 45441 | E18: 0 | F18: 0 | G18: 29.5 | H18: 33 | I18: 0 | J18: 16 | K18: 16
A19: 3 | B19: 12 | C19: =$C18+$C$7 -> 45441 | D19: =D18+$C$7 -> 45448 | E19: 1 | F19: 0 | G19: 27 | H19: 29 | I19: 2 | J19: 12 | K19: 13
A20: 3 | B20: 13 | C20: =$C19+$C$7 -> 45448 | D20: =D19+$C$7 -> 45455 | E20: 1 | F20: 0 | G20: 33.5 | H20: 35 | I20: 1 | J20: 16 | K20: 16
A21: 3 | B21: 14 | C21: =$C20+$C$7 -> 45455 | D21: =D20+$C$7 -> 45462 | E21: 0 | F21: 0 | G21: 31.5 | H21: 31.5 | I21: 0 | J21: 15 | K21: 15
A22: 3 | B22: 15 | C22: =$C21+$C$7 -> 45462 | D22: =D21+$C$7 -> 45469 | E22: 0 | F22: 0 | G22: 28.5 | H22: 27 | I22: 0 | J22: 9 | K22: 9
A23: 3 | B23: 16 | C23: =$C22+$C$7 -> 45469 | D23: =D22+$C$7 -> 45476 | E23: 0 | F23: 0 | G23: 28 | H23: 28.5 | I23: 0 | J23: 13 | K23: 13
A24: 3 | B24: 17 | C24: =$C23+$C$7 -> 45476 | D24: =D23+$C$7 -> 45483 | E24: 0 | F24: 0 | G24: 42.5 | H24: 39 | I24: 0 | J24: 14 | K24: 14
A25: 3 | B25: 18 | C25: =$C24+$C$7 -> 45483 | D25: =D24+$C$7 -> 45490 | E25: 3 | F25: 0 | G25: 28 | H25: 29 | I25: 5 | J25: 14 | K25: 14
A26: 3 | B26: 19 | C26: =$C25+$C$7 -> 45490 | D26: =D25+$C$7 -> 45497 | E26: 3 | F26: 0 | G26: 32.5 | H26: 29.5 | I26: 4 | J26: 12 | K26: 14
A27: 3 | B27: 20 | C27: =$C26+$C$7 -> 45497 | D27: 45505 | E27: 1 | F27: 0 | G27: 36 | H27: 38.5 | I27: 1 | J27: 20 | K27: 20
A28: 3 | B28: 21 | C28: 45505 | D28: 45518 | E28: 2 | F28: 0 | G28: 52 | H28: 46.5 | I28: 3.5 | J28: 22 | K28: 25
A29: 3 | B29: 22 | C29: 45518 | D29: =D28+$C$7 -> 45525 | E29: 3 | F29: 0 | G29: 40 | H29: 35 | I29: 3.5 | J29: 19 | K29: 19
A30: 3 | B30: 23 | C30: =$C29+$C$7 -> 45525 | D30: =D29+$C$7 -> 45532 | E30: 2 | F30: 0 | G30: 39 | H30: 36.5 | I30: 7 | J30: 17 | K30: 17
A31: 4 | B31: 24 | C31: =$C30+$C$7 -> 45532 | D31: =D30+$C$7 -> 45539 | E31: 0 | F31: 0 | G31: 7 | H31: 21 | I31: 0 | J31: 5 | K31: 12
A32: 4 | B32: 25 | C32: =$C31+$C$7 -> 45539 | D32: =D31+$C$7 -> 45546 | E32: 0 | F32: 0 | G32: 40.5 | H32: 36 | I32: 0 | J32: 18 | K32: 18
A33: 4 | B33: 26 | C33: =$C32+$C$7 -> 45546 | D33: =D32+$C$7 -> 45553 | E33: 3 | F33: 0 | G33: 36 | H33: 40 | I33: 7 | J33: 16 | K33: 18
A34: 4 | B34: 27 | C34: =$C33+$C$7 -> 45553 | D34: =D33+$C$7 -> 45560 | E34: 3 | F34: 0 | G34: 37 | H34: 40 | I34: 7 | J34: 14 | K34: 15
A35: 4 | B35: 28 | C35: =$C34+$C$7 -> 45560 | D35: =D34+$C$7 -> 45567 | E35: 0 | F35: 0 | G35: 200 | H35: 200 | I35: 0 | J35: 7 | K35: 10
A36: 4 | B36: 29 | C36: =$C35+$C$7 -> 45567 | D36: =D35+$C$7 -> 45574 | E36: 100 | F36: 0 | G36: 260 | H36: 260 | I36: 4 | J36: 21 | K36: 22
A37: 4 | B37: 30 | C37: =$C36+$C$7 -> 45574 | D37: =D36+$C$7 -> 45581 | E37: 1 | F37: 0 | G37: 320 | H37: 320 | I37: 120 | J37: 15 | K37: 17
A38: 4 | B38: 31 | C38: =$C37+$C$7 -> 45581 | D38: =D37+$C$7 -> 45588
A39: 5 | B39: 32 | C39: =$C38+$C$7 -> 45588 | D39: =D38+$C$7 -> 45595
A40: 5 | B40: 33 | C40: =$C39+$C$7 -> 45595 | D40: =D39+$C$7 -> 45602
A41: 5 | B41: 34 | C41: =$C40+$C$7 -> 45602 | D41: =D40+$C$7 -> 45609
...

Sheet 4.1 Project Summary_Sprint
C1: Project KPI Data | I1: No: BM-QT-1706-01
I2: Version: 1.6
I3: Issue Date: 22/09/2026
A4: SUN ASTERISK VIETNAM CO., LTD | I4: ISO/IEC 27001:2013&ISO 9001:2015
A6: Sprint | B6: Start phase | C6: End phase | D6: QA Bug Proportion (Q1) #/Mh Internal Bug Count / Total Actual Effort [MH] | E6: UAT Bug Rate (Q2)% ( UAT Bug Count/ All Bug Count ) * 100 | F6: Estimation Accuracy Rate (C1)% ( Total Actual Effort / Total Estimated Effort ) * 100 | G6: Bug Handling Cost Rate (C2)% ( Total Bug Handling Effort / Total Actual Effort ) * 100 | H6: Issue Closed Ratio (M1)% (Closed Issue Count / All Issue Count)*100 | I6: Note
A7: 1 | B7: ='3. Weekly raw data'!C8 -> 45358 | C7: ='3. Weekly raw data'!D8 -> 45364 | D7: =VLOOKUP(A7,'3. Weekly raw data'!$B$8:$N$50,4,0)/(VLOOKUP(A7,'3. Weekly raw data'!$B$8:$N$50,6,0)) -> 0 | E7: =Iferror(VLOOKUP(A7,'3. Weekly raw data'!$B$8:$N$50,5,0)/(VLOOKUP(A7,'3. Weekly raw data'!$B$8:$N$50,4,0)+VLOOKUP(A7,'3. Weekly raw data'!$B$8:$N$50,5,0)),"") | F7: =(VLOOKUP(A7,'3. Weekly raw data'!$B$8:$N$50,6,0)/VLOOKUP(A7,'3. Weekly raw data'!$B$8:$N$50,7,0)*100) -> 100 | G7: =(VLOOKUP(A7,'3. Weekly raw data'!$B$8:$N$50,8,0)/VLOOKUP(A7,'3. Weekly raw data'!$B$8:$N$50,6,0)*100) -> 0 | H7: =VLOOKUP(A7,'3. Weekly raw data'!$B$8:$N$50,9,0)/VLOOKUP(A7,'3. Weekly raw data'!$B$8:$N$50,10,0)*100 -> 70 | I7: Because one ticket was waiting for the client to review the PR, another ticket was waiting for stakeholders to respond, and three other tickets were awaiting review by a team member who was off that day.
A8: 2 | B8: ='3. Weekly raw data'!C9 -> 45365 | C8: ='3. Weekly raw data'!D9 -> 45371 | D8: =VLOOKUP(A8,'3. Weekly raw data'!$B$8:$N$50,4,0)/(VLOOKUP(A8,'3. Weekly raw data'!$B$8:$N$50,6,0)) -> 0.38461538 | E8: =Iferror(VLOOKUP(A8,'3. Weekly raw data'!$B$8:$N$50,5,0)/(VLOOKUP(A8,'3. Weekly raw data'!$B$8:$N$50,4,0)+VLOOKUP(A8,'3. Weekly raw data'!$B$8:$N$50,5,0)),"") -> 0 | F8: =(VLOOKUP(A8,'3. Weekly raw data'!$B$8:$N$50,6,0)/VLOOKUP(A8,'3. Weekly raw data'!$B$8:$N$50,7,0)*100) -> 100 | G8: =(VLOOKUP(A8,'3. Weekly raw data'!$B$8:$N$50,8,0)/VLOOKUP(A8,'3. Weekly raw data'!$B$8:$N$50,6,0)*100) -> 1.5384615 | H8: =VLOOKUP(A8,'3. Weekly raw data'!$B$8:$N$50,9,0)/VLOOKUP(A8,'3. Weekly raw data'!$B$8:$N$50,10,0)*100 -> 95.454545
A9: 3 | B9: ='3. Weekly raw data'!C10 -> 45372 | C9: ='3. Weekly raw data'!D10 -> 45378 | D9: =VLOOKUP(A9,'3. Weekly raw data'!$B$8:$N$50,4,0)/(VLOOKUP(A9,'3. Weekly raw data'!$B$8:$N$50,6,0)) -> 0.003125 | E9: =Iferror(VLOOKUP(A9,'3. Weekly raw data'!$B$8:$N$50,5,0)/(VLOOKUP(A9,'3. Weekly raw data'!$B$8:$N$50,4,0)+VLOOKUP(A9,'3. Weekly raw data'!$B$8:$N$50,5,0)),"") -> 0 | F9: =(VLOOKUP(A9,'3. Weekly raw data'!$B$8:$N$50,6,0)/VLOOKUP(A9,'3. Weekly raw data'!$B$8:$N$50,7,0)*100) -> 100 | G9: =(VLOOKUP(A9,'3. Weekly raw data'!$B$8:$N$50,8,0)/VLOOKUP(A9,'3. Weekly raw data'!$B$8:$N$50,6,0)*100) -> 37.5 | H9: =VLOOKUP(A9,'3. Weekly raw data'!$B$8:$N$50,9,0)/VLOOKUP(A9,'3. Weekly raw data'!$B$8:$N$50,10,0)*100 -> 88.235294 | I9: In this sprint, one of our team members took 2 days off. When he returned to work, there were a lot of investigation reports and pull requests for him to review. These tasks took up his time and hindered him from handling the implementation tasks. Another reason is that the engineers spent time discussing the requirements of a new user story.
A10: 4 | B10: ='3. Weekly raw data'!C11 -> 45379 | C10: ='3. Weekly raw data'!D11 -> 45385 | D10: =VLOOKUP(A10,'3. Weekly raw data'!$B$8:$N$50,4,0)/(VLOOKUP(A10,'3. Weekly raw data'!$B$8:$N$50,6,0)) -> 0.16666667 | E10: =Iferror(VLOOKUP(A10,'3. Weekly raw data'!$B$8:$N$50,5,0)/(VLOOKUP(A10,'3. Weekly raw data'!$B$8:$N$50,4,0)+VLOOKUP(A10,'3. Weekly raw data'!$B$8:$N$50,5,0)),"") -> 0 | F10: =(VLOOKUP(A10,'3. Weekly raw data'!$B$8:$N$50,6,0)/VLOOKUP(A10,'3. Weekly raw data'!$B$8:$N$50,7,0)*100) -> 120 | G10: =(VLOOKUP(A10,'3. Weekly raw data'!$B$8:$N$50,8,0)/VLOOKUP(A10,'3. Weekly raw data'!$B$8:$N$50,6,0)*100) -> 175 | H10: =VLOOKUP(A10,'3. Weekly raw data'!$B$8:$N$50,9,0)/VLOOKUP(A10,'3. Weekly raw data'!$B$8:$N$50,10,0)*100 -> 100
A11: 5 | B11: ='3. Weekly raw data'!C12 -> 45386 | C11: ='3. Weekly raw data'!D12 -> 45392 | D11: =VLOOKUP(A11,'3. Weekly raw data'!$B$8:$N$50,4,0)/(VLOOKUP(A11,'3. Weekly raw data'!$B$8:$N$50,6,0)) -> 0.090909091 | E11: =Iferror(VLOOKUP(A11,'3. Weekly raw data'!$B$8:$N$50,5,0)/(VLOOKUP(A11,'3. Weekly raw data'!$B$8:$N$50,4,0)+VLOOKUP(A11,'3. Weekly raw data'!$B$8:$N$50,5,0)),"") -> 0.83333333 | F11: =(VLOOKUP(A11,'3. Weekly raw data'!$B$8:$N$50,6,0)/VLOOKUP(A11,'3. Weekly raw data'!$B$8:$N$50,7,0)*100) -> 36.666667 | G11: =(VLOOKUP(A11,'3. Weekly raw data'!$B$8:$N$50,8,0)/VLOOKUP(A11,'3. Weekly raw data'!$B$8:$N$50,6,0)*100) -> 1009.0909 | H11: =VLOOKUP(A11,'3. Weekly raw data'!$B$8:$N$50,9,0)/VLOOKUP(A11,'3. Weekly raw data'!$B$8:$N$50,10,0)*100 -> 94.444444
A12: 6 | B12: ='3. Weekly raw data'!C13 -> 45393 | C12: ='3. Weekly raw data'!D13 -> 45399 | D12: =VLOOKUP(A12,'3. Weekly raw data'!$B$8:$N$50,4,0)/(VLOOKUP(A12,'3. Weekly raw data'!$B$8:$N$50,6,0)) -> 0.0083333333 | E12: =Iferror(VLOOKUP(A12,'3. Weekly raw data'!$B$8:$N$50,5,0)/(VLOOKUP(A12,'3. Weekly raw data'!$B$8:$N$50,4,0)+VLOOKUP(A12,'3. Weekly raw data'!$B$8:$N$50,5,0)),"") -> 0.90909091 | F12: =(VLOOKUP(A12,'3. Weekly raw data'!$B$8:$N$50,6,0)/VLOOKUP(A12,'3. Weekly raw data'!$B$8:$N$50,7,0)*100) -> 80 | G12: =(VLOOKUP(A12,'3. Weekly raw data'!$B$8:$N$50,8,0)/VLOOKUP(A12,'3. Weekly raw data'!$B$8:$N$50,6,0)*100) -> 25 | H12: =VLOOKUP(A12,'3. Weekly raw data'!$B$8:$N$50,9,0)/VLOOKUP(A12,'3. Weekly raw data'!$B$8:$N$50,10,0)*100 -> 100
A13: 7 | B13: ='3. Weekly raw data'!C14 -> 45400 | C13: ='3. Weekly raw data'!D14 -> 45406 | D13: =VLOOKUP(A13,'3. Weekly raw data'!$B$8:$N$50,4,0)/(VLOOKUP(A13,'3. Weekly raw data'!$B$8:$N$50,6,0)) -> 0.034482759 | E13: =Iferror(VLOOKUP(A13,'3. Weekly raw data'!$B$8:$N$50,5,0)/(VLOOKUP(A13,'3. Weekly raw data'!$B$8:$N$50,4,0)+VLOOKUP(A13,'3. Weekly raw data'!$B$8:$N$50,5,0)),"") -> 0 | F13: =(VLOOKUP(A13,'3. Weekly raw data'!$B$8:$N$50,6,0)/VLOOKUP(A13,'3. Weekly raw data'!$B$8:$N$50,7,0)*100) -> 107.40741 | G13: =(VLOOKUP(A13,'3. Weekly raw data'!$B$8:$N$50,8,0)/VLOOKUP(A13,'3. Weekly raw data'!$B$8:$N$50,6,0)*100) -> 0 | H13: =VLOOKUP(A13,'3. Weekly raw data'!$B$8:$N$50,9,0)/VLOOKUP(A13,'3. Weekly raw data'!$B$8:$N$50,10,0)*100 -> 100
A14: 8 | B14: ='3. Weekly raw data'!C15 -> 45407 | C14: ='3. Weekly raw data'!D15 -> 45420 | D14: =VLOOKUP(A14,'3. Weekly raw data'!$B$8:$N$50,4,0)/(VLOOKUP(A14,'3. Weekly raw data'!$B$8:$N$50,6,0)) -> 0 | E14: =Iferror(VLOOKUP(A14,'3. Weekly raw data'!$B$8:$N$50,5,0)/(VLOOKUP(A14,'3. Weekly raw data'!$B$8:$N$50,4,0)+VLOOKUP(A14,'3. Weekly raw data'!$B$8:$N$50,5,0)),"") | F14: =(VLOOKUP(A14,'3. Weekly raw data'!$B$8:$N$50,6,0)/VLOOKUP(A14,'3. Weekly raw data'!$B$8:$N$50,7,0)*100) -> 97.101449 | G14: =(VLOOKUP(A14,'3. Weekly raw data'!$B$8:$N$50,8,0)/VLOOKUP(A14,'3. Weekly raw data'!$B$8:$N$50,6,0)*100) -> 0 | H14: =VLOOKUP(A14,'3. Weekly raw data'!$B$8:$N$50,9,0)/VLOOKUP(A14,'3. Weekly raw data'!$B$8:$N$50,10,0)*100 -> 93.333333
A15: 9 | B15: ='3. Weekly raw data'!C16 -> 45420 | C15: ='3. Weekly raw data'!D16 -> 45427 | D15: =VLOOKUP(A15,'3. Weekly raw data'!$B$8:$N$50,4,0)/(VLOOKUP(A15,'3. Weekly raw data'!$B$8:$N$50,6,0)) -> 0.025974026 | E15: =Iferror(VLOOKUP(A15,'3. Weekly raw data'!$B$8:$N$50,5,0)/(VLOOKUP(A15,'3. Weekly raw data'!$B$8:$N$50,4,0)+VLOOKUP(A15,'3. Weekly raw data'!$B$8:$N$50,5,0)),"") -> 0 | F15: =(VLOOKUP(A15,'3. Weekly raw data'!$B$8:$N$50,6,0)/VLOOKUP(A15,'3. Weekly raw data'!$B$8:$N$50,7,0)*100) -> 113.23529 | G15: =(VLOOKUP(A15,'3. Weekly raw data'!$B$8:$N$50,8,0)/VLOOKUP(A15,'3. Weekly raw data'!$B$8:$N$50,6,0)*100) -> 5.1948052 | H15: =VLOOKUP(A15,'3. Weekly raw data'!$B$8:$N$50,9,0)/VLOOKUP(A15,'3. Weekly raw data'!$B$8:$N$50,10,0)*100 -> 87.5 | I15: During this sprint, there were some investigation tickets related to new pages and features that the team had not encountered before. This is why the investigation took longer than expected.
A16: 10 | B16: ='3. Weekly raw data'!C17 -> 45427 | C16: ='3. Weekly raw data'!D17 -> 45434 | D16: =VLOOKUP(A16,'3. Weekly raw data'!$B$8:$N$50,4,0)/(VLOOKUP(A16,'3. Weekly raw data'!$B$8:$N$50,6,0)) -> 0 | E16: =Iferror(VLOOKUP(A16,'3. Weekly raw data'!$B$8:$N$50,5,0)/(VLOOKUP(A16,'3. Weekly raw data'!$B$8:$N$50,4,0)+VLOOKUP(A16,'3. Weekly raw data'!$B$8:$N$50,5,0)),"") | F16: =(VLOOKUP(A16,'3. Weekly raw data'!$B$8:$N$50,6,0)/VLOOKUP(A16,'3. Weekly raw data'!$B$8:$N$50,7,0)*100) -> 97.183099 | G16: =(VLOOKUP(A16,'3. Weekly raw data'!$B$8:$N$50,8,0)/VLOOKUP(A16,'3. Weekly raw data'!$B$8:$N$50,6,0)*100) -> 0 | H16: =VLOOKUP(A16,'3. Weekly raw data'!$B$8:$N$50,9,0)/VLOOKUP(A16,'3. Weekly raw data'!$B$8:$N$50,10,0)*100 -> 100
A17: 11 | B17: ='3. Weekly raw data'!C18 -> 45434 | C17: ='3. Weekly raw data'!D18 -> 45441 | D17: =VLOOKUP(A17,'3. Weekly raw data'!$B$8:$N$50,4,0)/(VLOOKUP(A17,'3. Weekly raw data'!$B$8:$N$50,6,0)) -> 0 | E17: =Iferror(VLOOKUP(A17,'3. Weekly raw data'!$B$8:$N$50,5,0)/(VLOOKUP(A17,'3. Weekly raw data'!$B$8:$N$50,4,0)+VLOOKUP(A17,'3. Weekly raw data'!$B$8:$N$50,5,0)),"") | F17: =(VLOOKUP(A17,'3. Weekly raw data'!$B$8:$N$50,6,0)/VLOOKUP(A17,'3. Weekly raw data'!$B$8:$N$50,7,0)*100) -> 89.393939 | G17: =(VLOOKUP(A17,'3. Weekly raw data'!$B$8:$N$50,8,0)/VLOOKUP(A17,'3. Weekly raw data'!$B$8:$N$50,6,0)*100) -> 0 | H17: =VLOOKUP(A17,'3. Weekly raw data'!$B$8:$N$50,9,0)/VLOOKUP(A17,'3. Weekly raw data'!$B$8:$N$50,10,0)*100 -> 100
A18: 12 | B18: ='3. Weekly raw data'!C19 -> 45441 | C18: ='3. Weekly raw data'!D19 -> 45448 | D18: =VLOOKUP(A18,'3. Weekly raw data'!$B$8:$N$50,4,0)/(VLOOKUP(A18,'3. Weekly raw data'!$B$8:$N$50,6,0)) -> 0.037037037 | E18: =Iferror(VLOOKUP(A18,'3. Weekly raw data'!$B$8:$N$50,5,0)/(VLOOKUP(A18,'3. Weekly raw data'!$B$8:$N$50,4,0)+VLOOKUP(A18,'3. Weekly raw data'!$B$8:$N$50,5,0)),"") -> 0 | F18: =(VLOOKUP(A18,'3. Weekly raw data'!$B$8:$N$50,6,0)/VLOOKUP(A18,'3. Weekly raw data'!$B$8:$N$50,7,0)*100) -> 93.103448 | G18: =(VLOOKUP(A18,'3. Weekly raw data'!$B$8:$N$50,8,0)/VLOOKUP(A18,'3. Weekly raw data'!$B$8:$N$50,6,0)*100) -> 7.4074074 | H18: =VLOOKUP(A18,'3. Weekly raw data'!$B$8:$N$50,9,0)/VLOOKUP(A18,'3. Weekly raw data'!$B$8:$N$50,10,0)*100 -> 92.307692
A19: 13 | B19: ='3. Weekly raw data'!C20 -> 45448 | C19: ='3. Weekly raw data'!D20 -> 45455 | D19: =VLOOKUP(A19,'3. Weekly raw data'!$B$8:$N$50,4,0)/(VLOOKUP(A19,'3. Weekly raw data'!$B$8:$N$50,6,0)) -> 0.029850746 | E19: =Iferror(VLOOKUP(A19,'3. Weekly raw data'!$B$8:$N$50,5,0)/(VLOOKUP(A19,'3. Weekly raw data'!$B$8:$N$50,4,0)+VLOOKUP(A19,'3. Weekly raw data'!$B$8:$N$50,5,0)),"") -> 0 | F19: =(VLOOKUP(A19,'3. Weekly raw data'!$B$8:$N$50,6,0)/VLOOKUP(A19,'3. Weekly raw data'!$B$8:$N$50,7,0)*100) -> 95.714286 | G19: =(VLOOKUP(A19,'3. Weekly raw data'!$B$8:$N$50,8,0)/VLOOKUP(A19,'3. Weekly raw data'!$B$8:$N$50,6,0)*100) -> 2.9850746 | H19: =VLOOKUP(A19,'3. Weekly raw data'!$B$8:$N$50,9,0)/VLOOKUP(A19,'3. Weekly raw data'!$B$8:$N$50,10,0)*100 -> 100
A20: 14 | B20: ='3. Weekly raw data'!C21 -> 45455 | C20: ='3. Weekly raw data'!D21 -> 45462 | D20: =VLOOKUP(A20,'3. Weekly raw data'!$B$8:$N$50,4,0)/(VLOOKUP(A20,'3. Weekly raw data'!$B$8:$N$50,6,0)) -> 0 | E20: =Iferror(VLOOKUP(A20,'3. Weekly raw data'!$B$8:$N$50,5,0)/(VLOOKUP(A20,'3. Weekly raw data'!$B$8:$N$50,4,0)+VLOOKUP(A20,'3. Weekly raw data'!$B$8:$N$50,5,0)),"") | F20: =(VLOOKUP(A20,'3. Weekly raw data'!$B$8:$N$50,6,0)/VLOOKUP(A20,'3. Weekly raw data'!$B$8:$N$50,7,0)*100) -> 100 | G20: =(VLOOKUP(A20,'3. Weekly raw data'!$B$8:$N$50,8,0)/VLOOKUP(A20,'3. Weekly raw data'!$B$8:$N$50,6,0)*100) -> 0 | H20: =VLOOKUP(A20,'3. Weekly raw data'!$B$8:$N$50,9,0)/VLOOKUP(A20,'3. Weekly raw data'!$B$8:$N$50,10,0)*100 -> 100
A21: 15 | B21: ='3. Weekly raw data'!C22 -> 45462 | C21: ='3. Weekly raw data'!D22 -> 45469 | D21: =VLOOKUP(A21,'3. Weekly raw data'!$B$8:$N$50,4,0)/(VLOOKUP(A21,'3. Weekly raw data'!$B$8:$N$50,6,0)) -> 0 | E21: =Iferror(VLOOKUP(A21,'3. Weekly raw data'!$B$8:$N$50,5,0)/(VLOOKUP(A21,'3. Weekly raw data'!$B$8:$N$50,4,0)+VLOOKUP(A21,'3. Weekly raw data'!$B$8:$N$50,5,0)),"") | F21: =(VLOOKUP(A21,'3. Weekly raw data'!$B$8:$N$50,6,0)/VLOOKUP(A21,'3. Weekly raw data'!$B$8:$N$50,7,0)*100) -> 105.55556 | G21: =(VLOOKUP(A21,'3. Weekly raw data'!$B$8:$N$50,8,0)/VLOOKUP(A21,'3. Weekly raw data'!$B$8:$N$50,6,0)*100) -> 0 | H21: =VLOOKUP(A21,'3. Weekly raw data'!$B$8:$N$50,9,0)/VLOOKUP(A21,'3. Weekly raw data'!$B$8:$N$50,10,0)*100 -> 100
A22: 16 | B22: ='3. Weekly raw data'!C23 -> 45469 | C22: ='3. Weekly raw data'!D23 -> 45476 | D22: =VLOOKUP(A22,'3. Weekly raw data'!$B$8:$N$50,4,0)/(VLOOKUP(A22,'3. Weekly raw data'!$B$8:$N$50,6,0)) -> 0 | E22: =Iferror(VLOOKUP(A22,'3. Weekly raw data'!$B$8:$N$50,5,0)/(VLOOKUP(A22,'3. Weekly raw data'!$B$8:$N$50,4,0)+VLOOKUP(A22,'3. Weekly raw data'!$B$8:$N$50,5,0)),"") | F22: =(VLOOKUP(A22,'3. Weekly raw data'!$B$8:$N$50,6,0)/VLOOKUP(A22,'3. Weekly raw data'!$B$8:$N$50,7,0)*100) -> 98.245614 | G22: =(VLOOKUP(A22,'3. Weekly raw data'!$B$8:$N$50,8,0)/VLOOKUP(A22,'3. Weekly raw data'!$B$8:$N$50,6,0)*100) -> 0 | H22: =VLOOKUP(A22,'3. Weekly raw data'!$B$8:$N$50,9,0)/VLOOKUP(A22,'3. Weekly raw data'!$B$8:$N$50,10,0)*100 -> 100
A23: 17 | B23: ='3. Weekly raw data'!C24 -> 45476 | C23: ='3. Weekly raw data'!D24 -> 45483 | D23: =VLOOKUP(A23,'3. Weekly raw data'!$B$8:$N$50,4,0)/(VLOOKUP(A23,'3. Weekly raw data'!$B$8:$N$50,6,0)) -> 0 | E23: =Iferror(VLOOKUP(A23,'3. Weekly raw data'!$B$8:$N$50,5,0)/(VLOOKUP(A23,'3. Weekly raw data'!$B$8:$N$50,4,0)+VLOOKUP(A23,'3. Weekly raw data'!$B$8:$N$50,5,0)),"") | F23: =(VLOOKUP(A23,'3. Weekly raw data'!$B$8:$N$50,6,0)/VLOOKUP(A23,'3. Weekly raw data'!$B$8:$N$50,7,0)*100) -> 108.97436 | G23: =(VLOOKUP(A23,'3. Weekly raw data'!$B$8:$N$50,8,0)/VLOOKUP(A23,'3. Weekly raw data'!$B$8:$N$50,6,0)*100) -> 0 | H23: =VLOOKUP(A23,'3. Weekly raw data'!$B$8:$N$50,9,0)/VLOOKUP(A23,'3. Weekly raw data'!$B$8:$N$50,10,0)*100 -> 100
A24: 18 | B24: ='3. Weekly raw data'!C25 -> 45483 | C24: ='3. Weekly raw data'!D25 -> 45490 | D24: =VLOOKUP(A24,'3. Weekly raw data'!$B$8:$N$50,4,0)/(VLOOKUP(A24,'3. Weekly raw data'!$B$8:$N$50,6,0)) -> 0.10714286 | E24: =Iferror(VLOOKUP(A24,'3. Weekly raw data'!$B$8:$N$50,5,0)/(VLOOKUP(A24,'3. Weekly raw data'!$B$8:$N$50,4,0)+VLOOKUP(A24,'3. Weekly raw data'!$B$8:$N$50,5,0)),"") -> 0 | F24: =(VLOOKUP(A24,'3. Weekly raw data'!$B$8:$N$50,6,0)/VLOOKUP(A24,'3. Weekly raw data'!$B$8:$N$50,7,0)*100) -> 96.551724 | G24: =(VLOOKUP(A24,'3. Weekly raw data'!$B$8:$N$50,8,0)/VLOOKUP(A24,'3. Weekly raw data'!$B$8:$N$50,6,0)*100) -> 17.857143 | H24: =VLOOKUP(A24,'3. Weekly raw data'!$B$8:$N$50,9,0)/VLOOKUP(A24,'3. Weekly raw data'!$B$8:$N$50,10,0)*100 -> 100
A25: 19 | B25: ='3. Weekly raw data'!C26 -> 45490 | C25: ='3. Weekly raw data'!D26 -> 45497 | D25: =VLOOKUP(A25,'3. Weekly raw data'!$B$8:$N$50,4,0)/(VLOOKUP(A25,'3. Weekly raw data'!$B$8:$N$50,6,0)) -> 0.092307692 | E25: =Iferror(VLOOKUP(A25,'3. Weekly raw data'!$B$8:$N$50,5,0)/(VLOOKUP(A25,'3. Weekly raw data'!$B$8:$N$50,4,0)+VLOOKUP(A25,'3. Weekly raw data'!$B$8:$N$50,5,0)),"") -> 0 | F25: =(VLOOKUP(A25,'3. Weekly raw data'!$B$8:$N$50,6,0)/VLOOKUP(A25,'3. Weekly raw data'!$B$8:$N$50,7,0)*100) -> 110.16949 | G25: =(VLOOKUP(A25,'3. Weekly raw data'!$B$8:$N$50,8,0)/VLOOKUP(A25,'3. Weekly raw data'!$B$8:$N$50,6,0)*100) -> 12.307692 | H25: =VLOOKUP(A25,'3. Weekly raw data'!$B$8:$N$50,9,0)/VLOOKUP(A25,'3. Weekly raw data'!$B$8:$N$50,10,0)*100 -> 85.714286 | I25: C1: Engineer took time for self-testing in stg environment. M1: Clients visited and had a lot of mtgs and team events. The team and clients had decided in advance to consider this as a special sprint.
A26: 20 | B26: ='3. Weekly raw data'!C27 -> 45497 | C26: ='3. Weekly raw data'!D27 -> 45505 | D26: =VLOOKUP(A26,'3. Weekly raw data'!$B$8:$N$50,4,0)/(VLOOKUP(A26,'3. Weekly raw data'!$B$8:$N$50,6,0)) -> 0.027777778 | E26: =Iferror(VLOOKUP(A26,'3. Weekly raw data'!$B$8:$N$50,5,0)/(VLOOKUP(A26,'3. Weekly raw data'!$B$8:$N$50,4,0)+VLOOKUP(A26,'3. Weekly raw data'!$B$8:$N$50,5,0)),"") -> 0 | F26: =(VLOOKUP(A26,'3. Weekly raw data'!$B$8:$N$50,6,0)/VLOOKUP(A26,'3. Weekly raw data'!$B$8:$N$50,7,0)*100) -> 93.506494 | G26: =(VLOOKUP(A26,'3. Weekly raw data'!$B$8:$N$50,8,0)/VLOOKUP(A26,'3. Weekly raw data'!$B$8:$N$50,6,0)*100) -> 2.7777778 | H26: =VLOOKUP(A26,'3. Weekly raw data'!$B$8:$N$50,9,0)/VLOOKUP(A26,'3. Weekly raw data'!$B$8:$N$50,10,0)*100 -> 100
A27: 21 | B27: ='3. Weekly raw data'!C28 -> 45505 | C27: ='3. Weekly raw data'!D28 -> 45518 | D27: =VLOOKUP(A27,'3. Weekly raw data'!$B$8:$N$50,4,0)/(VLOOKUP(A27,'3. Weekly raw data'!$B$8:$N$50,6,0)) -> 0.038461538 | E27: =Iferror(VLOOKUP(A27,'3. Weekly raw data'!$B$8:$N$50,5,0)/(VLOOKUP(A27,'3. Weekly raw data'!$B$8:$N$50,4,0)+VLOOKUP(A27,'3. Weekly raw data'!$B$8:$N$50,5,0)),"") -> 0 | F27: =(VLOOKUP(A27,'3. Weekly raw data'!$B$8:$N$50,6,0)/VLOOKUP(A27,'3. Weekly raw data'!$B$8:$N$50,7,0)*100) -> 111.82796 | G27: =(VLOOKUP(A27,'3. Weekly raw data'!$B$8:$N$50,8,0)/VLOOKUP(A27,'3. Weekly raw data'!$B$8:$N$50,6,0)*100) -> 6.7307692 | H27: =VLOOKUP(A27,'3. Weekly raw data'!$B$8:$N$50,9,0)/VLOOKUP(A27,'3. Weekly raw data'!$B$8:$N$50,10,0)*100 -> 88 | I27: Took time supporting new members. There was a user story requirement that needed to wait for stakeholder confirmation. The discussion during the review phase took time.
A28: 22 | B28: ='3. Weekly raw data'!C29 -> 45518 | C28: ='3. Weekly raw data'!D29 -> 45525 | D28: =VLOOKUP(A28,'3. Weekly raw data'!$B$8:$N$50,4,0)/(VLOOKUP(A28,'3. Weekly raw data'!$B$8:$N$50,6,0)) -> 0.075 | E28: =Iferror(VLOOKUP(A28,'3. Weekly raw data'!$B$8:$N$50,5,0)/(VLOOKUP(A28,'3. Weekly raw data'!$B$8:$N$50,4,0)+VLOOKUP(A28,'3. Weekly raw data'!$B$8:$N$50,5,0)),"") -> 0 | F28: =(VLOOKUP(A28,'3. Weekly raw data'!$B$8:$N$50,6,0)/VLOOKUP(A28,'3. Weekly raw data'!$B$8:$N$50,7,0)*100) -> 114.28571 | G28: =(VLOOKUP(A28,'3. Weekly raw data'!$B$8:$N$50,8,0)/VLOOKUP(A28,'3. Weekly raw data'!$B$8:$N$50,6,0)*100) -> 8.75 | H28: =VLOOKUP(A28,'3. Weekly raw data'!$B$8:$N$50,9,0)/VLOOKUP(A28,'3. Weekly raw data'!$B$8:$N$50,10,0)*100 -> 100 | I28: The new engineer took more time than expected because it was his first task, so it was still hard to estimate correctly, and he also needed time to get used to the project.
A29: 23 | B29: ='3. Weekly raw data'!C30 -> 45525 | C29: ='3. Weekly raw data'!D30 -> 45532 | D29: =VLOOKUP(A29,'3. Weekly raw data'!$B$8:$N$50,4,0)/(VLOOKUP(A29,'3. Weekly raw data'!$B$8:$N$50,6,0)) -> 0.051282051 | E29: =Iferror(VLOOKUP(A29,'3. Weekly raw data'!$B$8:$N$50,5,0)/(VLOOKUP(A29,'3. Weekly raw data'!$B$8:$N$50,4,0)+VLOOKUP(A29,'3. Weekly raw data'!$B$8:$N$50,5,0)),"") -> 0 | F29: =(VLOOKUP(A29,'3. Weekly raw data'!$B$8:$N$50,6,0)/VLOOKUP(A29,'3. Weekly raw data'!$B$8:$N$50,7,0)*100) -> 106.84932 | G29: =(VLOOKUP(A29,'3. Weekly raw data'!$B$8:$N$50,8,0)/VLOOKUP(A29,'3. Weekly raw data'!$B$8:$N$50,6,0)*100) -> 17.948718 | H29: =VLOOKUP(A29,'3. Weekly raw data'!$B$8:$N$50,9,0)/VLOOKUP(A29,'3. Weekly raw data'!$B$8:$N$50,10,0)*100 -> 100
A30: 24 | B30: ='3. Weekly raw data'!C31 -> 45532 | C30: ='3. Weekly raw data'!D31 -> 45539 | D30: =VLOOKUP(A30,'3. Weekly raw data'!$B$8:$N$50,4,0)/(VLOOKUP(A30,'3. Weekly raw data'!$B$8:$N$50,6,0)) -> 0 | E30: =Iferror(VLOOKUP(A30,'3. Weekly raw data'!$B$8:$N$50,5,0)/(VLOOKUP(A30,'3. Weekly raw data'!$B$8:$N$50,4,0)+VLOOKUP(A30,'3. Weekly raw data'!$B$8:$N$50,5,0)),"") | F30: =(VLOOKUP(A30,'3. Weekly raw data'!$B$8:$N$50,6,0)/VLOOKUP(A30,'3. Weekly raw data'!$B$8:$N$50,7,0)*100) -> 33.333333 | G30: =(VLOOKUP(A30,'3. Weekly raw data'!$B$8:$N$50,8,0)/VLOOKUP(A30,'3. Weekly raw data'!$B$8:$N$50,6,0)*100) -> 0 | H30: =VLOOKUP(A30,'3. Weekly raw data'!$B$8:$N$50,9,0)/VLOOKUP(A30,'3. Weekly raw data'!$B$8:$N$50,10,0)*100 -> 41.666667 | I30: - The reviewer from the client took 2 days off so the PR review process was delayed quite a lot. - An engineer in the team took an unexpected day off and after coming back there are some issues that he need to catch up and resolve with the team so the ticket situation of him was also delayed
A31: 25 | B31: ='3. Weekly raw data'!C32 -> 45539 | C31: ='3. Weekly raw data'!D32 -> 45546 | D31: =VLOOKUP(A31,'3. Weekly raw data'!$B$8:$N$50,4,0)/(VLOOKUP(A31,'3. Weekly raw data'!$B$8:$N$50,6,0)) -> 0 | E31: =Iferror(VLOOKUP(A31,'3. Weekly raw data'!$B$8:$N$50,5,0)/(VLOOKUP(A31,'3. Weekly raw data'!$B$8:$N$50,4,0)+VLOOKUP(A31,'3. Weekly raw data'!$B$8:$N$50,5,0)),"") | F31: =(VLOOKUP(A31,'3. Weekly raw data'!$B$8:$N$50,6,0)/VLOOKUP(A31,'3. Weekly raw data'!$B$8:$N$50,7,0)*100) -> 112.5 | G31: =(VLOOKUP(A31,'3. Weekly raw data'!$B$8:$N$50,8,0)/VLOOKUP(A31,'3. Weekly raw data'!$B$8:$N$50,6,0)*100) -> 0 | H31: =VLOOKUP(A31,'3. Weekly raw data'!$B$8:$N$50,9,0)/VLOOKUP(A31,'3. Weekly raw data'!$B$8:$N$50,10,0)*100 -> 100 | I31: There is a ticket that costed more time than the engineer expected, it's the task for testing the script to check the inconsistency data between DB and Hubspot created and tested by the engineer but the engineer is not familiar with the system so it took more time for him to prepare the data and the document to report about the test result.
A32: 26 | B32: ='3. Weekly raw data'!C33 -> 45546 | C32: ='3. Weekly raw data'!D33 -> 45553 | D32: =VLOOKUP(A32,'3. Weekly raw data'!$B$8:$N$50,4,0)/(VLOOKUP(A32,'3. Weekly raw data'!$B$8:$N$50,6,0)) -> 0.083333333 | E32: =Iferror(VLOOKUP(A32,'3. Weekly raw data'!$B$8:$N$50,5,0)/(VLOOKUP(A32,'3. Weekly raw data'!$B$8:$N$50,4,0)+VLOOKUP(A32,'3. Weekly raw data'!$B$8:$N$50,5,0)),"") -> 0 | F32: =(VLOOKUP(A32,'3. Weekly raw data'!$B$8:$N$50,6,0)/VLOOKUP(A32,'3. Weekly raw data'!$B$8:$N$50,7,0)*100) -> 90 | G32: =(VLOOKUP(A32,'3. Weekly raw data'!$B$8:$N$50,8,0)/VLOOKUP(A32,'3. Weekly raw data'!$B$8:$N$50,6,0)*100) -> 19.444444 | H32: =VLOOKUP(A32,'3. Weekly raw data'!$B$8:$N$50,9,0)/VLOOKUP(A32,'3. Weekly raw data'!$B$8:$N$50,10,0)*100 -> 88.888889 | I32: During this sprint, there are some tickets that costed the team more time to implement and fix comment so the team didn't have chance to handle some other tickets then the number of closed ticket does not meet the standard.
A33: 27 | B33: ='3. Weekly raw data'!C34 -> 45553 | C33: ='3. Weekly raw data'!D34 -> 45560 | D33: =VLOOKUP(A33,'3. Weekly raw data'!$B$8:$N$50,4,0)/(VLOOKUP(A33,'3. Weekly raw data'!$B$8:$N$50,6,0)) -> 0.081081081 | E33: =Iferror(VLOOKUP(A33,'3. Weekly raw data'!$B$8:$N$50,5,0)/(VLOOKUP(A33,'3. Weekly raw data'!$B$8:$N$50,4,0)+VLOOKUP(A33,'3. Weekly raw data'!$B$8:$N$50,5,0)),"") -> 0 | F33: =(VLOOKUP(A33,'3. Weekly raw data'!$B$8:$N$50,6,0)/VLOOKUP(A33,'3. Weekly raw data'!$B$8:$N$50,7,0)*100) -> 92.5 | G33: =(VLOOKUP(A33,'3. Weekly raw data'!$B$8:$N$50,8,0)/VLOOKUP(A33,'3. Weekly raw data'!$B$8:$N$50,6,0)*100) -> 18.918919 | H33: =VLOOKUP(A33,'3. Weekly raw data'!$B$8:$N$50,9,0)/VLOOKUP(A33,'3. Weekly raw data'!$B$8:$N$50,10,0)*100 -> 93.333333
A34: 28 | B34: ='3. Weekly raw data'!C35 -> 45560 | C34: ='3. Weekly raw data'!D35 -> 45567 | D34: =VLOOKUP(A34,'3. Weekly raw data'!$B$8:$N$50,4,0)/(VLOOKUP(A34,'3. Weekly raw data'!$B$8:$N$50,6,0)) -> 0 | E34: =Iferror(VLOOKUP(A34,'3. Weekly raw data'!$B$8:$N$50,5,0)/(VLOOKUP(A34,'3. Weekly raw data'!$B$8:$N$50,4,0)+VLOOKUP(A34,'3. Weekly raw data'!$B$8:$N$50,5,0)),"") | F34: =(VLOOKUP(A34,'3. Weekly raw data'!$B$8:$N$50,6,0)/VLOOKUP(A34,'3. Weekly raw data'!$B$8:$N$50,7,0)*100) -> 100 | G34: =(VLOOKUP(A34,'3. Weekly raw data'!$B$8:$N$50,8,0)/VLOOKUP(A34,'3. Weekly raw data'!$B$8:$N$50,6,0)*100) -> 0 | H34: =VLOOKUP(A34,'3. Weekly raw data'!$B$8:$N$50,9,0)/VLOOKUP(A34,'3. Weekly raw data'!$B$8:$N$50,10,0)*100 -> 70 | I34: There is an engineer in the team took one day off, besides that there was a ticket with high complexity which caused the engineer to spend more time for the implementation.
A35: 29 | B35: ='3. Weekly raw data'!C36 -> 45567 | C35: ='3. Weekly raw data'!D36 -> 45574 | D35: =VLOOKUP(A35,'3. Weekly raw data'!$B$8:$N$50,4,0)/(VLOOKUP(A35,'3. Weekly raw data'!$B$8:$N$50,6,0)) -> 0.38461538 | E35: =Iferror(VLOOKUP(A35,'3. Weekly raw data'!$B$8:$N$50,5,0)/(VLOOKUP(A35,'3. Weekly raw data'!$B$8:$N$50,4,0)+VLOOKUP(A35,'3. Weekly raw data'!$B$8:$N$50,5,0)),"") -> 0 | F35: =(VLOOKUP(A35,'3. Weekly raw data'!$B$8:$N$50,6,0)/VLOOKUP(A35,'3. Weekly raw data'!$B$8:$N$50,7,0)*100) -> 100 | G35: =(VLOOKUP(A35,'3. Weekly raw data'!$B$8:$N$50,8,0)/VLOOKUP(A35,'3. Weekly raw data'!$B$8:$N$50,6,0)*100) -> 1.5384615 | H35: =VLOOKUP(A35,'3. Weekly raw data'!$B$8:$N$50,9,0)/VLOOKUP(A35,'3. Weekly raw data'!$B$8:$N$50,10,0)*100 -> 95.454545
A36: 30 | B36: ='3. Weekly raw data'!C37 -> 45574 | C36: ='3. Weekly raw data'!D37 -> 45581 | D36: =VLOOKUP(A36,'3. Weekly raw data'!$B$8:$N$50,4,0)/(VLOOKUP(A36,'3. Weekly raw data'!$B$8:$N$50,6,0)) -> 0.003125 | E36: =Iferror(VLOOKUP(A36,'3. Weekly raw data'!$B$8:$N$50,5,0)/(VLOOKUP(A36,'3. Weekly raw data'!$B$8:$N$50,4,0)+VLOOKUP(A36,'3. Weekly raw data'!$B$8:$N$50,5,0)),"") -> 0 | F36: =(VLOOKUP(A36,'3. Weekly raw data'!$B$8:$N$50,6,0)/VLOOKUP(A36,'3. Weekly raw data'!$B$8:$N$50,7,0)*100) -> 100 | G36: =(VLOOKUP(A36,'3. Weekly raw data'!$B$8:$N$50,8,0)/VLOOKUP(A36,'3. Weekly raw data'!$B$8:$N$50,6,0)*100) -> 37.5 | H36: =VLOOKUP(A36,'3. Weekly raw data'!$B$8:$N$50,9,0)/VLOOKUP(A36,'3. Weekly raw data'!$B$8:$N$50,10,0)*100 -> 88.235294 | I36: In this sprint, 2 tasks have the actual point higher than the estimated point: - The first one is a task for implementing the UI of the new feature, during the implementation, the engineer raised some concerns about the UI and suggested some changes to improve it, therefore a rework has been conducted to adapt the specification improvement. - Another one is an engineer's task to support QA in executing some test cases. The task cost more time than estimated since the team raised some more abnormal cases to test, and also the data preparation phase took quite an amount of time.
A37: 31 | B37: ='3. Weekly raw data'!C38 -> 45581 | C37: ='3. Weekly raw data'!D38 -> 45588 | D37: =VLOOKUP(A37,'3. Weekly raw data'!$B$8:$N$50,4,0)/(VLOOKUP(A37,'3. Weekly raw data'!$B$8:$N$50,6,0)) -> #DIV/0! | E37: =Iferror(VLOOKUP(A37,'3. Weekly raw data'!$B$8:$N$50,5,0)/(VLOOKUP(A37,'3. Weekly raw data'!$B$8:$N$50,4,0)+VLOOKUP(A37,'3. Weekly raw data'!$B$8:$N$50,5,0)),"") | F37: =(VLOOKUP(A37,'3. Weekly raw data'!$B$8:$N$50,6,0)/VLOOKUP(A37,'3. Weekly raw data'!$B$8:$N$50,7,0)*100) -> #DIV/0! | G37: =(VLOOKUP(A37,'3. Weekly raw data'!$B$8:$N$50,8,0)/VLOOKUP(A37,'3. Weekly raw data'!$B$8:$N$50,6,0)*100) -> #DIV/0! | H37: =VLOOKUP(A37,'3. Weekly raw data'!$B$8:$N$50,9,0)/VLOOKUP(A37,'3. Weekly raw data'!$B$8:$N$50,10,0)*100 -> #DIV/0!
A38: 32 | B38: ='3. Weekly raw data'!C39 -> 45588 | C38: ='3. Weekly raw data'!D39 -> 45595 | D38: =VLOOKUP(A38,'3. Weekly raw data'!$B$8:$N$50,4,0)/(VLOOKUP(A38,'3. Weekly raw data'!$B$8:$N$50,6,0)) -> #DIV/0! | E38: =Iferror(VLOOKUP(A38,'3. Weekly raw data'!$B$8:$N$50,5,0)/(VLOOKUP(A38,'3. Weekly raw data'!$B$8:$N$50,4,0)+VLOOKUP(A38,'3. Weekly raw data'!$B$8:$N$50,5,0)),"") | F38: =(VLOOKUP(A38,'3. Weekly raw data'!$B$8:$N$50,6,0)/VLOOKUP(A38,'3. Weekly raw data'!$B$8:$N$50,7,0)*100) -> #DIV/0! | G38: =(VLOOKUP(A38,'3. Weekly raw data'!$B$8:$N$50,8,0)/VLOOKUP(A38,'3. Weekly raw data'!$B$8:$N$50,6,0)*100) -> #DIV/0! | H38: =VLOOKUP(A38,'3. Weekly raw data'!$B$8:$N$50,9,0)/VLOOKUP(A38,'3. Weekly raw data'!$B$8:$N$50,10,0)*100 -> #DIV/0!
A39: 33 | B39: ='3. Weekly raw data'!C40 -> 45595 | C39: ='3. Weekly raw data'!D40 -> 45602 | D39: =VLOOKUP(A39,'3. Weekly raw data'!$B$8:$N$50,4,0)/(VLOOKUP(A39,'3. Weekly raw data'!$B$8:$N$50,6,0)) -> #DIV/0! | E39: =Iferror(VLOOKUP(A39,'3. Weekly raw data'!$B$8:$N$50,5,0)/(VLOOKUP(A39,'3. Weekly raw data'!$B$8:$N$50,4,0)+VLOOKUP(A39,'3. Weekly raw data'!$B$8:$N$50,5,0)),"") | F39: =(VLOOKUP(A39,'3. Weekly raw data'!$B$8:$N$50,6,0)/VLOOKUP(A39,'3. Weekly raw data'!$B$8:$N$50,7,0)*100) -> #DIV/0! | G39: =(VLOOKUP(A39,'3. Weekly raw data'!$B$8:$N$50,8,0)/VLOOKUP(A39,'3. Weekly raw data'!$B$8:$N$50,6,0)*100) -> #DIV/0! | H39: =VLOOKUP(A39,'3. Weekly raw data'!$B$8:$N$50,9,0)/VLOOKUP(A39,'3. Weekly raw data'!$B$8:$N$50,10,0)*100 -> #DIV/0!
A40: 34 | B40: ='3. Weekly raw data'!C41 -> 45602 | C40: ='3. Weekly raw data'!D41 -> 45609 | D40: =VLOOKUP(A40,'3. Weekly raw data'!$B$8:$N$50,4,0)/(VLOOKUP(A40,'3. Weekly raw data'!$B$8:$N$50,6,0)) -> #DIV/0! | E40: =Iferror(VLOOKUP(A40,'3. Weekly raw data'!$B$8:$N$50,5,0)/(VLOOKUP(A40,'3. Weekly raw data'!$B$8:$N$50,4,0)+VLOOKUP(A40,'3. Weekly raw data'!$B$8:$N$50,5,0)),"") | F40: =(VLOOKUP(A40,'3. Weekly raw data'!$B$8:$N$50,6,0)/VLOOKUP(A40,'3. Weekly raw data'!$B$8:$N$50,7,0)*100) -> #DIV/0! | G40: =(VLOOKUP(A40,'3. Weekly raw data'!$B$8:$N$50,8,0)/VLOOKUP(A40,'3. Weekly raw data'!$B$8:$N$50,6,0)*100) -> #DIV/0! | H40: =VLOOKUP(A40,'3. Weekly raw data'!$B$8:$N$50,9,0)/VLOOKUP(A40,'3. Weekly raw data'!$B$8:$N$50,10,0)*100 -> #DIV/0!
A41: 35 | B41: ='3. Weekly raw data'!C42 -> 45609 | C41: ='3. Weekly raw data'!D42 -> 45616 | D41: =VLOOKUP(A41,'3. Weekly raw data'!$B$8:$N$50,4,0)/(VLOOKUP(A41,'3. Weekly raw data'!$B$8:$N$50,6,0)) -> #DIV/0! | E41: =Iferror(VLOOKUP(A41,'3. Weekly raw data'!$B$8:$N$50,5,0)/(VLOOKUP(A41,'3. Weekly raw data'!$B$8:$N$50,4,0)+VLOOKUP(A41,'3. Weekly raw data'!$B$8:$N$50,5,0)),"") | F41: =(VLOOKUP(A41,'3. Weekly raw data'!$B$8:$N$50,6,0)/VLOOKUP(A41,'3. Weekly raw data'!$B$8:$N$50,7,0)*100) -> #DIV/0! | G41: =(VLOOKUP(A41,'3. Weekly raw data'!$B$8:$N$50,8,0)/VLOOKUP(A41,'3. Weekly raw data'!$B$8:$N$50,6,0)*100) -> #DIV/0! | H41: =VLOOKUP(A41,'3. Weekly raw data'!$B$8:$N$50,9,0)/VLOOKUP(A41,'3. Weekly raw data'!$B$8:$N$50,10,0)*100 -> #DIV/0!
...

Sheet 4.2 Project Summary_By Phase
C1: Project KPI Data | I1: No: BM-QT-1706-01
I2: Version: 1.6
I3: Issue Date: 22/09/2026
A4: SUN ASTERISK VIETNAM CO., LTD | I4: ISO/IEC 27001:2013&ISO 9001:2015
A6: Phase | B6: Sprint/ Week | C6: Start date | D6: End date | E6: QA Bug Proportion (Q1) #/Mh Internal Bug Count / Total Actual Effort [MH] | F6: UAT Bug Rate (Q2)% ( UAT Bug Count/ All Bug Count ) * 100 | G6: Estimation Accuracy Rate (C1)% ( Total Actual Effort / Total Estimated Effort ) * 100 | H6: Bug Handling Cost Rate (C2)% ( Total Bug Handling Effort / Total Actual Effort ) * 100 | I6: Issue Closed Ratio (M1)% (Closed Issue Count / All Issue Count)*100 | J6: Note
A7: 1 | B7: 1 | C7: 45358 | D7: 45364 | E7: 0 | F7: #NUM! | G7: 100 | H7: 0 | I7: 70
A8: 2 | B8: 2 | C8: 45365 | D8: 45441 | E8: 12.550201 | F8: 10.714286 | G8: 97.265625 | H8: 47.891566 | I8: 95.977011
B9: 3
B10: 4
B11: 5
B12: 6
B13: 7
B14: 8
B15: 9
B16: 10
B17: 11
A18: 3 | B18: 12 | C18: 45441 | D18: 45532 | E18: 3.823178 | F18: 0 | G18: 103.33333 | H18: 6.4516129 | I18: 96.825397
B19: 13
B20: 14
B21: 15
B22: 16
B23: 17
B24: 18
B25: 19
B26: 20
B27: 21
B28: 22
B29: 23
A30: 4 | B30: 24 | C30: 45532 | D30: 45588 | E30: 11.882288 | F30: 0 | G30: 98.200654 | H30: 15.32482 | I30: 85.714286
B31: 25
B32: 26
B33: 27
B34: 28
B35: 29
B36: 30
B37: 31
A38: 5 | B38: 32 | C38: 45588 | D38: 45651 | E38: #NUM! | F38: #NUM! | G38: #NUM! | H38: #NUM! | I38: #NUM!
B39: 33
B40: 34
B41: 35
...

Sheet 5.1 Chart_By Sprint
C1: Project KPI Data | G1: No: BM-QT-1706-01
G2: Version: 1.6
G3: Issue Date: 22/09/2026
A4: SUN ASTERISK VIETNAM CO., LTD | G4: ISO/IEC 27001:2013&ISO 9001:2015
C7: UCL | D7: Target | E7: LCL
C8: 0.5 | D8: 0.05 | E8: 0
C9: 0.5 | D9: 0.05 | E9: 0
C10: 0.5 | D10: 0.05 | E10: 0
C11: 0.5 | D11: 0.05 | E11: 0
C12: 0.5 | D12: 0.05 | E12: 0
C13: 0.5 | D13: 0.05 | E13: 0
C14: 0.5 | D14: 0.05 | E14: 0
C15: 0.5 | D15: 0.05 | E15: 0
C16: 0.5 | D16: 0.05 | E16: 0
C17: 0.5 | D17: 0.05 | E17: 0
C18: 0.5 | D18: 0.05 | E18: 0
C19: 0.5 | D19: 0.05 | E19: 0
... C25: 0.5 | D25: 0.05 | E25: 0
C28: UCL | D28: Target | E28: LCL
C29: 20 | D29: 5 | E29: 0
C30: 20 | D30: 5 | E30: 0
C31: 20 | D31: 5 | E31: 0
C32: 20 | D32: 5 | E32: 0
C33: 20 | D33: 5 | E33: 0
C34: 20 | D34: 5 | E34: 0
C35: 20 | D35: 5 | E35: 0
C36: 20 | D36: 5 | E36: 0
C37: 20 | D37: 5 | E37: 0
C38: 20 | D38: 5 | E38: 0
C39: 20 | D39: 5 | E39: 0
C40: 20 | D40: 5 | E40: 0
... C46: 20 | D46: 5 | E46: 0
C49: UCL | D49: Target | E49: LCL
C50: 115 | D50: 100 | E50: 85
C51: 115 | D51: 100 | E51: 85
C52: 115 | D52: 100 | E52: 85
C53: 115 | D53: 100 | E53: 85
C54: 115 | D54: 100 | E54: 85
C55: 115 | D55: 100 | E55: 85
C56: 115 | D56: 100 | E56: 85
...

Sheet 5.2 Chart_By Phase
C1: Project KPI Data | G1: No: BM-QT-1706-01
G2: Version: 1.6
G3: Issue Date: 22/09/2026
A4: SUN ASTERISK VIETNAM CO., LTD | G4: ISO/IEC 27001:2013&ISO 9001:2015
C7: UCL | D7: Target | E7: LCL
C8: 0.5 | D8: 0.05 | E8: 0
C9: 0.5 | D9: 0.05 | E9: 0
C10: 0.5 | D10: 0.05 | E10: 0
C11: 0.5 | D11: 0.05 | E11: 0
C12: 0.5 | D12: 0.05 | E12: 0
C13: 0.5 | D13: 0.05 | E13: 0
C14: 0.5 | D14: 0.05 | E14: 0
C21: UCL | D21: Target | E21: LCL
C22: 20 | D22: 5 | E22: 0
C23: 20 | D23: 5 | E23: 0
C24: 20 | D24: 5 | E24: 0
C25: 20 | D25: 5 | E25: 0
C26: 20 | D26: 5 | E26: 0
C27: 20 | D27: 5 | E27: 0
C28: 20 | D28: 5 | E28: 0
C38: UCL | D38: Target | E38: LCL
C39: 115 | D39: 100 | E39: 85
C40: 115 | D40: 100 | E40: 85
C41: 115 | D41: 100 | E41: 85
C42: 115 | D42: 100 | E42: 85
C43: 115 | D43: 100 | E43: 85
C44: 115 | D44: 100 | E44: 85
C45: 115 | D45: 100 | E45: 85
C56: UCL | D56: Target | E56: LCL
C57: 20 | D57: 10 | E57: 5
C58: 20 | D58: 10 | E58: 5
C59: 20 | D59: 10 | E59: 5
C60: 20 | D60: 10 | E60: 5
C61: 20 | D61: 10 | E61: 5
C62: 20 | D62: 10 | E62: 5
C63: 20 | D63: 10 | E63: 5
C71: UCL | D71: Target | E71: LCL
C72: 110 | D72: 100 | E72: 90
C73: 110 | D73: 100 | E73: 90
C74: 110 | D74: 100 | E74: 90
...

Sheet 6. KPI analysis
C1: Project KPI Data | H1: No: BM-QT-1706-01
H2: Version: 1.6
H3: Issue Date: 22/09/2026
A4: SUN ASTERISK VIETNAM CO., LTD | H4: ISO/IEC 27001:2013&ISO 9001:2015
A6: Phase | B6: Sprint/ Week | C6: Start date | D6: End date | E6: Abnormal KPI | F6: Target | G6: Cause | H6: Action of project | I6: Follow up | J6: Tracking result
B7: Total | C7: 7
