Workbook

Sheet History of changes
E1: RISK MANAGEMENT | J1: No: BM-QT-1704-01
J2: Version: 2.3
J3: Issue Date: 22/09/2026
A4: SUN ASTERISK VIETNAM CO., LTD | J4: ISO/IEC 27001:2013&ISO 9001:2015
A6: HISTORY OF CHANGES
A7: No | B7: Change Item | E7: Description of changes | J7: Change Date
A8: 1 | E8: Add new | J8: 13/01/2020
A9: 2 | E9: Update format | J9: 44320
A10: 3 | B10: Risk Management & Appendix sheet | E10: Customize template: - Delete Risk Source field - Add new field: Risk Trigger, Current Control Response - Update criteria of impact | J10: 44202
A11: 4 | E11: - Bổ sung nội dung Risk Origin: Là nguồn gốc gây ra rủi ro theo từng phân loại, điều này giúp sự thống kê các rủi ro thường xảy ra trong công ty, dự án dễ dàng, từ đó có thể học được các giải pháp phù hợp để áp dụng giảm thiểu rủi ro trong tương lai. - Bổ sung sheet Summary: Thống kê các rủi ro theo Priority, Risk Category và Risk Origin | J11: 44510
A12: 5 | B12: Sheet Appendix | E12: Customize bảng Risk Category: Tách thành các dòng độc lập cho rõ ràng | J12: 20/01/2022
A13: 6 | B13: Sheet Risk Management | E13: Thêm cột Summary for reporting: tóm tắt nhanh các thông tin thiết yếu tới Unit manager và các bên liên quan về hiện trạng quản lý risk tại dự án | J13: 18/11/2024
A14: 7 | B14: Sheet Appendix | E14: Thêm mục Security Requirement vào phần Risk Origin | J14: 45455
A15: 8 | B15: All sheet | E15: Update mã biểu mẫu theo tiêu chuẩn ISO. | J15: 22/09/2026

Sheet Summary
C1: Risk Management | I1: No: BM-QT-1704-01
I2: Version: 2.3
I3: Issue Date: 22/09/2026
A4: SUN ASTERISK VIETNAM CO., LTD | I4: ISO/IEC 27001:2013&ISO 9001:2015
A8: 1- Risk Trend - Count
B10: Identified | C10: Mitigating | D10: Occurred | E10: Closed
A11: Critical | B11: =COUNTIFS('Risk Management'!$L:$L,"Critical",'Risk Management'!$U:$U,"Identified") -> 0 | C11: =COUNTIFS('Risk Management'!$L:$L,"Critical",'Risk Management'!$U:$U,"Mitigating") -> 0 | D11: =COUNTIFS('Risk Management'!$L:$L,"Critical",'Risk Management'!$U:$U,"Occurred") -> 0 | E11: =COUNTIFS('Risk Management'!$L:$L,"Critical",'Risk Management'!$U:$U,"Closed") -> 0
A12: Extreme | B12: =COUNTIFS('Risk Management'!$L:$L,"Extreme",'Risk Management'!$U:$U,"Identified") -> 0 | C12: =COUNTIFS('Risk Management'!$L:$L,"Extreme",'Risk Management'!$U:$U,"Mitigating") -> 0 | D12: =COUNTIFS('Risk Management'!$L:$L,"Extreme",'Risk Management'!$U:$U,"Occurred") -> 0 | E12: =COUNTIFS('Risk Management'!$L:$L,"Extreme",'Risk Management'!$U:$U,"Closed") -> 0
A13: High | B13: =COUNTIFS('Risk Management'!$L:$L,"High",'Risk Management'!$U:$U,"Identified") -> 0 | C13: =COUNTIFS('Risk Management'!$L:$L,"High",'Risk Management'!$U:$U,"Mitigating") -> 0 | D13: =COUNTIFS('Risk Management'!$L:$L,"High",'Risk Management'!$U:$U,"Occurred") -> 0 | E13: =COUNTIFS('Risk Management'!$L:$L,"High",'Risk Management'!$U:$U,"Closed") -> 0
A14: Medium | B14: =COUNTIFS('Risk Management'!$L:$L,"Medium",'Risk Management'!$U:$U,"Identified") -> 0 | C14: =COUNTIFS('Risk Management'!$L:$L,"Medium",'Risk Management'!$U:$U,"Mitigating") -> 0 | D14: =COUNTIFS('Risk Management'!$L:$L,"Medium",'Risk Management'!$U:$U,"Occurred") -> 0 | E14: =COUNTIFS('Risk Management'!$L:$L,"Medium",'Risk Management'!$U:$U,"Closed") -> 0
A15: Low | B15: =COUNTIFS('Risk Management'!$L:$L,"Low",'Risk Management'!$U:$U,"Identified") -> 0 | C15: =COUNTIFS('Risk Management'!$L:$L,"CLow",'Risk Management'!$U:$U,"Mitigating") -> 0 | D15: =COUNTIFS('Risk Management'!$L:$L,"Low",'Risk Management'!$U:$U,"Occurred") -> 0 | E15: =COUNTIFS('Risk Management'!$L:$L,"Low",'Risk Management'!$U:$U,"Closed") -> 0
A16: Total | B16: =SUM(B11:B15) -> 0 | C16: =SUM(C11:C15) -> 0 | D16: =SUM(D11:D15) -> 0 | E16: =SUM(E11:E15) -> 0
A22: 2- Risk Trend - Risk Category
A24: Risk Category | B24: Identified | C24: Mitigating | D24: Occurred | E24: Closed
A25: Financial Risk | B25: =COUNTIFS('Risk Management'!$C:$C,"Financial Risk",'Risk Management'!$U:$U,"Identified") -> 0 | C25: =COUNTIFS('Risk Management'!$C:$C,"Financial Risk",'Risk Management'!$U:$U,"Mitigating") -> 0 | D25: =COUNTIFS('Risk Management'!$C:$C,"Financial Risk",'Risk Management'!$U:$U,"Occurred") -> 0 | E25: =COUNTIFS('Risk Management'!$C:$C,"Financial Risk",'Risk Management'!$U:$U,"Closed") -> 0
A26: Market Risk | B26: =COUNTIFS('Risk Management'!$C:$C,"Market Risk",'Risk Management'!$U:$U,"Identified") -> 0 | C26: =COUNTIFS('Risk Management'!$C:$C,"Market Risk",'Risk Management'!$U:$U,"Mitigating") -> 0 | D26: =COUNTIFS('Risk Management'!$C:$C,"Market Risk",'Risk Management'!$U:$U,"Occurred") -> 0 | E26: =COUNTIFS('Risk Management'!$C:$C,"Market Risk",'Risk Management'!$U:$U,"Closed") -> 0
A27: Operation Risk | B27: =COUNTIFS('Risk Management'!$C:$C,"Operation Risk",'Risk Management'!$U:$U,"Identified") -> 0 | C27: =COUNTIFS('Risk Management'!$C:$C,"Operation Risk",'Risk Management'!$U:$U,"Mitigating") -> 0 | D27: =COUNTIFS('Risk Management'!$C:$C,"Operation Risk",'Risk Management'!$U:$U,"Occurred") -> 0 | E27: =COUNTIFS('Risk Management'!$C:$C,"Operation Risk",'Risk Management'!$U:$U,"Closed") -> 0
A28: Information Security Risk | B28: =COUNTIFS('Risk Management'!$C:$C,"Information Security Risk",'Risk Management'!$U:$U,"Identified") -> 0 | C28: =COUNTIFS('Risk Management'!$C:$C,"Information Security Risk",'Risk Management'!$U:$U,"Mitigating") -> 0 | D28: =COUNTIFS('Risk Management'!$C:$C,"Information Security Risk",'Risk Management'!$U:$U,"Occurred") -> 0 | E28: =COUNTIFS('Risk Management'!$C:$C,"Information Security Risk",'Risk Management'!$U:$U,"Closed") -> 0
A29: Compliance Risk | B29: =COUNTIFS('Risk Management'!$C:$C,"Compliance Risk",'Risk Management'!$U:$U,"Identified") -> 0 | C29: =COUNTIFS('Risk Management'!$C:$C,"Compliance Risk",'Risk Management'!$U:$U,"Mitigating") -> 0 | D29: =COUNTIFS('Risk Management'!$C:$C,"Compliance Risk",'Risk Management'!$U:$U,"Occurred") -> 0 | E29: =COUNTIFS('Risk Management'!$C:$C,"Compliance Risk",'Risk Management'!$U:$U,"Closed") -> 0
A30: Human Risk | B30: =COUNTIFS('Risk Management'!$C:$C,"Human Risk",'Risk Management'!$U:$U,"Identified") -> 0 | C30: =COUNTIFS('Risk Management'!$C:$C,"Human Risk",'Risk Management'!$U:$U,"Mitigating") -> 0 | D30: =COUNTIFS('Risk Management'!$C:$C,"Human Risk",'Risk Management'!$U:$U,"Occurred") -> 0 | E30: =COUNTIFS('Risk Management'!$C:$C,"Human Risk",'Risk Management'!$U:$U,"Closed") -> 0
A31: Event Risk | B31: =COUNTIFS('Risk Management'!$C:$C,"Event Risk",'Risk Management'!$U:$U,"Identified") -> 0 | C31: =COUNTIFS('Risk Management'!$C:$C,"Event Risk",'Risk Management'!$U:$U,"Mitigating") -> 0 | D31: =COUNTIFS('Risk Management'!$C:$C,"Event Risk",'Risk Management'!$U:$U,"Occurred") -> 0 | E31: =COUNTIFS('Risk Management'!$C:$C,"Event Risk",'Risk Management'!$U:$U,"Closed") -> 0
A32: Rumor Risk | B32: =COUNTIFS('Risk Management'!$C:$C,"Rumor Risk",'Risk Management'!$U:$U,"Identified") -> 0 | C32: =COUNTIFS('Risk Management'!$C:$C,"Rumor Risk",'Risk Management'!$U:$U,"Mitigating") -> 0 | D32: =COUNTIFS('Risk Management'!$C:$C,"Rumor Risk",'Risk Management'!$U:$U,"Occurred") -> 0 | E32: =COUNTIFS('Risk Management'!$C:$C,"Rumor Risk",'Risk Management'!$U:$U,"Closed") -> 0
A37: 3- Risk Trend - Risk Origin
A39: Risk Origin | B39: Identified | C39: Mitigating | D39: Occurred | E39: Closed
A40: Cost, expense, budget management | B40: =COUNTIFS('Risk Management'!$B:$B,A40,'Risk Management'!$U:$U,"Identified") -> 0 | C40: =COUNTIFS('Risk Management'!$B:$B,A40,'Risk Management'!$U:$U,"Mitigating") -> 0 | D40: =COUNTIFS('Risk Management'!$B:$B,A40,'Risk Management'!$U:$U,"Occurred") -> 0 | E40: =COUNTIFS('Risk Management'!$B:$B,A40,'Risk Management'!$U:$U,"Closed") -> 0
A41: Funding cycle | B41: =COUNTIFS('Risk Management'!$B:$B,A41,'Risk Management'!$U:$U,"Identified") -> 0 | C41: =COUNTIFS('Risk Management'!$B:$B,A41,'Risk Management'!$U:$U,"Mitigating") -> 0 | D41: =COUNTIFS('Risk Management'!$B:$B,A41,'Risk Management'!$U:$U,"Occurred") -> 0 | E41: =COUNTIFS('Risk Management'!$B:$B,A41,'Risk Management'!$U:$U,"Closed") -> 0
A42: Foreign exchange | B42: =COUNTIFS('Risk Management'!$B:$B,A42,'Risk Management'!$U:$U,"Identified") -> 0 | C42: =COUNTIFS('Risk Management'!$B:$B,A42,'Risk Management'!$U:$U,"Mitigating") -> 0 | D42: =COUNTIFS('Risk Management'!$B:$B,A42,'Risk Management'!$U:$U,"Occurred") -> 0 | E42: =COUNTIFS('Risk Management'!$B:$B,A42,'Risk Management'!$U:$U,"Closed") -> 0
A43: Customer's change about business, demands | B43: =COUNTIFS('Risk Management'!$B:$B,A43,'Risk Management'!$U:$U,"Identified") -> 0 | C43: =COUNTIFS('Risk Management'!$B:$B,A43,'Risk Management'!$U:$U,"Mitigating") -> 0 | D43: =COUNTIFS('Risk Management'!$B:$B,A43,'Risk Management'!$U:$U,"Occurred") -> 0 | E43: =COUNTIFS('Risk Management'!$B:$B,A43,'Risk Management'!$U:$U,"Closed") -> 0
A44: Technique | B44: =COUNTIFS('Risk Management'!$B:$B,A44,'Risk Management'!$U:$U,"Identified") -> 0 | C44: =COUNTIFS('Risk Management'!$B:$B,A44,'Risk Management'!$U:$U,"Mitigating") -> 0 | D44: =COUNTIFS('Risk Management'!$B:$B,A44,'Risk Management'!$U:$U,"Occurred") -> 0 | E44: =COUNTIFS('Risk Management'!$B:$B,A44,'Risk Management'!$U:$U,"Closed") -> 0
A45: Project Requirement | B45: =COUNTIFS('Risk Management'!$B:$B,A45,'Risk Management'!$U:$U,"Identified") -> 0 | C45: =COUNTIFS('Risk Management'!$B:$B,A45,'Risk Management'!$U:$U,"Mitigating") -> 0 | D45: =COUNTIFS('Risk Management'!$B:$B,A45,'Risk Management'!$U:$U,"Occurred") -> 0 | E45: =COUNTIFS('Risk Management'!$B:$B,A45,'Risk Management'!$U:$U,"Closed") -> 0
A46: Project Management | B46: =COUNTIFS('Risk Management'!$B:$B,A46,'Risk Management'!$U:$U,"Identified") -> 0 | C46: =COUNTIFS('Risk Management'!$B:$B,A46,'Risk Management'!$U:$U,"Mitigating") -> 0 | D46: =COUNTIFS('Risk Management'!$B:$B,A46,'Risk Management'!$U:$U,"Occurred") -> 0 | E46: =COUNTIFS('Risk Management'!$B:$B,A46,'Risk Management'!$U:$U,"Closed") -> 0
A47: Project Characteristics | B47: =COUNTIFS('Risk Management'!$B:$B,A47,'Risk Management'!$U:$U,"Identified") -> 0 | C47: =COUNTIFS('Risk Management'!$B:$B,A47,'Risk Management'!$U:$U,"Mitigating") -> 0 | D47: =COUNTIFS('Risk Management'!$B:$B,A47,'Risk Management'!$U:$U,"Occurred") -> 0 | E47: =COUNTIFS('Risk Management'!$B:$B,A47,'Risk Management'!$U:$U,"Closed") -> 0
A48: Project Dependencies | B48: =COUNTIFS('Risk Management'!$B:$B,A48,'Risk Management'!$U:$U,"Identified") -> 0 | C48: =COUNTIFS('Risk Management'!$B:$B,A48,'Risk Management'!$U:$U,"Mitigating") -> 0 | D48: =COUNTIFS('Risk Management'!$B:$B,A48,'Risk Management'!$U:$U,"Occurred") -> 0 | E48: =COUNTIFS('Risk Management'!$B:$B,A48,'Risk Management'!$U:$U,"Closed") -> 0
A49: Customer's related problems | B49: =COUNTIFS('Risk Management'!$B:$B,A49,'Risk Management'!$U:$U,"Identified") -> 0 | C49: =COUNTIFS('Risk Management'!$B:$B,A49,'Risk Management'!$U:$U,"Mitigating") -> 0 | D49: =COUNTIFS('Risk Management'!$B:$B,A49,'Risk Management'!$U:$U,"Occurred") -> 0 | E49: =COUNTIFS('Risk Management'!$B:$B,A49,'Risk Management'!$U:$U,"Closed") -> 0
A50: Project Environment | B50: =COUNTIFS('Risk Management'!$B:$B,A50,'Risk Management'!$U:$U,"Identified") -> 0 | C50: =COUNTIFS('Risk Management'!$B:$B,A50,'Risk Management'!$U:$U,"Mitigating") -> 0 | D50: =COUNTIFS('Risk Management'!$B:$B,A50,'Risk Management'!$U:$U,"Occurred") -> 0 | E50: =COUNTIFS('Risk Management'!$B:$B,A50,'Risk Management'!$U:$U,"Closed") -> 0
A51: Project operations | B51: =COUNTIFS('Risk Management'!$B:$B,A51,'Risk Management'!$U:$U,"Identified") -> 0 | C51: =COUNTIFS('Risk Management'!$B:$B,A51,'Risk Management'!$U:$U,"Mitigating") -> 0 | D51: =COUNTIFS('Risk Management'!$B:$B,A51,'Risk Management'!$U:$U,"Occurred") -> 0 | E51: =COUNTIFS('Risk Management'!$B:$B,A51,'Risk Management'!$U:$U,"Closed") -> 0
... A62: Rumor Risk | B62: =COUNTIFS('Risk Management'!$B:$B,A62,'Risk Management'!$U:$U,"Identified") -> 0 | C62: =COUNTIFS('Risk Management'!$B:$B,A62,'Risk Management'!$U:$U,"Mitigating") -> 0 | D62: =COUNTIFS('Risk Management'!$B:$B,A62,'Risk Management'!$U:$U,"Occurred") -> 0 | E62: =COUNTIFS('Risk Management'!$B:$B,A62,'Risk Management'!$U:$U,"Closed") -> 0

Sheet Data
A1: Risk Category | B1: Risk Origin
A2: Financial Risk | B2: Cost, expense, budget management | C2: Funding cycle
A3: Market Risk | B3: Foreign exchange | C3: Business competitors | D3: Customer's change about business, demands
A4: Operation Risk | B4: Technique | C4: Project Requirement | D4: Project Management | E4: Project Characteristics | F4: Project Dependencies | G4: Customer's related problems | H4: Project Environment | I4: Project operations
A5: Information Security Risk | B5: Cyber security | C5: Human interference | D5: Third-Party Suppliers
A6: Compliance Risk | B6: Contract penalties | C6: Project's Non - compliance
A7: Human Risk | B7: Shortage of resource | C7: Skill deficiency | D7: Labor issue
A8: Event Risk | B8: External business sources | C8: Internal business sources
A9: Rumor Risk | B9: Rumor Risk

Sheet Risk Management
D1: RISK MANAGEMENT | S1: No: BM-QT-1704-01
S2: Version: 2.3
S3: Issue Date: 22/09/2026
A4: SUN ASTERISK VIETNAM CO., LTD | S4: ISO/IEC 27001:2013 & ISO 9001:2015
A5: Refer Risk Management Process at here
A6: I. RISK IDENTIFICATION | F6: II.RISK ANALYSIS & EVALUATION | M6: III. PLAN & IMPLEMENT RISK RESPONSE | T6: IV. RISK MONITOR
A7: Identified Date | B7: Risk Origin | C7: Risk Category (Auto fill dựa vào Risk Origin) | D7: Risk Description | E7: Risk Owner | F7: Risk Trigger | G7: Current Control Response (If have) | H7: Probability | I7: Probability Description | J7: Impact | K7: Impact Description | L7: Risk Priority (Probability x Impact) | M7: Risk response | N7: Mitigation Plan | O7: PIC | P7: Deadline | Q7: Status | R7: Contingency Plan | S7: PIC | T7: Review Date | U7: Risk Status | V7: Summary for reporting
A8: 44489 | B8: Technique | C8: =IFS(B8="Cost, expense, budget management","Financial Risk",B8="Funding cycle","Financial Risk",B8="Foreign exchange","Market Risk",B8="Business competitors","Market Risk",B8="Customer's change about business, demands","Market Risk",B8="Project Requirement","Operation Risk",B8="Technique","Operation Risk",B8="Project Characteristics","Operation Risk",B8="Project Dependencies","Operation Risk",B8="Customer's related problems","Operation Risk",B8="Project Environment","Operation Risk",B8="Project operations","Operation Risk",B8="Cyber security","Information Security Risk",B8="Human interference","Information Security Risk",B8="Third-Party Suppliers","Information Security Risk",B8="Contract penalties","Compliance Risk",B8="Project's Non - compliance","Compliance Risk",B8="Shortage of resource","Human Risk",B8="Skill deficiency","Human Risk",B8="Labor issue","Human Risk",B8="External business sources","Event Risk",B8="Internal business sources","Event Risk",B8="Rumor Risk","Rumor Risk",B8="","") -> Operation Risk | D8: Bối cảnh: Khách hàng upload nhiều file lên Redmine của dự án Dẫn đến rủi ro: Dung lượng lưu trữ trên server bị giảm, tốc độ xử lý server bị chậm Ảnh hưởng của rủi ro: Ảnh hưởng đến chất lượng của Redmine, dự án mất thời gian chờ đợi để hệ thống load data | E8: Nguyen Van B | F8: Dấu hiệu rủi ro đã trở thành vấn đề: Dung lượng lưu trữ trên server đạt ngưỡng 90% | G8: Xin nâng cấp dung lượng lưu trữ trên server của khách hàng | H8: High | I8: Đã xảy ra trong dự án vào 08/2020 | J8: Low | K8: Team không load được dữ liệu của ticket để xử lý theo plan. Ảnh hưởng <5% tiến độ của dự án | L8: =IF(OR(H8="",J8=""),"",IF(AND(H8="Low",J8="Low"),"Low",IF(AND(H8="Low",J8="Normal"),"Medium",IF(AND(H8="Normal",J8="Low"),"Medium",IF(AND(H8="Low",J8="High"),"High",IF(AND(H8="Normal",J8="Normal"),"High",IF(AND(H8="High",J8="Low"),"High",IF(AND(H8="Normal",J8="High"),"Extreme",IF(AND(H8="High",J8="Normal"),"Extreme", IF(AND(H8="High",J8="High"),"Critical")))))))))) -> High | M8: Manage | N8: Tham khảo ý kiến khách hàng về việc xoá bớt file/pj ko còn active. | O8: Nguyen Van A | P8: 44489 | Q8: In Progress | R8: Nếu server quá tải thì yêu cầu khách hàng chuyển bớt file tài liệu sang GG Driver | S8: Nguyen Van A | T8: 44499 | U8: Closed | V8: =CONCATENATE("[","Identified date","]",":"," ",TEXT(A8,"yyyy/mm/dd"), CHAR(10),"[", "Risk Description","]",CHAR(10)," ", D8,CHAR(10),"[","Current Control Response(If have)","]",":",CHAR(10),G8,CHAR(10),"[", "Risk Trigger","]",":",CHAR(10), F8,"["," Risk Priority","]",L8,CHAR(10),"[","Mitigation Plan","]",":",CHAR(10), N8,CHAR(10),"[","Contingency Plan","]",":",CHAR(10),R8,CHAR(10),"[", "PIC","]",":",CHAR(10), E8,) -> [Identified date]: 2021/10/20 [Risk Description] Bối cảnh: Khách hàng upload nhiều file lên Redmine của dự án Dẫn đến rủi ro: Dung lượng lưu trữ trên server bị giảm, tốc độ xử lý server bị chậm Ảnh hưởng của rủi ro: Ảnh hưởng đến chất lượng của Redmine, dự án mất thời gian chờ đợi để hệ thống load data [Current Control Response(If have)]: Xin nâng cấp dung lượng lưu trữ trên server của khách hàng [Risk Trigger]: Dấu hiệu rủi ro đã trở thành vấn đề: Dung lượng lưu trữ trên server đạt ngưỡng 90% [ Risk Priority]High [Mitigation Plan]: Tham khảo ý kiến khách hàng về việc xoá bớt file/pj ko còn active. [Contingency Plan]: Nếu server quá tải thì yêu cầu khách hàng chuyển bớt file tài liệu sang GG Driver [PIC]: Nguyen Van B
A9: 44489 | B9: Foreign exchange | C9: =IFS(B9="Cost, expense, budget management","Financial Risk",B9="Funding cycle","Financial Risk",B9="Foreign exchange","Market Risk",B9="Business competitors","Market Risk",B9="Customer's change about business, demands","Market Risk",B9="Project Requirement","Operation Risk",B9="Technique","Operation Risk",B9="Project Characteristics","Operation Risk",B9="Project Dependencies","Operation Risk",B9="Customer's related problems","Operation Risk",B9="Project Environment","Operation Risk",B9="Project operations","Operation Risk",B9="Cyber security","Information Security Risk",B9="Human interference","Information Security Risk",B9="Third-Party Suppliers","Information Security Risk",B9="Contract penalties","Compliance Risk",B9="Project's Non - compliance","Compliance Risk",B9="Shortage of resource","Human Risk",B9="Skill deficiency","Human Risk",B9="Labor issue","Human Risk",B9="External business sources","Event Risk",B9="Internal business sources","Event Risk",B9="Rumor Risk","Rumor Risk",B9="","") -> Market Risk | D9: Bối cảnh: PC mới không có kinh nghiệm quản lý dự án Dẫn đến rủi ro: Không detect kịp thời các risk, issue trong dự án Ảnh hưởng của rủi ro: Các bên liên quan không kịp thời nắm được issue dự án | E9: Nguyen Van B | F9: Tiến độ bị trễ 2 tuần so với kế hoạch mới nhận ra để report cho khách hàng | H9: Normal | I9: Có thể xảy ra vào 1 lúc nào đó | J9: High | K9: Có khả năng bị ảnh hưởng 25% tiến độ dự án | L9: =IF(OR(H9="",J9=""),"",IF(AND(H9="Low",J9="Low"),"Low",IF(AND(H9="Low",J9="Normal"),"Medium",IF(AND(H9="Normal",J9="Low"),"Medium",IF(AND(H9="Low",J9="High"),"High",IF(AND(H9="Normal",J9="Normal"),"High",IF(AND(H9="High",J9="Low"),"High",IF(AND(H9="Normal",J9="High"),"Extreme",IF(AND(H9="High",J9="Normal"),"Extreme", IF(AND(H9="High",J9="High"),"Critical")))))))))) -> Extreme | M9: Manage | N9: - Tham gia các khóa training định kỳ trong group/section/công ty - Define cách thức đánh giá và tần suất tracking tiến độ dự án. | O9: Nguyen Van A | P9: 44494 | Q9: Open | R9: - Add Senior hỗ trợ xử lý vấn đề | S9: Nguyen Van A | T9: 44499 | U9: Identified | V9: =CONCATENATE("[","Identified date","]",":"," ",TEXT(A9,"yyyy/mm/dd"),CHAR(10),"[", "Risk Description","]",CHAR(10)," ", D9,CHAR(10),"[","Current Control Response(If have)","]",":",CHAR(10),G9,CHAR(10),"[", "Risk Trigger","]",":",CHAR(10), F9,"["," Risk Priority","]",L9,CHAR(10),"[","Mitigation Plan","]",":",CHAR(10), N9,CHAR(10),"[","Contingency Plan","]",":",CHAR(10),R9,CHAR(10),"[", "PIC","]",":",CHAR(10), E9,) -> [Identified date]: 2021/10/20 [Risk Description] Bối cảnh: PC mới không có kinh nghiệm quản lý dự án Dẫn đến rủi ro: Không detect kịp thời các risk, issue trong dự án Ảnh hưởng của rủi ro: Các bên liên quan không kịp thời nắm được issue dự án [Current Control Response(If have)]: [Risk Trigger]: Tiến độ bị trễ 2 tuần so với kế hoạch mới nhận ra để report cho khách hàng[ Risk Priority]Extreme [Mitigation Plan]: - Tham gia các khóa training định kỳ trong group/section/công ty - Define cách thức đánh giá và tần suất tracking tiến độ dự án. [Contingency Plan]: - Add Senior hỗ trợ xử lý vấn đề [PIC]: Nguyen Van B
B10: Project Management | C10: =IFS(B10="Cost, expense, budget management","Financial Risk",B10="Funding cycle","Financial Risk",B10="Foreign exchange","Market Risk",B10="Business competitors","Market Risk",B10="Customer's change about business, demands","Market Risk",B10="Project Requirement","Operation Risk",B10="Technique","Operation Risk",B10="Project Characteristics","Operation Risk",B10="Project Dependencies","Operation Risk",B10="Customer's related problems","Operation Risk",B10="Project Environment","Operation Risk",B10="Project operations","Operation Risk",B10="Cyber security","Information Security Risk",B10="Human interference","Information Security Risk",B10="Third-Party Suppliers","Information Security Risk",B10="Contract penalties","Compliance Risk",B10="Project's Non - compliance","Compliance Risk",B10="Shortage of resource","Human Risk",B10="Skill deficiency","Human Risk",B10="Labor issue","Human Risk",B10="External business sources","Event Risk",B10="Internal business sources","Event Risk",B10="Rumor Risk","Rumor Risk",B10="","") -> #N/A
C11: =IFS(B11="Cost, expense, budget management","Financial Risk",B11="Funding cycle","Financial Risk",B11="Foreign exchange","Market Risk",B11="Business competitors","Market Risk",B11="Customer's change about business, demands","Market Risk",B11="Project Requirement","Operation Risk",B11="Technique","Operation Risk",B11="Project Characteristics","Operation Risk",B11="Project Dependencies","Operation Risk",B11="Customer's related problems","Operation Risk",B11="Project Environment","Operation Risk",B11="Project operations","Operation Risk",B11="Cyber security","Information Security Risk",B11="Human interference","Information Security Risk",B11="Third-Party Suppliers","Information Security Risk",B11="Contract penalties","Compliance Risk",B11="Project's Non - compliance","Compliance Risk",B11="Shortage of resource","Human Risk",B11="Skill deficiency","Human Risk",B11="Labor issue","Human Risk",B11="External business sources","Event Risk",B11="Internal business sources","Event Risk",B11="Rumor Risk","Rumor Risk",B11="","") | L11: =IF(OR(H11="",J11=""),"",IF(AND(H11="Low",J11="Low"),"Low",IF(AND(H11="Low",J11="Normal"),"Medium",IF(AND(H11="Normal",J11="Low"),"Medium",IF(AND(H11="Low",J11="High"),"High",IF(AND(H11="Normal",J11="Normal"),"High",IF(AND(H11="High",J11="Low"),"High",IF(AND(H11="Normal",J11="High"),"Extreme",IF(AND(H11="High",J11="Normal"),"Extreme", IF(AND(H11="High",J11="High"),"Critical"))))))))))
C12: =IFS(B12="Cost, expense, budget management","Financial Risk",B12="Funding cycle","Financial Risk",B12="Foreign exchange","Market Risk",B12="Business competitors","Market Risk",B12="Customer's change about business, demands","Market Risk",B12="Project Requirement","Operation Risk",B12="Technique","Operation Risk",B12="Project Characteristics","Operation Risk",B12="Project Dependencies","Operation Risk",B12="Customer's related problems","Operation Risk",B12="Project Environment","Operation Risk",B12="Project operations","Operation Risk",B12="Cyber security","Information Security Risk",B12="Human interference","Information Security Risk",B12="Third-Party Suppliers","Information Security Risk",B12="Contract penalties","Compliance Risk",B12="Project's Non - compliance","Compliance Risk",B12="Shortage of resource","Human Risk",B12="Skill deficiency","Human Risk",B12="Labor issue","Human Risk",B12="External business sources","Event Risk",B12="Internal business sources","Event Risk",B12="Rumor Risk","Rumor Risk",B12="","")
C13: =IFS(B13="Cost, expense, budget management","Financial Risk",B13="Funding cycle","Financial Risk",B13="Foreign exchange","Market Risk",B13="Business competitors","Market Risk",B13="Customer's change about business, demands","Market Risk",B13="Project Requirement","Operation Risk",B13="Technique","Operation Risk",B13="Project Characteristics","Operation Risk",B13="Project Dependencies","Operation Risk",B13="Customer's related problems","Operation Risk",B13="Project Environment","Operation Risk",B13="Project operations","Operation Risk",B13="Cyber security","Information Security Risk",B13="Human interference","Information Security Risk",B13="Third-Party Suppliers","Information Security Risk",B13="Contract penalties","Compliance Risk",B13="Project's Non - compliance","Compliance Risk",B13="Shortage of resource","Human Risk",B13="Skill deficiency","Human Risk",B13="Labor issue","Human Risk",B13="External business sources","Event Risk",B13="Internal business sources","Event Risk",B13="Rumor Risk","Rumor Risk",B13="","") | L13: =IF(OR(H13="",J13=""),"",IF(AND(H13="Low",J13="Low"),"Low",IF(AND(H13="Low",J13="Normal"),"Medium",IF(AND(H13="Normal",J13="Low"),"Medium",IF(AND(H13="Low",J13="High"),"High",IF(AND(H13="Normal",J13="Normal"),"High",IF(AND(H13="High",J13="Low"),"High",IF(AND(H13="Normal",J13="High"),"Extreme",IF(AND(H13="High",J13="Normal"),"Extreme", IF(AND(H13="High",J13="High"),"Critical"))))))))))
C14: =IFS(B14="Cost, expense, budget management","Financial Risk",B14="Funding cycle","Financial Risk",B14="Foreign exchange","Market Risk",B14="Business competitors","Market Risk",B14="Customer's change about business, demands","Market Risk",B14="Project Requirement","Operation Risk",B14="Technique","Operation Risk",B14="Project Characteristics","Operation Risk",B14="Project Dependencies","Operation Risk",B14="Customer's related problems","Operation Risk",B14="Project Environment","Operation Risk",B14="Project operations","Operation Risk",B14="Cyber security","Information Security Risk",B14="Human interference","Information Security Risk",B14="Third-Party Suppliers","Information Security Risk",B14="Contract penalties","Compliance Risk",B14="Project's Non - compliance","Compliance Risk",B14="Shortage of resource","Human Risk",B14="Skill deficiency","Human Risk",B14="Labor issue","Human Risk",B14="External business sources","Event Risk",B14="Internal business sources","Event Risk",B14="Rumor Risk","Rumor Risk",B14="","") | L14: =IF(OR(H14="",J14=""),"",IF(AND(H14="Low",J14="Low"),"Low",IF(AND(H14="Low",J14="Normal"),"Medium",IF(AND(H14="Normal",J14="Low"),"Medium",IF(AND(H14="Low",J14="High"),"High",IF(AND(H14="Normal",J14="Normal"),"High",IF(AND(H14="High",J14="Low"),"High",IF(AND(H14="Normal",J14="High"),"Extreme",IF(AND(H14="High",J14="Normal"),"Extreme", IF(AND(H14="High",J14="High"),"Critical"))))))))))
C15: =IFS(B15="Cost, expense, budget management","Financial Risk",B15="Funding cycle","Financial Risk",B15="Foreign exchange","Market Risk",B15="Business competitors","Market Risk",B15="Customer's change about business, demands","Market Risk",B15="Project Requirement","Operation Risk",B15="Technique","Operation Risk",B15="Project Characteristics","Operation Risk",B15="Project Dependencies","Operation Risk",B15="Customer's related problems","Operation Risk",B15="Project Environment","Operation Risk",B15="Project operations","Operation Risk",B15="Cyber security","Information Security Risk",B15="Human interference","Information Security Risk",B15="Third-Party Suppliers","Information Security Risk",B15="Contract penalties","Compliance Risk",B15="Project's Non - compliance","Compliance Risk",B15="Shortage of resource","Human Risk",B15="Skill deficiency","Human Risk",B15="Labor issue","Human Risk",B15="External business sources","Event Risk",B15="Internal business sources","Event Risk",B15="Rumor Risk","Rumor Risk",B15="","") | L15: =IF(OR(H15="",J15=""),"",IF(AND(H15="Low",J15="Low"),"Low",IF(AND(H15="Low",J15="Normal"),"Medium",IF(AND(H15="Normal",J15="Low"),"Medium",IF(AND(H15="Low",J15="High"),"High",IF(AND(H15="Normal",J15="Normal"),"High",IF(AND(H15="High",J15="Low"),"High",IF(AND(H15="Normal",J15="High"),"Extreme",IF(AND(H15="High",J15="Normal"),"Extreme", IF(AND(H15="High",J15="High"),"Critical"))))))))))
C16: =IFS(B16="Cost, expense, budget management","Financial Risk",B16="Funding cycle","Financial Risk",B16="Foreign exchange","Market Risk",B16="Business competitors","Market Risk",B16="Customer's change about business, demands","Market Risk",B16="Project Requirement","Operation Risk",B16="Technique","Operation Risk",B16="Project Characteristics","Operation Risk",B16="Project Dependencies","Operation Risk",B16="Customer's related problems","Operation Risk",B16="Project Environment","Operation Risk",B16="Project operations","Operation Risk",B16="Cyber security","Information Security Risk",B16="Human interference","Information Security Risk",B16="Third-Party Suppliers","Information Security Risk",B16="Contract penalties","Compliance Risk",B16="Project's Non - compliance","Compliance Risk",B16="Shortage of resource","Human Risk",B16="Skill deficiency","Human Risk",B16="Labor issue","Human Risk",B16="External business sources","Event Risk",B16="Internal business sources","Event Risk",B16="Rumor Risk","Rumor Risk",B16="","") | L16: =IF(OR(H16="",J16=""),"",IF(AND(H16="Low",J16="Low"),"Low",IF(AND(H16="Low",J16="Normal"),"Medium",IF(AND(H16="Normal",J16="Low"),"Medium",IF(AND(H16="Low",J16="High"),"High",IF(AND(H16="Normal",J16="Normal"),"High",IF(AND(H16="High",J16="Low"),"High",IF(AND(H16="Normal",J16="High"),"Extreme",IF(AND(H16="High",J16="Normal"),"Extreme", IF(AND(H16="High",J16="High"),"Critical"))))))))))
C17: =IFS(B17="Cost, expense, budget management","Financial Risk",B17="Funding cycle","Financial Risk",B17="Foreign exchange","Market Risk",B17="Business competitors","Market Risk",B17="Customer's change about business, demands","Market Risk",B17="Project Requirement","Operation Risk",B17="Technique","Operation Risk",B17="Project Characteristics","Operation Risk",B17="Project Dependencies","Operation Risk",B17="Customer's related problems","Operation Risk",B17="Project Environment","Operation Risk",B17="Project operations","Operation Risk",B17="Cyber security","Information Security Risk",B17="Human interference","Information Security Risk",B17="Third-Party Suppliers","Information Security Risk",B17="Contract penalties","Compliance Risk",B17="Project's Non - compliance","Compliance Risk",B17="Shortage of resource","Human Risk",B17="Skill deficiency","Human Risk",B17="Labor issue","Human Risk",B17="External business sources","Event Risk",B17="Internal business sources","Event Risk",B17="Rumor Risk","Rumor Risk",B17="","") | L17: =IF(OR(H17="",J17=""),"",IF(AND(H17="Low",J17="Low"),"Low",IF(AND(H17="Low",J17="Normal"),"Medium",IF(AND(H17="Normal",J17="Low"),"Medium",IF(AND(H17="Low",J17="High"),"High",IF(AND(H17="Normal",J17="Normal"),"High",IF(AND(H17="High",J17="Low"),"High",IF(AND(H17="Normal",J17="High"),"Extreme",IF(AND(H17="High",J17="Normal"),"Extreme", IF(AND(H17="High",J17="High"),"Critical"))))))))))
C18: =IFS(B18="Cost, expense, budget management","Financial Risk",B18="Funding cycle","Financial Risk",B18="Foreign exchange","Market Risk",B18="Business competitors","Market Risk",B18="Customer's change about business, demands","Market Risk",B18="Project Requirement","Operation Risk",B18="Technique","Operation Risk",B18="Project Characteristics","Operation Risk",B18="Project Dependencies","Operation Risk",B18="Customer's related problems","Operation Risk",B18="Project Environment","Operation Risk",B18="Project operations","Operation Risk",B18="Cyber security","Information Security Risk",B18="Human interference","Information Security Risk",B18="Third-Party Suppliers","Information Security Risk",B18="Contract penalties","Compliance Risk",B18="Project's Non - compliance","Compliance Risk",B18="Shortage of resource","Human Risk",B18="Skill deficiency","Human Risk",B18="Labor issue","Human Risk",B18="External business sources","Event Risk",B18="Internal business sources","Event Risk",B18="Rumor Risk","Rumor Risk",B18="","") | L18: =IF(OR(H18="",J18=""),"",IF(AND(H18="Low",J18="Low"),"Low",IF(AND(H18="Low",J18="Normal"),"Medium",IF(AND(H18="Normal",J18="Low"),"Medium",IF(AND(H18="Low",J18="High"),"High",IF(AND(H18="Normal",J18="Normal"),"High",IF(AND(H18="High",J18="Low"),"High",IF(AND(H18="Normal",J18="High"),"Extreme",IF(AND(H18="High",J18="Normal"),"Extreme", IF(AND(H18="High",J18="High"),"Critical"))))))))))
C19: =IFS(B19="Cost, expense, budget management","Financial Risk",B19="Funding cycle","Financial Risk",B19="Foreign exchange","Market Risk",B19="Business competitors","Market Risk",B19="Customer's change about business, demands","Market Risk",B19="Project Requirement","Operation Risk",B19="Technique","Operation Risk",B19="Project Characteristics","Operation Risk",B19="Project Dependencies","Operation Risk",B19="Customer's related problems","Operation Risk",B19="Project Environment","Operation Risk",B19="Project operations","Operation Risk",B19="Cyber security","Information Security Risk",B19="Human interference","Information Security Risk",B19="Third-Party Suppliers","Information Security Risk",B19="Contract penalties","Compliance Risk",B19="Project's Non - compliance","Compliance Risk",B19="Shortage of resource","Human Risk",B19="Skill deficiency","Human Risk",B19="Labor issue","Human Risk",B19="External business sources","Event Risk",B19="Internal business sources","Event Risk",B19="Rumor Risk","Rumor Risk",B19="","") | L19: =IF(OR(H19="",J19=""),"",IF(AND(H19="Low",J19="Low"),"Low",IF(AND(H19="Low",J19="Normal"),"Medium",IF(AND(H19="Normal",J19="Low"),"Medium",IF(AND(H19="Low",J19="High"),"High",IF(AND(H19="Normal",J19="Normal"),"High",IF(AND(H19="High",J19="Low"),"High",IF(AND(H19="Normal",J19="High"),"Extreme",IF(AND(H19="High",J19="Normal"),"Extreme", IF(AND(H19="High",J19="High"),"Critical"))))))))))
C20: =IFS(B20="Cost, expense, budget management","Financial Risk",B20="Funding cycle","Financial Risk",B20="Foreign exchange","Market Risk",B20="Business competitors","Market Risk",B20="Customer's change about business, demands","Market Risk",B20="Project Requirement","Operation Risk",B20="Technique","Operation Risk",B20="Project Characteristics","Operation Risk",B20="Project Dependencies","Operation Risk",B20="Customer's related problems","Operation Risk",B20="Project Environment","Operation Risk",B20="Project operations","Operation Risk",B20="Cyber security","Information Security Risk",B20="Human interference","Information Security Risk",B20="Third-Party Suppliers","Information Security Risk",B20="Contract penalties","Compliance Risk",B20="Project's Non - compliance","Compliance Risk",B20="Shortage of resource","Human Risk",B20="Skill deficiency","Human Risk",B20="Labor issue","Human Risk",B20="External business sources","Event Risk",B20="Internal business sources","Event Risk",B20="Rumor Risk","Rumor Risk",B20="","") | L20: =IF(OR(H20="",J20=""),"",IF(AND(H20="Low",J20="Low"),"Low",IF(AND(H20="Low",J20="Normal"),"Medium",IF(AND(H20="Normal",J20="Low"),"Medium",IF(AND(H20="Low",J20="High"),"High",IF(AND(H20="Normal",J20="Normal"),"High",IF(AND(H20="High",J20="Low"),"High",IF(AND(H20="Normal",J20="High"),"Extreme",IF(AND(H20="High",J20="Normal"),"Extreme", IF(AND(H20="High",J20="High"),"Critical"))))))))))
C21: =IFS(B21="Cost, expense, budget management","Financial Risk",B21="Funding cycle","Financial Risk",B21="Foreign exchange","Market Risk",B21="Business competitors","Market Risk",B21="Customer's change about business, demands","Market Risk",B21="Project Requirement","Operation Risk",B21="Technique","Operation Risk",B21="Project Characteristics","Operation Risk",B21="Project Dependencies","Operation Risk",B21="Customer's related problems","Operation Risk",B21="Project Environment","Operation Risk",B21="Project operations","Operation Risk",B21="Cyber security","Information Security Risk",B21="Human interference","Information Security Risk",B21="Third-Party Suppliers","Information Security Risk",B21="Contract penalties","Compliance Risk",B21="Project's Non - compliance","Compliance Risk",B21="Shortage of resource","Human Risk",B21="Skill deficiency","Human Risk",B21="Labor issue","Human Risk",B21="External business sources","Event Risk",B21="Internal business sources","Event Risk",B21="Rumor Risk","Rumor Risk",B21="","") | L21: =IF(OR(H21="",J21=""),"",IF(AND(H21="Low",J21="Low"),"Low",IF(AND(H21="Low",J21="Normal"),"Medium",IF(AND(H21="Normal",J21="Low"),"Medium",IF(AND(H21="Low",J21="High"),"High",IF(AND(H21="Normal",J21="Normal"),"High",IF(AND(H21="High",J21="Low"),"High",IF(AND(H21="Normal",J21="High"),"Extreme",IF(AND(H21="High",J21="Normal"),"Extreme", IF(AND(H21="High",J21="High"),"Critical"))))))))))
C22: =IFS(B22="Cost, expense, budget management","Financial Risk",B22="Funding cycle","Financial Risk",B22="Foreign exchange","Market Risk",B22="Business competitors","Market Risk",B22="Customer's change about business, demands","Market Risk",B22="Project Requirement","Operation Risk",B22="Technique","Operation Risk",B22="Project Characteristics","Operation Risk",B22="Project Dependencies","Operation Risk",B22="Customer's related problems","Operation Risk",B22="Project Environment","Operation Risk",B22="Project operations","Operation Risk",B22="Cyber security","Information Security Risk",B22="Human interference","Information Security Risk",B22="Third-Party Suppliers","Information Security Risk",B22="Contract penalties","Compliance Risk",B22="Project's Non - compliance","Compliance Risk",B22="Shortage of resource","Human Risk",B22="Skill deficiency","Human Risk",B22="Labor issue","Human Risk",B22="External business sources","Event Risk",B22="Internal business sources","Event Risk",B22="Rumor Risk","Rumor Risk",B22="","") | L22: =IF(OR(H22="",J22=""),"",IF(AND(H22="Low",J22="Low"),"Low",IF(AND(H22="Low",J22="Normal"),"Medium",IF(AND(H22="Normal",J22="Low"),"Medium",IF(AND(H22="Low",J22="High"),"High",IF(AND(H22="Normal",J22="Normal"),"High",IF(AND(H22="High",J22="Low"),"High",IF(AND(H22="Normal",J22="High"),"Extreme",IF(AND(H22="High",J22="Normal"),"Extreme", IF(AND(H22="High",J22="High"),"Critical"))))))))))
C23: =IFS(B23="Cost, expense, budget management","Financial Risk",B23="Funding cycle","Financial Risk",B23="Foreign exchange","Market Risk",B23="Business competitors","Market Risk",B23="Customer's change about business, demands","Market Risk",B23="Project Requirement","Operation Risk",B23="Technique","Operation Risk",B23="Project Characteristics","Operation Risk",B23="Project Dependencies","Operation Risk",B23="Customer's related problems","Operation Risk",B23="Project Environment","Operation Risk",B23="Project operations","Operation Risk",B23="Cyber security","Information Security Risk",B23="Human interference","Information Security Risk",B23="Third-Party Suppliers","Information Security Risk",B23="Contract penalties","Compliance Risk",B23="Project's Non - compliance","Compliance Risk",B23="Shortage of resource","Human Risk",B23="Skill deficiency","Human Risk",B23="Labor issue","Human Risk",B23="External business sources","Event Risk",B23="Internal business sources","Event Risk",B23="Rumor Risk","Rumor Risk",B23="","") | L23: =IF(OR(H23="",J23=""),"",IF(AND(H23="Low",J23="Low"),"Low",IF(AND(H23="Low",J23="Normal"),"Medium",IF(AND(H23="Normal",J23="Low"),"Medium",IF(AND(H23="Low",J23="High"),"High",IF(AND(H23="Normal",J23="Normal"),"High",IF(AND(H23="High",J23="Low"),"High",IF(AND(H23="Normal",J23="High"),"Extreme",IF(AND(H23="High",J23="Normal"),"Extreme", IF(AND(H23="High",J23="High"),"Critical"))))))))))
C24: =IFS(B24="Cost, expense, budget management","Financial Risk",B24="Funding cycle","Financial Risk",B24="Foreign exchange","Market Risk",B24="Business competitors","Market Risk",B24="Customer's change about business, demands","Market Risk",B24="Project Requirement","Operation Risk",B24="Technique","Operation Risk",B24="Project Characteristics","Operation Risk",B24="Project Dependencies","Operation Risk",B24="Customer's related problems","Operation Risk",B24="Project Environment","Operation Risk",B24="Project operations","Operation Risk",B24="Cyber security","Information Security Risk",B24="Human interference","Information Security Risk",B24="Third-Party Suppliers","Information Security Risk",B24="Contract penalties","Compliance Risk",B24="Project's Non - compliance","Compliance Risk",B24="Shortage of resource","Human Risk",B24="Skill deficiency","Human Risk",B24="Labor issue","Human Risk",B24="External business sources","Event Risk",B24="Internal business sources","Event Risk",B24="Rumor Risk","Rumor Risk",B24="","") | L24: =IF(OR(H24="",J24=""),"",IF(AND(H24="Low",J24="Low"),"Low",IF(AND(H24="Low",J24="Normal"),"Medium",IF(AND(H24="Normal",J24="Low"),"Medium",IF(AND(H24="Low",J24="High"),"High",IF(AND(H24="Normal",J24="Normal"),"High",IF(AND(H24="High",J24="Low"),"High",IF(AND(H24="Normal",J24="High"),"Extreme",IF(AND(H24="High",J24="Normal"),"Extreme", IF(AND(H24="High",J24="High"),"Critical"))))))))))
... C30: =IFS(B30="Cost, expense, budget management","Financial Risk",B30="Funding cycle","Financial Risk",B30="Foreign exchange","Market Risk",B30="Business competitors","Market Risk",B30="Customer's change about business, demands","Market Risk",B30="Project Requirement","Operation Risk",B30="Technique","Operation Risk",B30="Project Characteristics","Operation Risk",B30="Project Dependencies","Operation Risk",B30="Customer's related problems","Operation Risk",B30="Project Environment","Operation Risk",B30="Project operations","Operation Risk",B30="Cyber security","Information Security Risk",B30="Human interference","Information Security Risk",B30="Third-Party Suppliers","Information Security Risk",B30="Contract penalties","Compliance Risk",B30="Project's Non - compliance","Compliance Risk",B30="Shortage of resource","Human Risk",B30="Skill deficiency","Human Risk",B30="Labor issue","Human Risk",B30="External business sources","Event Risk",B30="Internal business sources","Event Risk",B30="Rumor Risk","Rumor Risk",B30="","") | L30: =IF(OR(H30="",J30=""),"",IF(AND(H30="Low",J30="Low"),"Low",IF(AND(H30="Low",J30="Normal"),"Medium",IF(AND(H30="Normal",J30="Low"),"Medium",IF(AND(H30="Low",J30="High"),"High",IF(AND(H30="Normal",J30="Normal"),"High",IF(AND(H30="High",J30="Low"),"High",IF(AND(H30="Normal",J30="High"),"Extreme",IF(AND(H30="High",J30="Normal"),"Extreme", IF(AND(H30="High",J30="High"),"Critical"))))))))))

Sheet Appendix
A2: 1- Risk Category
A3: Risk Category | B3: Risk Origin | C3: Description
A4: Financial Risk | B4: ● Cost, expense, budget management | C4: ● Rủi ro chi phí do lỗi lập kế hoạch ngân sách, quản lý chi phí dự án không chính xác, mức phạt và phạm vi ảnh hưởng.
B5: ● Funding cycle | C5: ● Chu kỳ cấp vốn
A6: Market Risk | B6: ● Foreign exchange | C6: ● Rủi ro về biến động tỷ giá.
B7: ● Business competitors | C7: ● Rủi ro đến từ các đối thủ kinh doanh cùng ngành
B8: ● Customer's change about business, demands | C8: ● Những thay đổi của công việc kinh doanh, nhu cầu của Khách hàng ảnh hưởng đến sản phẩm được phát triển.
A9: Operation Risk | B9: ● Technique | C9: ● Rủi ro về Kỹ thuật: thay đổi về công nghệ, sử dụng công nghệ mới. Rủi ro kỹ thuật liên quan đến vấn đề phương pháp, triển khai, giao diện, thử nghiệm và bảo trì tiềm ẩn.
B10: ● Project Requirement | C10: ● Rủi ro về Spect của dự án: Spec sai hoặc thiếu chi tiết, do sự hiểu sai yêu cầu về sản phẩm từ phía đội ngũ quản lý dự án.
B11: ● Project Management | C11: ● Rủi ro trong hoạt động Quản lý dự án: Quản lý kế hoạch dòng đời của dự án, theo dõi task, quá trình giao tiếp với khách hàng, đội dự án, chuyển giao thông tin ...
B12: ● Project Characteristics | C12: ● Rủi ro từ đặc điểm của dự án: Rủi ro từ các đặc điểm của dự án như các loại dự án: fix price, maintain, phát triển nhanh, ngắn hạn...
B13: ● Project Dependencies | C13: ● Rủi ro từ những bên liên quan: Rủi ro từ nhà cung cấp dịch vụ, sản phẩm / đơn vị gia công bên ngoài (nếu có)
B14: ● Customer's related problems | C14: ● Rủi ro quan đến khách hàng: Kinh nghiệm phát triển phần mềm của khách hàng (công ty CNTT, công ty phi CNTT, ..), tổng số điểm tiếp xúc của khách hàng, ...
B15: ● Project Environment | C15: ● Rủi ro về môi trường dự án: Rủi ro từ hạ tầng, phần cứng / phần mềm như giấy phép, đa nền tảng, ... ảnh hưởng đến chi phí, hạn chế của dự án.
B16: ● Project operations | C16: ● Hoạt động dự án: Lỗi từ hoạt động Release, Testing, chất lượng sourcode không được đảm bảo cùng với CI, UT và quy trình review source code.
A17: Information Security Risk | B17: ● Security Requirement | C17: ● Rủi ro liên quan đến việc các yêu cầu về Bảo mật không được cover đầy đủ trong quá trình phát triển sản phẩm
B18: ● Cyber security | C18: ● Rủi ro An ninh mạng: Không đáp ứng yêu cầu cơ bản về an ninh mạng, thiếu chính sách an ninh mạng, không tuân thủ quy định về an ninh mạng - không đảm bảo tính toàn vẹn, tính khả dụng, bảo mật của thông tin. ● Thiếu kế hoạch khôi phục - tính toàn vẹn của thông tin, tính khả dụng không được đảm bảo
B19: ● Human interference | C19: ● Sự can thiệp của con người: rò rỉ mã nguồn, thông tin dự án...
B20: ● Third-Party Suppliers | C20: ● Dữ liệu bị lộ ra bên ngoài thông qua nhà cung cấp bên thứ ba ● Tiết lộ mật khẩu ● Vi phạm bản quyền sử dụng, cấp phép phần mềm ...
A21: Compliance Risk | B21: ● Contract penalties | C21: ● Phạt hợp đồng: Những điều khoản hợp đồng: thời gian, các điều khoản bị vi phạm
B22: ● Project's Non - compliance | C22: ● Không tuân thủ hoạt động kinh doanh của bên thứ ba: giấy phép, quy định ...
A23: Human Risk | B23: ● Shortage of resource | C23: ● Thiếu nguồn lực: nhân viên ốm đau, không đủ nguồn lực ...
B24: ● Skill deficiency | C24: ● Thiếu kỹ năng: thiếu chuyên môn...
B25: ● Labor issue | C25: ● Cơ cấu tổ chức: sự thay đổi của ban lãnh đạo, từ đó có thể dẫn đến sự thay đổi trong định hướng chiến lược. ● Vấn đề về nguồn lực nói chung
A26: Event Risk | B26: ● External business sources | C26: ● Rủi ro kinh doanh bên ngoài: thiên tai, dịch bệnh, tấn công mạng...
B27: ● Internal business sources | C27: ● Rủi ro kinh doanh nội bộ là các mối đe dọa đến từ bên trong công ty, chẳng hạn như không tuân thủ, nợ quá nhiều hoặc tranh chấp lao động.
A28: Rumor Risk | B28: ● Rumor Risk | C28: ● Sự cố dự án xảy ra thường xuyên và / hoặc mức độ ưu tiên sự cố nghiêm trọng có thể làm giảm uy tín của công ty khách hàng. ● Tin đồn làm giảm hiệu suất dự án, sa sút tinh thần làm việc, ...
A30: 2- Estimate Probability of risk
A31: Đánh giá khả năng xảy ra của rủi ro:
A32: Probability | B32: Explanation
A33: High | B33: ● Có thể sẽ xảy ra trong hầu hết các trường hợp hoặc dự kiến sẽ xảy ra trong hầu hết các trường hợp; ● Đã xảy ra gần đây trong dự án/ trong các dự án tương tự khác/ trong các tổ chức tương tự khác.
A34: Normal | B34: ● Có thể xảy ra vào một lúc nào đó; ● Có cơ hội hợp lý nhưng không hoàn toàn được mong đợi sẽ xảy ra trong tương lai; ● Đã xảy ra ít nhất một lần trong tổ chức này hoặc được coi là có cơ hội xảy ra trong dự án của bạn; ● Chưa bao giờ xảy ra ở tổ chức này nhưng hiếm khi xảy ra ở các tổ chức tương tự khác.
A35: Low | B35: ● Rất khó xảy ra; ● Không thường xuyên xảy ra hoặc dự kiến không xảy ra; ● Chỉ có thể xảy ra trong trường hợp ngoại lệ; ● Có thể xảy ra nhưng chưa xảy ra trong lịch sử của tổ chức này hoặc bất kỳ tổ chức nào tương tự.
A37: 3- Estimate Impact of risk
A38: Đánh giá mức độ Ảnh hưởng khi rủi ro xảy ra theo các mức độ Low - Normal - High:
A39: Impact | B39: Schedule/Cost/Project Scope | F39: End User | G39: Financial | H39: Reputation | J39: Leaking project assets
A40: Low | B40: < 5% project size affected Or Minor areas of project scope affected < 5% project effort /cost increase < 5% project duration increase | F40: < 20% | G40: < $1,000 | H40: Không ảnh hưởng, không bị lộ ra bên ngoài | J40: Level 1
A41: Normal | B41: 5% - 20% project size affected 5% - 20% project effort /cost increase 5% - 20% project duration increase | F41: 20% - 80% | G41: $10,000-$1,000 | H41: Công bố nội bộ: Trong công ty khách hàng hoặc trong các công ty bên liên quan | J41: Level 2
A42: High | B42: > 20% project size affected Or Minor areas of project scope affected > 20% project effort /cost increase > 20% project duration increase | F42: > 80% | G42: > $10,000 | H42: Quảng bá ra bên ngoài: TV, trang web tin tức trọng điểm. | J42: Level 3
A44: 4- Risk Priority
...
