Workbook
Name API: API_List!$A$9:$A$35

Sheet History of changes
E1: Screen Specification | M1: No: BM-QT-1701-29
M2: Version: 2.2
M3: Issue Date: 22/09/2026
A4: SUN ASTERISK VIETNAM CO., LTD | M4: ISO/IEC 27001:2013&ISO 9001:2015
E6: History of changes
A7: No | B7: Version | E7: Action | F7: Sheet Name | H7: Description | M7: Link to updated cells | N7: Updated Date | O7: Updated By
A8: =row()-7 -> 1 | B8: Ver 1.0 | E8: Add New | F8: [Template]01_Name | H8: Create New | M8: https://docs.google.com/spreadsheets/d/1SZoDhtySiZ4HTcHT2ryxAS2Q5A9V3VqpvVXGHNNjIpY/edit#gid=221804026 | N8: 44273
A9: =row()-7 -> 2 | B9: Ver 2.0 | E9: Updated | H9: Customize format | N9: 44977
A10: =row()-7 -> 3 | B10: Ver 2.1 | E10: Updated | H10: 1. Add new sheets: - API_List. - Common_Spec. - (Sample) [A001] Search_SearchTop 2. Customize format sheet: - (Template) [ID] ScreenCategory_ScreenName - (TemplateSimple) [ID] ScreenCategory_ScreenName | N10: 45709
A11: =row()-7 -> 4 | B11: Ver 2.2 | E11: Updated | F11: All sheet | H11: Update mã biểu mẫu theo tiêu chuẩn ISO. | N11: 22/09/2026
A12: =row()-7 -> 5
A13: =row()-7 -> 6
A14: =row()-7 -> 7
A15: =row()-7 -> 8
A16: =row()-7 -> 9
A17: =row()-7 -> 10
A18: =row()-7 -> 11

Sheet Screen_List
B1: Screen Specification | D1: No: BM-QT-1701-29
D2: Version: 2.2
D3: Issue Date: 22/09/2026
A4: SUN ASTERISK VIETNAM CO., LTD | D4: ISO/IEC 27001:2013&ISO 9001:2015
A6: Screen List
A8: Screen ID | B8: Screen / Feature category | C8: Screen name | D8: Note
A9: A001 | B9: 検索 | C9: 検索TOP画面
A10: A002 | B10: 検索 | C10: 検索詳細画面

Sheet Common_Message_List
C1: Screen Specification | E1: No: BM-QT-1701-29
E2: Version: 2.2
E3: Issue Date: 22/09/2026
A4: SUN ASTERISK VIETNAM CO., LTD | E4: ISO/IEC 27001:2013&ISO 9001:2015
A6: Common Message List
A8: Message ID | B8: Category | C8: Original Message | D8: - English / Vietnamese - | E8: Description | F8: Note
A9: M_01 | B9: Error | C9: {field}は必須です | D9: {field} is required
A10: M_02 | C10: {field}を入力してください | D10: {field} can't be blank
A11: M_03 | C11: {field}は{value}より大きい必要があります | D11: {field} must be greater than {value}
A12: M_04 | C12: {field}は{value}以上である必要があります | D12: {field} must be greater than or equal to {value}
A13: M_05 | C13: {field}は{value}未満である必要があります | D13: {field} must be less than {value}
A14: M_06 | C14: {field}は{value}以下である必要があります | D14: {field} must be less than or equal to {value}
A15: M_07 | C15: {field}は無効な値です | D15: {field} is invalid
A16: M_08 | C16: {field}は数値ではありません | D16: {field} is not a number
A17: M_09 | C17: {field}は整数でなければなりません | D17: {field} must be an integer
A18: M_10 | C18: {field}は既に登録されています | D18: {field} has already been taken
A19: M_11 | C19: {field}が、許可されている最大文字数を超えています。（最大の文字数は{count}文字です） | D19: {field} is too long (maximum is {count} characters)
A20: M_12 | C20: {field}が、最小値より小さな値が指定されました。（最小の文字数は{count}文字です） | D20: {field} is too short (minimum is {count} characters)
A21: M_13 | C21: {field}の形式が正しくありません | D21: {field} format is incorrect
... A35: M_27 | C35: 予期しないエラーが発生しました。時間をおいてアクセスしてください。しばらく経っても改善されない場合、システム管理者に連絡してください。 | D35: An unexpected error has occurred. Please access after a while. If it does not improve after a while, please contact your system administrator.

Sheet API_List
C1: Screen Specification | G1: No: BM-QT-1701-29
G2: Version: 2.2
G3: Issue Date: 22/09/2026
A4: SUN ASTERISK VIETNAM CO., LTD | G4: ISO/IEC 27001:2013&ISO 9001:2015
A6: API List
A8: API ID | B8: Category | C8: API Name | D8: Method | E8: Endpoint | F8: API URL（参照用） | G8: Description | H8: Note
A9: USR-1 | B9: 認証 | C9: ユーザー情報取得API | D9: GET | E9: /user | F9: =D9&" "&E9 -> GET /user | G9: ユーザーアカウント情報を取得する
A10: SER-1 | B10: 検索 | C10: おすすめ一覧取得API | D10: GET | E10: /recommend | F10: =D10&" "&E10 -> GET /recommend | G10: 検索画面で表示するおすすめ一覧を取得する
F11: =D11&" "&E11
F12: =D12&" "&E12
F13: =D13&" "&E13
F14: =D14&" "&E14
F15: =D15&" "&E15
F16: =D16&" "&E16
F17: =D17&" "&E17
F18: =D18&" "&E18
F19: =D19&" "&E19
F20: =D20&" "&E20
F21: =D21&" "&E21
F22: =D22&" "&E22
... F500: =D500&" "&E500

Sheet Common_Spec
C1: Screen Specification | E1: No: BM-QT-1701-29
E2: Version: 2.2
E3: Issue Date: 22/09/2026
A4: SUN ASTERISK VIETNAM CO., LTD | E4: ISO/IEC 27001:2013&ISO 9001:2015
A6: Common Spec
A8: Spec ID | B8: Category | C8: Event | F8: Note
C9: Given (Pre-condirion) | D9: When (Trigger/Action) | E9: Then (Result)
A10: 1
A11: 2
A12: 3
A13: 4
A14: 5
A15: 6
A16: 7
A17: 8
A18: 9
A19: 10
A20: 11
A21: 12
... A39: 30

Sheet (Template) ID ScreenCategory_Sc
G1: Screen Specification | BN1: No: BM-2-901-51
BN2: Version: 2.1
BN3: Issue Date: 21/02/2025
A4: SUN ASTERISK VIETNAM CO., LTD | BN4: ISO/IEC 27001:2013&ISO 9001:2015
A6: Screen ID | M6: Screen Name | S6: =IFERROR(VLOOKUP(G6,Screen_List!A9:D501,3,FALSE),"") | AY6: Created by | BN6: Updated by
A7: Feature ID / Name | AY7: Created date | BN7: Updated date
A8: Design URL
A9: 更新/変更箇所は赤文字にしてわかりやすくしてください！（Mark any updates/changes in red for clarity.）
A10: Layout
G14: ※画面はFigma, Draw.io, Adobe XDなどで作成して貼り付けてください。
G15: Paste image files of a screen design that created with Figma, Draw.io or Adobe XD.
G17: ※ExcelやSpreadsheetでの画面デザイン作成は表示崩れやメンテナンス性の観点から非推奨です。
G18: Screen design created with Excel or Spreadsheet is not recommended
G19: because it causes display collapse and takes much effort for maintenance.
G21: ※画面上で表示するモーダル・ポップアップ・ダイアログは、表示対象の画面デザインと併せて1シートに記載してください。
G22: Describe the modal/ pop-up/ dialog displayed on the screen along with the screen design on the same sheet.
G24: ※貼り付けた画像を説明する際は、以下サンプルを活用ください（任意）。
G25: When explaining the pasted image, please use the sample below (optional).
A44: Description
A48: View
A49: ID | C49: Item | O49: Validation | AJ49: Data Mapping | BL49: Note
C50: Name | K50: Type | O50: Required | R50: Type | V50: Min | X50: Max | Z50: Default | AD50: Note | AJ50: Data Source | AN50: API ID | AS50: API URL | AZ50: Key / Param | BF50: Note
A51: A | C51: Section Name
A52: 1 | AS52: =IFERROR(VLOOKUP(AN52,API_List!$A$9:$H$500,6,FALSE),"")
A53: 2 | AS53: =IFERROR(VLOOKUP(AN53,API_List!$A$9:$H$500,6,FALSE),"")
A54: 3 | AS54: =IFERROR(VLOOKUP(AN54,API_List!$A$9:$H$500,6,FALSE),"")
A55: 4 | AS55: =IFERROR(VLOOKUP(AN55,API_List!$A$9:$H$500,6,FALSE),"")
A56: 5 | AS56: =IFERROR(VLOOKUP(AN56,API_List!$A$9:$H$500,6,FALSE),"")
A57: B | C57: Section Name
A58: 1 | AS58: =IFERROR(VLOOKUP(AN58,API_List!$A$9:$H$500,6,FALSE),"")
A59: 2 | AS59: =IFERROR(VLOOKUP(AN59,API_List!$A$9:$H$500,6,FALSE),"")
A60: 3 | AS60: =IFERROR(VLOOKUP(AN60,API_List!$A$9:$H$500,6,FALSE),"")
A61: 4 | AS61: =IFERROR(VLOOKUP(AN61,API_List!$A$9:$H$500,6,FALSE),"")
A62: 5 | AS62: =IFERROR(VLOOKUP(AN62,API_List!$A$9:$H$500,6,FALSE),"")
A63: C | C63: Section Name
A64: 1
A65: 2
A66: 3
A67: 4 | AS67: =IFERROR(VLOOKUP(AN67,API_List!$A$9:$H$500,6,FALSE),"")
A68: 5 | AS68: =IFERROR(VLOOKUP(AN68,API_List!$A$9:$H$500,6,FALSE),"")
...

Sheet (TemplateSimple) ID ScreenCateg
G1: Screen Specification | AW1: No: BM-2-901-51
AW2: Version: 2.1
AW3: Issue Date: 21/02/2025
A4: SUN ASTERISK VIETNAM CO., LTD | AW4: ISO/IEC 27001:2013&ISO 9001:2015
A6: Screen ID | N6: Screen Name | T6: =IFERROR(VLOOKUP(G6,Screen_List!A9:D501,3,FALSE),"") | AE6: Created by | AR6: Updated by
A7: Feature ID / Name | AE7: Created date | AR7: Updated date
A8: Design URL
A9: 更新/変更箇所は赤文字にしてわかりやすくしてください！（Mark any updates/changes in red for clarity.）
A10: Layout
G14: ※画面はFigma, Draw.io, Adobe XDなどで作成して貼り付けてください。
G15: Paste image files of a screen design that created with Figma, Draw.io or Adobe XD.
G17: ※ExcelやSpreadsheetでの画面デザイン作成は表示崩れやメンテナンス性の観点から非推奨です。
G18: Screen design created with Excel or Spreadsheet is not recommended
G19: because it causes display collapse and takes much effort for maintenance.
G21: ※画面上で表示するモーダル・ポップアップ・ダイアログは、表示対象の画面デザインと併せて1シートに記載してください。
G22: Describe the modal/ pop-up/ dialog displayed on the screen along with the screen design on the same sheet.
G24: ※貼り付けた画像を説明する際は、以下サンプルを活用ください（任意）。
G25: When explaining the pasted image, please use the sample below (optional).
A44: Description
A48: View
A49: ID | C49: Item | P49: Validation | AN49: Note
C50: Name | L50: Type | P50: Required | S50: Type | W50: Min | Y50: Max | AA50: Default | AF50: Note
A51: A | C51: Section Name
A52: 1
A53: 2
A54: 3
A55: 4
A56: 5
A57: B | C57: Section Name
A58: 1
A59: 2
A60: 3
A61: 4
A62: 5
A63: C | C63: Section Name
A64: 1
A65: 2
A66: 3
A67: 4
A68: 5
...

Sheet (Sample) A001 Search_SearchTop
G1: Screen Specification | BN1: No: BM-2-901-51
BN2: Version: 2.1
BN3: Issue Date: 21/02/2025
A4: SUN ASTERISK VIETNAM CO., LTD | BN4: ISO/IEC 27001:2013&ISO 9001:2015
A6: Screen ID | G6: A001 | M6: Screen Name | S6: =IFERROR(VLOOKUP(G6,Screen_List!A9:D501,3,FALSE),"") -> 検索TOP画面 | AX6: Created by | BC6: Yuta Ikeno | BM6: Updated by | BR6: Yuta Ikeno
A7: Feature ID / Name | G7: SER001 | AX7: Created date | BC7: 45658 | BM7: Updated date | BR7: 45658
A8: Design URL | G8: http://adfadfadfafasfasfasasdfas
A9: 更新/変更箇所は赤文字にしてわかりやすくしてください！（Mark any updates/changes in red for clarity.）
A10: Layout
A44: Description | F44: 検索TOP画面。AppleStoreでインストール可能なアプリを検索することができる。また「おすすめ」「閲覧」（カテゴライズ）ごとにアプリを確認することも可能。
A48: View
A49: ID | C49: Item | O49: Validation | AI49: Data Mapping | BK49: Note
C50: Name | K50: Type | O50: Required | R50: Type | U50: Min | W50: Max | Y50: Default | AC50: Note | AI50: Data Source | AM50: API ID | AR50: API URL | AY50: Key / Param | BE50: Note
A51: A | C51: ヘッダー
A52: 1 | C52: 検索 | K52: Label | AR52: =IFERROR(VLOOKUP(AM52,API_List!$A$9:$H$500,6,FALSE),"")
A53: 2 | C53: ユーザーアイコン | K53: Image | AI53: API | AM53: USR-1 | AR53: =IFERROR(VLOOKUP(AM53,API_List!$A$9:$H$500,6,FALSE),"") -> GET /user | AY53: user_icon
A54: 3 | C54: 検索欄 | K54: Text box | R54: String | U54: 0 | W54: 255 | AR54: =IFERROR(VLOOKUP(AM54,API_List!$A$9:$H$500,6,FALSE),"") | BK54: ・placeholder「ゲーム、アプリ、ストーリーなど」
A55: B | C55: おすすめ
A56: 1 | C56: おすすめ | K56: Button | AR56: =IFERROR(VLOOKUP(AM56,API_List!$A$9:$H$500,6,FALSE),"")
A57: 2 | C57: アプリアイコン | K57: Image | AI57: API | AM57: SER-1 | AR57: =IFERROR(VLOOKUP(AM57,API_List!$A$9:$H$500,6,FALSE),"") -> GET /recommend | AY57: app_icon | BE57: API は 1 コールのみでローカルキャッシュより取得
A58: 3 | C58: アプリ名 | K58: Label | AI58: API | AM58: SER-1 | AR58: =IFERROR(VLOOKUP(AM58,API_List!$A$9:$H$500,6,FALSE),"") -> GET /recommend | AY58: app_name | BK58: ・最大2行まで表示可。1行の場合は上下中央寄せで表示。 ・表示しきれない場合は、「･･･」で省略表示
A59: 4 | C59: サブタイトル | K59: Label | AI59: API | AM59: SER-1 | AR59: =IFERROR(VLOOKUP(AM59,API_List!$A$9:$H$500,6,FALSE),"") -> GET /recommend | AY59: sub_title | BK59: ・最大1行まで表示可。 ・表示しきれない場合は、「･･･」で省略表示
A60: 5 | C60: 広告表示 | K60: Image | AI60: API | AM60: SER-1 | AR60: =IFERROR(VLOOKUP(AM60,API_List!$A$9:$H$500,6,FALSE),"") -> GET /recommend | AY60: ad_flag | BK60: ・ad_flagがTRUEの場合、「広告」アイコンを表示 ・ad_flagがFALSEの場合、「広告」アイコンは表示しない
A61: 6 | C61: 入手 | K61: Button | AI61: API | AM61: SER-1 | AR61: =IFERROR(VLOOKUP(AM61,API_List!$A$9:$H$500,6,FALSE),"") -> GET /recommend | AY61: downloaded_flag | BK61: ・downloaded_flagがTRUEの場合、「開く」ボタンを表示 ・downloaded_flagがFALSEの場合、「入手」ボタンを表示
A62: C | C62: 閲覧
A63: 1 | C63: 閲覧 | K63: Button | AR63: =IFERROR(VLOOKUP(AM63,API_List!$A$9:$H$500,6,FALSE),"")
A64: 2 | C64: カテゴリタイトル | K64: Label | AR64: =IFERROR(VLOOKUP(AM64,API_List!$A$9:$H$500,6,FALSE),"") | BK64: ・最大2行まで表示可。1行の場合は上下中央寄せで表示。 ・表示しきれない場合は、「･･･」で省略表示
A65: 3 | C65: カテゴリ画像 | K65: Image | AR65: =IFERROR(VLOOKUP(AM65,API_List!$A$9:$H$500,6,FALSE),"")
A66: 4 | C66: カテゴリ背景 | K66: Button | AR66: =IFERROR(VLOOKUP(AM66,API_List!$A$9:$H$500,6,FALSE),"") | BK66: ・カードの背景色はパラメータのカラーコード（16進数）指定する
A67: D | C67: フッター
A68: 1 | C68: Today | K68: Button | AR68: =IFERROR(VLOOKUP(AM68,API_List!$A$9:$H$500,6,FALSE),"")
A69: 2 | C69: ゲーム | K69: Button | AR69: =IFERROR(VLOOKUP(AM69,API_List!$A$9:$H$500,6,FALSE),"")
A70: 3 | C70: アプリ | K70: Button | AR70: =IFERROR(VLOOKUP(AM70,API_List!$A$9:$H$500,6,FALSE),"")
A71: 4 | C71: Arcade | K71: Button | AR71: =IFERROR(VLOOKUP(AM71,API_List!$A$9:$H$500,6,FALSE),"")
A72: 5 | C72: 検索 | K72: Button | AR72: =IFERROR(VLOOKUP(AM72,API_List!$A$9:$H$500,6,FALSE),"")
A73: E | C73: 検索中
A74: 1 | C74: 入力欄（検索中） | K74: Text box | AR74: =IFERROR(VLOOKUP(AM74,API_List!$A$9:$H$500,6,FALSE),"")
A75: 2 | C75: キャンセル | K75: Button | AR75: =IFERROR(VLOOKUP(AM75,API_List!$A$9:$H$500,6,FALSE),"")
A77: Event
A78: ID | C78: Given (Pre-condirion) | O78: When (Trigger/Action) | AC78: Then (Result) | BE78: Note
...

Sheet Appendix
B1: Screen Specification | E1: No: BM-QT-1701-29
E2: Version: 2.2
E3: Issue Date: 22/09/2026
A4: SUN ASTERISK VIETNAM CO., LTD | E4: ISO/IEC 27001:2013&ISO 9001:2015
A9: Atomic Design Elements | C9: Points
A10: Atoms | C10: Screen Layout | E10: Specs
A11: Molecules | C11: SL_1 | D11: 画面はFigma, Draw.io, Adobe XDなどで作成して貼り付けてください。 Paste image files of a screen design that created with Figma, Draw.io or Adobe XD. | E11: S_1 | F11: Atominc Designに沿った設計書になっています。わからない人はこちらを参照してください。 This design document was created based on Atominc Design. Refer here if you don't understand.
A12: Organisms | C12: SL_2 | D12: ExcelやSpreadsheetでの画面デザイン作成は表示崩れやメンテナンス性の観点から非推奨です。 Screen design created with Excel or Spreadsheet is not recommended because it causes display collapse and takes much effort for maintenance. | E12: S_2 | F12: https://atomicdesign.bradfrost.com/chapter-2/
A13: Templates | C13: SL_3 | D13: 画面上で表示するモーダル・ポップアップ・ダイアログは、表示対象の画面デザインと併せて1シートに記載してください。 Describe the modal/ pop-up/ dialog displayed on the screen along with the screen design on the same sheet. | E13: S_3 | F13: 更新/変更箇所は赤文字にしてわかりやすくしてください！ Mark any updates/changes in red for clarity.
A14: Pages
A20: Data Source Elements
A21: API
A22: Cookie
A23: Shared Prefs
A24: Local DB
