Workbook
Name FEReceiverManagement: #REF!
Name BEBasicLayout: #REF!
Name BEAdvanceFeatures: #REF!
Name Holiday: General!$U$13:$U$26
Name BEBasicLayout: #REF!
Name BEAdvanceFeatures: #REF!
Name FEAdvanceFeatures: #REF!
Name BEReceiMng: #REF!

Sheet 開発スケジュール
B1: Project NewYearCardB2C
B2: Team : ATS | E2: Start | F2: End | H2: Bug fixing | I2: 0.1
B3: Last update | C3: 43403 | E3: =MIN(E13:E35) -> 43801 | F3: =MAX(F13:F35) -> 43815 | H3: Management | I3: 0.2
B4: Updated by | C4: DinhPQ | H4: RSpec | I4: 0.3 | P4: =IF(P12=TODAY(),"TODAY","") | Q4: =IF(Q12=TODAY(),"TODAY","") | R4: =IF(R12=TODAY(),"TODAY","") | S4: =IF(S12=TODAY(),"TODAY","") | T4: =IF(T12=TODAY(),"TODAY","") | U4: =IF(U12=TODAY(),"TODAY","") | V4: =IF(V12=TODAY(),"TODAY","") | W4: =IF(W12=TODAY(),"TODAY","") | ... FX4: =IF(FX12=TODAY(),"TODAY","")
B5: Total point | C5: =SUM(#REF!) -> #REF!
B8: FireFox 20% | C8: 1.2 | E8: Start | F8: End | I8: SUM QA | Q8: =SUMIF($D13:$D300, "QA" ,Q13:Q300) -> 0 | R8: =SUMIF($D13:$D300, "QA" ,R13:R300) -> 1 | S8: =SUMIF($D13:$D300, "QA" ,S13:S300) -> 1 | T8: =SUMIF($D13:$D300, "QA" ,T13:T300) -> 1 | U8: =SUMIF($D13:$D300, "QA" ,U13:U300) -> 1 | V8: =SUMIF($D13:$D300, "QA" ,V13:V300) -> 0 | W8: =SUMIF($D13:$D300, "QA" ,W13:W300) -> 0 | X8: =SUMIF($D13:$D300, "QA" ,X13:X300) -> 1 | ... FX8: =SUMIF($D13:$D300, "QA" ,FX13:FX300) -> 0
B9: Design Fb 30% | C9: 1.3 | E9: =MIN(E13:E100) -> 43801 | F9: =MAX(F13:F100) -> 43830 | I9: SUM PG | Q9: =SUMIF($D13:$D300, "PG" ,Q13:Q300) -> 1 | R9: =SUMIF($D13:$D300, "PG" ,R13:R300) -> 1 | S9: =SUMIF($D13:$D300, "PG" ,S13:S300) -> 1 | T9: =SUMIF($D13:$D300, "PG" ,T13:T300) -> 1 | U9: =SUMIF($D13:$D300, "PG" ,U13:U300) -> 1 | V9: =SUMIF($D13:$D300, "PG" ,V13:V300) -> 0 | W9: =SUMIF($D13:$D300, "PG" ,W13:W300) -> 0 | X9: =SUMIF($D13:$D300, "PG" ,X13:X300) -> 1 | ... FX9: =SUMIF($D13:$D300, "PG" ,FX13:FX300) -> 0
I10: SUM Front | Q10: =SUMIF($D13:$D300, "Front" ,Q13:Q300) -> 0 | R10: =SUMIF($D13:$D300, "Front" ,R13:R300) -> 0 | S10: =SUMIF($D13:$D300, "Front" ,S13:S300) -> 0 | T10: =SUMIF($D13:$D300, "Front" ,T13:T300) -> 0 | U10: =SUMIF($D13:$D300, "Front" ,U13:U300) -> 0 | V10: =SUMIF($D13:$D300, "Front" ,V13:V300) -> 0 | W10: =SUMIF($D13:$D300, "Front" ,W13:W300) -> 0 | X10: =SUMIF($D13:$D300, "Front" ,X13:X300) -> 0 | ... FX10: =SUMIF($D13:$D300, "Front" ,FX13:FX300) -> 0
G11: must fill | I11: must fill | P11: M | Q11: =IF(Month(Q12)=Month(R12),"",Month(Q12)) | R11: =IF(Month(R12)=Month(Q12),"",Month(R12)) | S11: =IF(Month(S12)=Month(R12),"",Month(S12)) | T11: =IF(Month(T12)=Month(S12),"",Month(T12)) | U11: =IF(Month(U12)=Month(T12),"",Month(U12)) | V11: =IF(Month(V12)=Month(U12),"",Month(V12)) | W11: =IF(Month(W12)=Month(V12),"",Month(W12)) | X11: =IF(Month(X12)=Month(W12),"",Month(X12)) | Y11: =IF(Month(Y12)=Month(X12),"",Month(Y12)) | ... FX11: =IF(Month(FX12)=Month(FW12),"",Month(FX12))
A12: _x0008_Redmine | B12: Story/Screen | C12: Feature | D12: Role | E12: =E2 -> Start | F12: =F2 -> End | G12: Estimate | H12: PIC | I12: Assign | J12: Status | K12: Actual Start | L12: Actual End | M12: Progress | N12: Current point (%) | O12: Check deadline | P12: D | Q12: =E3 -> 43801 | R12: =Q12+1 -> 43802 | S12: =R12+1 -> 43803 | T12: =S12+1 -> 43804 | U12: =T12+1 -> 43805 | V12: =U12+1 -> 43806 | W12: =V12+1 -> 43807 | X12: =W12+1 -> 43808 | Y12: =X12+1 -> 43809 | ... FX12: =FW12+1 -> 43964
A13: 388176 | B13: プロジェクトコピー | D13: PG | E13: 43801 | F13: =WORKDAY(E13,ROUNDUP(G13/I13,0),General!$U$13:$U$27)-1 -> 43801 | G13: 0.5 | I13: 1 | Q13: =IF(AND(Q$12>=$E13,Q$12<=$F13,MOD(Q$12,7)>1,NOT(COUNTIF(General!$U$13:$U$19,Q$12))),$I13,"") -> 1 | R13: =IF(AND(R$12>=$E13,R$12<=$F13,MOD(R$12,7)>1,NOT(COUNTIF(General!$U$13:$U$19,R$12))),$I13,"") | S13: =IF(AND(S$12>=$E13,S$12<=$F13,MOD(S$12,7)>1,NOT(COUNTIF(General!$U$13:$U$19,S$12))),$I13,"") | T13: =IF(AND(T$12>=$E13,T$12<=$F13,MOD(T$12,7)>1,NOT(COUNTIF(General!$U$13:$U$19,T$12))),$I13,"") | U13: =IF(AND(U$12>=$E13,U$12<=$F13,MOD(U$12,7)>1,NOT(COUNTIF(General!$U$13:$U$19,U$12))),$I13,"") | V13: =IF(AND(V$12>=$E13,V$12<=$F13,MOD(V$12,7)>1,NOT(COUNTIF(General!$U$13:$U$19,V$12))),$I13,"") | W13: =IF(AND(W$12>=$E13,W$12<=$F13,MOD(W$12,7)>1,NOT(COUNTIF(General!$U$13:$U$19,W$12))),$I13,"") | X13: =IF(AND(X$12>=$E13,X$12<=$F13,MOD(X$12,7)>1,NOT(COUNTIF(General!$U$13:$U$19,X$12))),$I13,"") | ... FX13: =IF(AND(FX$12>=$E13,FX$12<=$F13,MOD(FX$12,7)>1,NOT(COUNTIF(General!$U$13:$U$19,FX$12))),$I13,"")
A14: 388797 | B14: Select及びdirectURLからのsecret_key廃止 | D14: PG | E14: 43802 | F14: =WORKDAY(E14,ROUNDUP(G14/I14,0),General!$U$13:$U$27)-1 -> 43803 | G14: 2 | I14: 1 | Q14: =IF(AND(Q$12>=$E14,Q$12<=$F14,MOD(Q$12,7)>1,NOT(COUNTIF(General!$U$13:$U$19,Q$12))),$I14,"") | R14: =IF(AND(R$12>=$E14,R$12<=$F14,MOD(R$12,7)>1,NOT(COUNTIF(General!$U$13:$U$19,R$12))),$I14,"") -> 1 | S14: =IF(AND(S$12>=$E14,S$12<=$F14,MOD(S$12,7)>1,NOT(COUNTIF(General!$U$13:$U$19,S$12))),$I14,"") -> 1 | T14: =IF(AND(T$12>=$E14,T$12<=$F14,MOD(T$12,7)>1,NOT(COUNTIF(General!$U$13:$U$19,T$12))),$I14,"") | U14: =IF(AND(U$12>=$E14,U$12<=$F14,MOD(U$12,7)>1,NOT(COUNTIF(General!$U$13:$U$19,U$12))),$I14,"") | V14: =IF(AND(V$12>=$E14,V$12<=$F14,MOD(V$12,7)>1,NOT(COUNTIF(General!$U$13:$U$19,V$12))),$I14,"") | W14: =IF(AND(W$12>=$E14,W$12<=$F14,MOD(W$12,7)>1,NOT(COUNTIF(General!$U$13:$U$19,W$12))),$I14,"") | X14: =IF(AND(X$12>=$E14,X$12<=$F14,MOD(X$12,7)>1,NOT(COUNTIF(General!$U$13:$U$19,X$12))),$I14,"") | ... FX14: =IF(AND(FX$12>=$E14,FX$12<=$F14,MOD(FX$12,7)>1,NOT(COUNTIF(General!$U$13:$U$19,FX$12))),$I14,"")
D15: QA | E15: 43803 | F15: =WORKDAY(E15,ROUNDUP(G15/I15,0),General!$U$13:$U$27)-1 -> 43803 | G15: =G14*0.4 -> 0.8 | I15: 1 | Q15: =IF(AND(Q$12>=$E15,Q$12<=$F15,MOD(Q$12,7)>1,NOT(COUNTIF(General!$U$13:$U$19,Q$12))),$I15,"") | R15: =IF(AND(R$12>=$E15,R$12<=$F15,MOD(R$12,7)>1,NOT(COUNTIF(General!$U$13:$U$19,R$12))),$I15,"") | S15: =IF(AND(S$12>=$E15,S$12<=$F15,MOD(S$12,7)>1,NOT(COUNTIF(General!$U$13:$U$19,S$12))),$I15,"") -> 1 | T15: =IF(AND(T$12>=$E15,T$12<=$F15,MOD(T$12,7)>1,NOT(COUNTIF(General!$U$13:$U$19,T$12))),$I15,"") | U15: =IF(AND(U$12>=$E15,U$12<=$F15,MOD(U$12,7)>1,NOT(COUNTIF(General!$U$13:$U$19,U$12))),$I15,"") | V15: =IF(AND(V$12>=$E15,V$12<=$F15,MOD(V$12,7)>1,NOT(COUNTIF(General!$U$13:$U$19,V$12))),$I15,"") | W15: =IF(AND(W$12>=$E15,W$12<=$F15,MOD(W$12,7)>1,NOT(COUNTIF(General!$U$13:$U$19,W$12))),$I15,"") | X15: =IF(AND(X$12>=$E15,X$12<=$F15,MOD(X$12,7)>1,NOT(COUNTIF(General!$U$13:$U$19,X$12))),$I15,"") | ... FX15: =IF(AND(FX$12>=$E15,FX$12<=$F15,MOD(FX$12,7)>1,NOT(COUNTIF(General!$U$13:$U$19,FX$12))),$I15,"")
A16: 389079 | B16: 「印刷内容確認」画面からのsecret_key廃止 | D16: PG | E16: 43804 | F16: =WORKDAY(E16,ROUNDUP(G16/I16,0),General!$U$13:$U$27)-1 -> 43808 | G16: 3 | I16: 1 | Q16: =IF(AND(Q$12>=$E16,Q$12<=$F16,MOD(Q$12,7)>1,NOT(COUNTIF(General!$U$13:$U$19,Q$12))),$I16,"") | R16: =IF(AND(R$12>=$E16,R$12<=$F16,MOD(R$12,7)>1,NOT(COUNTIF(General!$U$13:$U$19,R$12))),$I16,"") | S16: =IF(AND(S$12>=$E16,S$12<=$F16,MOD(S$12,7)>1,NOT(COUNTIF(General!$U$13:$U$19,S$12))),$I16,"") | T16: =IF(AND(T$12>=$E16,T$12<=$F16,MOD(T$12,7)>1,NOT(COUNTIF(General!$U$13:$U$19,T$12))),$I16,"") -> 1 | U16: =IF(AND(U$12>=$E16,U$12<=$F16,MOD(U$12,7)>1,NOT(COUNTIF(General!$U$13:$U$19,U$12))),$I16,"") -> 1 | V16: =IF(AND(V$12>=$E16,V$12<=$F16,MOD(V$12,7)>1,NOT(COUNTIF(General!$U$13:$U$19,V$12))),$I16,"") | W16: =IF(AND(W$12>=$E16,W$12<=$F16,MOD(W$12,7)>1,NOT(COUNTIF(General!$U$13:$U$19,W$12))),$I16,"") | X16: =IF(AND(X$12>=$E16,X$12<=$F16,MOD(X$12,7)>1,NOT(COUNTIF(General!$U$13:$U$19,X$12))),$I16,"") -> 1 | ... FX16: =IF(AND(FX$12>=$E16,FX$12<=$F16,MOD(FX$12,7)>1,NOT(COUNTIF(General!$U$13:$U$19,FX$12))),$I16,"")
D17: QA | E17: 43808 | F17: =WORKDAY(E17,ROUNDUP(G17/I17,0),General!$U$13:$U$27)-1 -> 43809 | G17: =G16*0.4 -> 1.2 | I17: 1 | Q17: =IF(AND(Q$12>=$E17,Q$12<=$F17,MOD(Q$12,7)>1,NOT(COUNTIF(General!$U$13:$U$19,Q$12))),$I17,"") | R17: =IF(AND(R$12>=$E17,R$12<=$F17,MOD(R$12,7)>1,NOT(COUNTIF(General!$U$13:$U$19,R$12))),$I17,"") | S17: =IF(AND(S$12>=$E17,S$12<=$F17,MOD(S$12,7)>1,NOT(COUNTIF(General!$U$13:$U$19,S$12))),$I17,"") | T17: =IF(AND(T$12>=$E17,T$12<=$F17,MOD(T$12,7)>1,NOT(COUNTIF(General!$U$13:$U$19,T$12))),$I17,"") | U17: =IF(AND(U$12>=$E17,U$12<=$F17,MOD(U$12,7)>1,NOT(COUNTIF(General!$U$13:$U$19,U$12))),$I17,"") | V17: =IF(AND(V$12>=$E17,V$12<=$F17,MOD(V$12,7)>1,NOT(COUNTIF(General!$U$13:$U$19,V$12))),$I17,"") | W17: =IF(AND(W$12>=$E17,W$12<=$F17,MOD(W$12,7)>1,NOT(COUNTIF(General!$U$13:$U$19,W$12))),$I17,"") | X17: =IF(AND(X$12>=$E17,X$12<=$F17,MOD(X$12,7)>1,NOT(COUNTIF(General!$U$13:$U$19,X$12))),$I17,"") -> 1 | ... FX17: =IF(AND(FX$12>=$E17,FX$12<=$F17,MOD(FX$12,7)>1,NOT(COUNTIF(General!$U$13:$U$19,FX$12))),$I17,"")
A18: 389709 | B18: 宛名面の入力画面設計 | D18: PG2 | E18: 43801 | F18: =WORKDAY(E18,ROUNDUP(G18/I18,0),General!$U$13:$U$27)-1 -> 43802 | G18: 2 | I18: 1 | Q18: =IF(AND(Q$12>=$E18,Q$12<=$F18,MOD(Q$12,7)>1,NOT(COUNTIF(General!$U$13:$U$19,Q$12))),$I18,"") -> 1 | R18: =IF(AND(R$12>=$E18,R$12<=$F18,MOD(R$12,7)>1,NOT(COUNTIF(General!$U$13:$U$19,R$12))),$I18,"") -> 1 | S18: =IF(AND(S$12>=$E18,S$12<=$F18,MOD(S$12,7)>1,NOT(COUNTIF(General!$U$13:$U$19,S$12))),$I18,"") | T18: =IF(AND(T$12>=$E18,T$12<=$F18,MOD(T$12,7)>1,NOT(COUNTIF(General!$U$13:$U$19,T$12))),$I18,"") | U18: =IF(AND(U$12>=$E18,U$12<=$F18,MOD(U$12,7)>1,NOT(COUNTIF(General!$U$13:$U$19,U$12))),$I18,"") | V18: =IF(AND(V$12>=$E18,V$12<=$F18,MOD(V$12,7)>1,NOT(COUNTIF(General!$U$13:$U$19,V$12))),$I18,"") | W18: =IF(AND(W$12>=$E18,W$12<=$F18,MOD(W$12,7)>1,NOT(COUNTIF(General!$U$13:$U$19,W$12))),$I18,"") | X18: =IF(AND(X$12>=$E18,X$12<=$F18,MOD(X$12,7)>1,NOT(COUNTIF(General!$U$13:$U$19,X$12))),$I18,"") | ... FX18: =IF(AND(FX$12>=$E18,FX$12<=$F18,MOD(FX$12,7)>1,NOT(COUNTIF(General!$U$13:$U$19,FX$12))),$I18,"")
D19: QA | E19: 43802 | F19: =WORKDAY(E19,ROUNDUP(G19/I19,0),General!$U$13:$U$27)-1 -> 43802 | G19: =G18*0.4 -> 0.8 | I19: 1 | Q19: =IF(AND(Q$12>=$E19,Q$12<=$F19,MOD(Q$12,7)>1,NOT(COUNTIF(General!$U$13:$U$19,Q$12))),$I19,"") | R19: =IF(AND(R$12>=$E19,R$12<=$F19,MOD(R$12,7)>1,NOT(COUNTIF(General!$U$13:$U$19,R$12))),$I19,"") -> 1 | S19: =IF(AND(S$12>=$E19,S$12<=$F19,MOD(S$12,7)>1,NOT(COUNTIF(General!$U$13:$U$19,S$12))),$I19,"") | T19: =IF(AND(T$12>=$E19,T$12<=$F19,MOD(T$12,7)>1,NOT(COUNTIF(General!$U$13:$U$19,T$12))),$I19,"") | U19: =IF(AND(U$12>=$E19,U$12<=$F19,MOD(U$12,7)>1,NOT(COUNTIF(General!$U$13:$U$19,U$12))),$I19,"") | V19: =IF(AND(V$12>=$E19,V$12<=$F19,MOD(V$12,7)>1,NOT(COUNTIF(General!$U$13:$U$19,V$12))),$I19,"") | W19: =IF(AND(W$12>=$E19,W$12<=$F19,MOD(W$12,7)>1,NOT(COUNTIF(General!$U$13:$U$19,W$12))),$I19,"") | X19: =IF(AND(X$12>=$E19,X$12<=$F19,MOD(X$12,7)>1,NOT(COUNTIF(General!$U$13:$U$19,X$12))),$I19,"") | ... FX19: =IF(AND(FX$12>=$E19,FX$12<=$F19,MOD(FX$12,7)>1,NOT(COUNTIF(General!$U$13:$U$19,FX$12))),$I19,"")
A20: 388893 | B20: 利用規約画面へのバナーの掲載 | D20: PG2 | E20: 43803 | F20: =WORKDAY(E20,ROUNDUP(G20/I20,0),General!$U$13:$U$27)-1 -> 43803 | G20: 1 | I20: 1 | Q20: =IF(AND(Q$12>=$E20,Q$12<=$F20,MOD(Q$12,7)>1,NOT(COUNTIF(General!$U$13:$U$19,Q$12))),$I20,"") | R20: =IF(AND(R$12>=$E20,R$12<=$F20,MOD(R$12,7)>1,NOT(COUNTIF(General!$U$13:$U$19,R$12))),$I20,"") | S20: =IF(AND(S$12>=$E20,S$12<=$F20,MOD(S$12,7)>1,NOT(COUNTIF(General!$U$13:$U$19,S$12))),$I20,"") -> 1 | T20: =IF(AND(T$12>=$E20,T$12<=$F20,MOD(T$12,7)>1,NOT(COUNTIF(General!$U$13:$U$19,T$12))),$I20,"") | U20: =IF(AND(U$12>=$E20,U$12<=$F20,MOD(U$12,7)>1,NOT(COUNTIF(General!$U$13:$U$19,U$12))),$I20,"") | V20: =IF(AND(V$12>=$E20,V$12<=$F20,MOD(V$12,7)>1,NOT(COUNTIF(General!$U$13:$U$19,V$12))),$I20,"") | W20: =IF(AND(W$12>=$E20,W$12<=$F20,MOD(W$12,7)>1,NOT(COUNTIF(General!$U$13:$U$19,W$12))),$I20,"") | X20: =IF(AND(X$12>=$E20,X$12<=$F20,MOD(X$12,7)>1,NOT(COUNTIF(General!$U$13:$U$19,X$12))),$I20,"") | ... FX20: =IF(AND(FX$12>=$E20,FX$12<=$F20,MOD(FX$12,7)>1,NOT(COUNTIF(General!$U$13:$U$19,FX$12))),$I20,"")
D21: QA | E21: 43804 | F21: =WORKDAY(E21,ROUNDUP(G21/I21,0),General!$U$13:$U$27)-1 -> 43804 | G21: =G20*0.4 -> 0.4 | I21: 1 | Q21: =IF(AND(Q$12>=$E21,Q$12<=$F21,MOD(Q$12,7)>1,NOT(COUNTIF(General!$U$13:$U$19,Q$12))),$I21,"") | R21: =IF(AND(R$12>=$E21,R$12<=$F21,MOD(R$12,7)>1,NOT(COUNTIF(General!$U$13:$U$19,R$12))),$I21,"") | S21: =IF(AND(S$12>=$E21,S$12<=$F21,MOD(S$12,7)>1,NOT(COUNTIF(General!$U$13:$U$19,S$12))),$I21,"") | T21: =IF(AND(T$12>=$E21,T$12<=$F21,MOD(T$12,7)>1,NOT(COUNTIF(General!$U$13:$U$19,T$12))),$I21,"") -> 1 | U21: =IF(AND(U$12>=$E21,U$12<=$F21,MOD(U$12,7)>1,NOT(COUNTIF(General!$U$13:$U$19,U$12))),$I21,"") | V21: =IF(AND(V$12>=$E21,V$12<=$F21,MOD(V$12,7)>1,NOT(COUNTIF(General!$U$13:$U$19,V$12))),$I21,"") | W21: =IF(AND(W$12>=$E21,W$12<=$F21,MOD(W$12,7)>1,NOT(COUNTIF(General!$U$13:$U$19,W$12))),$I21,"") | X21: =IF(AND(X$12>=$E21,X$12<=$F21,MOD(X$12,7)>1,NOT(COUNTIF(General!$U$13:$U$19,X$12))),$I21,"") | ... FX21: =IF(AND(FX$12>=$E21,FX$12<=$F21,MOD(FX$12,7)>1,NOT(COUNTIF(General!$U$13:$U$19,FX$12))),$I21,"")
A22: 389262 | B22: メールアドレスのバリデーション | D22: PG2 | E22: 43804 | F22: =WORKDAY(E22,ROUNDUP(G22/I22,0),General!$U$13:$U$27)-1 -> 43807 | G22: 1.5 | I22: 1 | Q22: =IF(AND(Q$12>=$E22,Q$12<=$F22,MOD(Q$12,7)>1,NOT(COUNTIF(General!$U$13:$U$19,Q$12))),$I22,"") | R22: =IF(AND(R$12>=$E22,R$12<=$F22,MOD(R$12,7)>1,NOT(COUNTIF(General!$U$13:$U$19,R$12))),$I22,"") | S22: =IF(AND(S$12>=$E22,S$12<=$F22,MOD(S$12,7)>1,NOT(COUNTIF(General!$U$13:$U$19,S$12))),$I22,"") | T22: =IF(AND(T$12>=$E22,T$12<=$F22,MOD(T$12,7)>1,NOT(COUNTIF(General!$U$13:$U$19,T$12))),$I22,"") -> 1 | U22: =IF(AND(U$12>=$E22,U$12<=$F22,MOD(U$12,7)>1,NOT(COUNTIF(General!$U$13:$U$19,U$12))),$I22,"") -> 1 | V22: =IF(AND(V$12>=$E22,V$12<=$F22,MOD(V$12,7)>1,NOT(COUNTIF(General!$U$13:$U$19,V$12))),$I22,"") | W22: =IF(AND(W$12>=$E22,W$12<=$F22,MOD(W$12,7)>1,NOT(COUNTIF(General!$U$13:$U$19,W$12))),$I22,"") | X22: =IF(AND(X$12>=$E22,X$12<=$F22,MOD(X$12,7)>1,NOT(COUNTIF(General!$U$13:$U$19,X$12))),$I22,"") | ... FX22: =IF(AND(FX$12>=$E22,FX$12<=$F22,MOD(FX$12,7)>1,NOT(COUNTIF(General!$U$13:$U$19,FX$12))),$I22,"")
D23: QA | E23: 43805 | F23: =WORKDAY(E23,ROUNDUP(G23/I23,0),General!$U$13:$U$27)-1 -> 43807 | G23: =G22*0.4 -> 0.6 | I23: 1 | Q23: =IF(AND(Q$12>=$E23,Q$12<=$F23,MOD(Q$12,7)>1,NOT(COUNTIF(General!$U$13:$U$19,Q$12))),$I23,"") | R23: =IF(AND(R$12>=$E23,R$12<=$F23,MOD(R$12,7)>1,NOT(COUNTIF(General!$U$13:$U$19,R$12))),$I23,"") | S23: =IF(AND(S$12>=$E23,S$12<=$F23,MOD(S$12,7)>1,NOT(COUNTIF(General!$U$13:$U$19,S$12))),$I23,"") | T23: =IF(AND(T$12>=$E23,T$12<=$F23,MOD(T$12,7)>1,NOT(COUNTIF(General!$U$13:$U$19,T$12))),$I23,"") | U23: =IF(AND(U$12>=$E23,U$12<=$F23,MOD(U$12,7)>1,NOT(COUNTIF(General!$U$13:$U$19,U$12))),$I23,"") -> 1 | V23: =IF(AND(V$12>=$E23,V$12<=$F23,MOD(V$12,7)>1,NOT(COUNTIF(General!$U$13:$U$19,V$12))),$I23,"") | W23: =IF(AND(W$12>=$E23,W$12<=$F23,MOD(W$12,7)>1,NOT(COUNTIF(General!$U$13:$U$19,W$12))),$I23,"") | X23: =IF(AND(X$12>=$E23,X$12<=$F23,MOD(X$12,7)>1,NOT(COUNTIF(General!$U$13:$U$19,X$12))),$I23,"") | ... FX23: =IF(AND(FX$12>=$E23,FX$12<=$F23,MOD(FX$12,7)>1,NOT(COUNTIF(General!$U$13:$U$19,FX$12))),$I23,"")
A24: 389733 | B24: 設定画面上のカード登録機能 | D24: PG2 | E24: 43808 | F24: =WORKDAY(E24,ROUNDUP(G24/I24,0),General!$U$13:$U$27)-1 -> 43809 | G24: 2 | I24: 1 | Q24: =IF(AND(Q$12>=$E24,Q$12<=$F24,MOD(Q$12,7)>1,NOT(COUNTIF(General!$U$13:$U$19,Q$12))),$I24,"") | R24: =IF(AND(R$12>=$E24,R$12<=$F24,MOD(R$12,7)>1,NOT(COUNTIF(General!$U$13:$U$19,R$12))),$I24,"") | S24: =IF(AND(S$12>=$E24,S$12<=$F24,MOD(S$12,7)>1,NOT(COUNTIF(General!$U$13:$U$19,S$12))),$I24,"") | T24: =IF(AND(T$12>=$E24,T$12<=$F24,MOD(T$12,7)>1,NOT(COUNTIF(General!$U$13:$U$19,T$12))),$I24,"") | U24: =IF(AND(U$12>=$E24,U$12<=$F24,MOD(U$12,7)>1,NOT(COUNTIF(General!$U$13:$U$19,U$12))),$I24,"") | V24: =IF(AND(V$12>=$E24,V$12<=$F24,MOD(V$12,7)>1,NOT(COUNTIF(General!$U$13:$U$19,V$12))),$I24,"") | W24: =IF(AND(W$12>=$E24,W$12<=$F24,MOD(W$12,7)>1,NOT(COUNTIF(General!$U$13:$U$19,W$12))),$I24,"") | X24: =IF(AND(X$12>=$E24,X$12<=$F24,MOD(X$12,7)>1,NOT(COUNTIF(General!$U$13:$U$19,X$12))),$I24,"") -> 1 | ... FX24: =IF(AND(FX$12>=$E24,FX$12<=$F24,MOD(FX$12,7)>1,NOT(COUNTIF(General!$U$13:$U$19,FX$12))),$I24,"")
D25: QA | E25: 43809 | F25: =WORKDAY(E25,ROUNDUP(G25/I25,0),General!$U$13:$U$27)-1 -> 43809 | G25: =G24*0.4 -> 0.8 | I25: 1 | Q25: =IF(AND(Q$12>=$E25,Q$12<=$F25,MOD(Q$12,7)>1,NOT(COUNTIF(General!$U$13:$U$19,Q$12))),$I25,"") | R25: =IF(AND(R$12>=$E25,R$12<=$F25,MOD(R$12,7)>1,NOT(COUNTIF(General!$U$13:$U$19,R$12))),$I25,"") | S25: =IF(AND(S$12>=$E25,S$12<=$F25,MOD(S$12,7)>1,NOT(COUNTIF(General!$U$13:$U$19,S$12))),$I25,"") | T25: =IF(AND(T$12>=$E25,T$12<=$F25,MOD(T$12,7)>1,NOT(COUNTIF(General!$U$13:$U$19,T$12))),$I25,"") | U25: =IF(AND(U$12>=$E25,U$12<=$F25,MOD(U$12,7)>1,NOT(COUNTIF(General!$U$13:$U$19,U$12))),$I25,"") | V25: =IF(AND(V$12>=$E25,V$12<=$F25,MOD(V$12,7)>1,NOT(COUNTIF(General!$U$13:$U$19,V$12))),$I25,"") | W25: =IF(AND(W$12>=$E25,W$12<=$F25,MOD(W$12,7)>1,NOT(COUNTIF(General!$U$13:$U$19,W$12))),$I25,"") | X25: =IF(AND(X$12>=$E25,X$12<=$F25,MOD(X$12,7)>1,NOT(COUNTIF(General!$U$13:$U$19,X$12))),$I25,"") | ... FX25: =IF(AND(FX$12>=$E25,FX$12<=$F25,MOD(FX$12,7)>1,NOT(COUNTIF(General!$U$13:$U$19,FX$12))),$I25,"")
A26: 389736 | B26: 設定画面上のカード変更機能 | D26: PG2 | E26: 43810 | F26: =WORKDAY(E26,ROUNDUP(G26/I26,0),General!$U$13:$U$27)-1 -> 43811 | G26: 2 | I26: 1 | Q26: =IF(AND(Q$12>=$E26,Q$12<=$F26,MOD(Q$12,7)>1,NOT(COUNTIF(General!$U$13:$U$19,Q$12))),$I26,"") | R26: =IF(AND(R$12>=$E26,R$12<=$F26,MOD(R$12,7)>1,NOT(COUNTIF(General!$U$13:$U$19,R$12))),$I26,"") | S26: =IF(AND(S$12>=$E26,S$12<=$F26,MOD(S$12,7)>1,NOT(COUNTIF(General!$U$13:$U$19,S$12))),$I26,"") | T26: =IF(AND(T$12>=$E26,T$12<=$F26,MOD(T$12,7)>1,NOT(COUNTIF(General!$U$13:$U$19,T$12))),$I26,"") | U26: =IF(AND(U$12>=$E26,U$12<=$F26,MOD(U$12,7)>1,NOT(COUNTIF(General!$U$13:$U$19,U$12))),$I26,"") | V26: =IF(AND(V$12>=$E26,V$12<=$F26,MOD(V$12,7)>1,NOT(COUNTIF(General!$U$13:$U$19,V$12))),$I26,"") | W26: =IF(AND(W$12>=$E26,W$12<=$F26,MOD(W$12,7)>1,NOT(COUNTIF(General!$U$13:$U$19,W$12))),$I26,"") | X26: =IF(AND(X$12>=$E26,X$12<=$F26,MOD(X$12,7)>1,NOT(COUNTIF(General!$U$13:$U$19,X$12))),$I26,"") | ... FX26: =IF(AND(FX$12>=$E26,FX$12<=$F26,MOD(FX$12,7)>1,NOT(COUNTIF(General!$U$13:$U$19,FX$12))),$I26,"")
D27: QA | E27: 43811 | F27: =WORKDAY(E27,ROUNDUP(G27/I27,0),General!$U$13:$U$27)-1 -> 43811 | G27: =G26*0.4 -> 0.8 | I27: 1 | Q27: =IF(AND(Q$12>=$E27,Q$12<=$F27,MOD(Q$12,7)>1,NOT(COUNTIF(General!$U$13:$U$19,Q$12))),$I27,"") | R27: =IF(AND(R$12>=$E27,R$12<=$F27,MOD(R$12,7)>1,NOT(COUNTIF(General!$U$13:$U$19,R$12))),$I27,"") | S27: =IF(AND(S$12>=$E27,S$12<=$F27,MOD(S$12,7)>1,NOT(COUNTIF(General!$U$13:$U$19,S$12))),$I27,"") | T27: =IF(AND(T$12>=$E27,T$12<=$F27,MOD(T$12,7)>1,NOT(COUNTIF(General!$U$13:$U$19,T$12))),$I27,"") | U27: =IF(AND(U$12>=$E27,U$12<=$F27,MOD(U$12,7)>1,NOT(COUNTIF(General!$U$13:$U$19,U$12))),$I27,"") | V27: =IF(AND(V$12>=$E27,V$12<=$F27,MOD(V$12,7)>1,NOT(COUNTIF(General!$U$13:$U$19,V$12))),$I27,"") | W27: =IF(AND(W$12>=$E27,W$12<=$F27,MOD(W$12,7)>1,NOT(COUNTIF(General!$U$13:$U$19,W$12))),$I27,"") | X27: =IF(AND(X$12>=$E27,X$12<=$F27,MOD(X$12,7)>1,NOT(COUNTIF(General!$U$13:$U$19,X$12))),$I27,"") | ... FX27: =IF(AND(FX$12>=$E27,FX$12<=$F27,MOD(FX$12,7)>1,NOT(COUNTIF(General!$U$13:$U$19,FX$12))),$I27,"")
A28: 389739 | B28: 設定画面上のカード削除機能 | D28: PG2 | E28: 43812 | F28: =WORKDAY(E28,ROUNDUP(G28/I28,0),General!$U$13:$U$27)-1 -> 43814 | G28: 0.5 | I28: 1 | Q28: =IF(AND(Q$12>=$E28,Q$12<=$F28,MOD(Q$12,7)>1,NOT(COUNTIF(General!$U$13:$U$19,Q$12))),$I28,"") | R28: =IF(AND(R$12>=$E28,R$12<=$F28,MOD(R$12,7)>1,NOT(COUNTIF(General!$U$13:$U$19,R$12))),$I28,"") | S28: =IF(AND(S$12>=$E28,S$12<=$F28,MOD(S$12,7)>1,NOT(COUNTIF(General!$U$13:$U$19,S$12))),$I28,"") | T28: =IF(AND(T$12>=$E28,T$12<=$F28,MOD(T$12,7)>1,NOT(COUNTIF(General!$U$13:$U$19,T$12))),$I28,"") | U28: =IF(AND(U$12>=$E28,U$12<=$F28,MOD(U$12,7)>1,NOT(COUNTIF(General!$U$13:$U$19,U$12))),$I28,"") | V28: =IF(AND(V$12>=$E28,V$12<=$F28,MOD(V$12,7)>1,NOT(COUNTIF(General!$U$13:$U$19,V$12))),$I28,"") | W28: =IF(AND(W$12>=$E28,W$12<=$F28,MOD(W$12,7)>1,NOT(COUNTIF(General!$U$13:$U$19,W$12))),$I28,"") | X28: =IF(AND(X$12>=$E28,X$12<=$F28,MOD(X$12,7)>1,NOT(COUNTIF(General!$U$13:$U$19,X$12))),$I28,"") | ... FX28: =IF(AND(FX$12>=$E28,FX$12<=$F28,MOD(FX$12,7)>1,NOT(COUNTIF(General!$U$13:$U$19,FX$12))),$I28,"")
D29: QA | E29: 43815 | F29: =WORKDAY(E29,ROUNDUP(G29/I29,0),General!$U$13:$U$27)-1 -> 43815 | G29: =G28*0.4 -> 0.2 | I29: 1 | Q29: =IF(AND(Q$12>=$E29,Q$12<=$F29,MOD(Q$12,7)>1,NOT(COUNTIF(General!$U$13:$U$19,Q$12))),$I29,"") | R29: =IF(AND(R$12>=$E29,R$12<=$F29,MOD(R$12,7)>1,NOT(COUNTIF(General!$U$13:$U$19,R$12))),$I29,"") | S29: =IF(AND(S$12>=$E29,S$12<=$F29,MOD(S$12,7)>1,NOT(COUNTIF(General!$U$13:$U$19,S$12))),$I29,"") | T29: =IF(AND(T$12>=$E29,T$12<=$F29,MOD(T$12,7)>1,NOT(COUNTIF(General!$U$13:$U$19,T$12))),$I29,"") | U29: =IF(AND(U$12>=$E29,U$12<=$F29,MOD(U$12,7)>1,NOT(COUNTIF(General!$U$13:$U$19,U$12))),$I29,"") | V29: =IF(AND(V$12>=$E29,V$12<=$F29,MOD(V$12,7)>1,NOT(COUNTIF(General!$U$13:$U$19,V$12))),$I29,"") | W29: =IF(AND(W$12>=$E29,W$12<=$F29,MOD(W$12,7)>1,NOT(COUNTIF(General!$U$13:$U$19,W$12))),$I29,"") | X29: =IF(AND(X$12>=$E29,X$12<=$F29,MOD(X$12,7)>1,NOT(COUNTIF(General!$U$13:$U$19,X$12))),$I29,"") | ... FX29: =IF(AND(FX$12>=$E29,FX$12<=$F29,MOD(FX$12,7)>1,NOT(COUNTIF(General!$U$13:$U$19,FX$12))),$I29,"")
A30: 389712 | B30: 「recovery」画面画面からのsecret_key廃止 | D30: PG | E30: 43809 | F30: =WORKDAY(E30,ROUNDUP(G30/I30,0),General!$U$13:$U$27)-1 -> 43809 | G30: 1 | I30: 1 | Q30: =IF(AND(Q$12>=$E30,Q$12<=$F30,MOD(Q$12,7)>1,NOT(COUNTIF(General!$U$13:$U$19,Q$12))),$I30,"") | R30: =IF(AND(R$12>=$E30,R$12<=$F30,MOD(R$12,7)>1,NOT(COUNTIF(General!$U$13:$U$19,R$12))),$I30,"") | S30: =IF(AND(S$12>=$E30,S$12<=$F30,MOD(S$12,7)>1,NOT(COUNTIF(General!$U$13:$U$19,S$12))),$I30,"") | T30: =IF(AND(T$12>=$E30,T$12<=$F30,MOD(T$12,7)>1,NOT(COUNTIF(General!$U$13:$U$19,T$12))),$I30,"") | U30: =IF(AND(U$12>=$E30,U$12<=$F30,MOD(U$12,7)>1,NOT(COUNTIF(General!$U$13:$U$19,U$12))),$I30,"") | V30: =IF(AND(V$12>=$E30,V$12<=$F30,MOD(V$12,7)>1,NOT(COUNTIF(General!$U$13:$U$19,V$12))),$I30,"") | W30: =IF(AND(W$12>=$E30,W$12<=$F30,MOD(W$12,7)>1,NOT(COUNTIF(General!$U$13:$U$19,W$12))),$I30,"") | X30: =IF(AND(X$12>=$E30,X$12<=$F30,MOD(X$12,7)>1,NOT(COUNTIF(General!$U$13:$U$19,X$12))),$I30,"") | ... FX30: =IF(AND(FX$12>=$E30,FX$12<=$F30,MOD(FX$12,7)>1,NOT(COUNTIF(General!$U$13:$U$19,FX$12))),$I30,"")
D31: QA | E31: 43810 | F31: =WORKDAY(E31,ROUNDUP(G31/I31,0),General!$U$13:$U$27)-1 -> 43810 | G31: =G30*0.4 -> 0.4 | I31: 1 | Q31: =IF(AND(Q$12>=$E31,Q$12<=$F31,MOD(Q$12,7)>1,NOT(COUNTIF(General!$U$13:$U$19,Q$12))),$I31,"") | R31: =IF(AND(R$12>=$E31,R$12<=$F31,MOD(R$12,7)>1,NOT(COUNTIF(General!$U$13:$U$19,R$12))),$I31,"") | S31: =IF(AND(S$12>=$E31,S$12<=$F31,MOD(S$12,7)>1,NOT(COUNTIF(General!$U$13:$U$19,S$12))),$I31,"") | T31: =IF(AND(T$12>=$E31,T$12<=$F31,MOD(T$12,7)>1,NOT(COUNTIF(General!$U$13:$U$19,T$12))),$I31,"") | U31: =IF(AND(U$12>=$E31,U$12<=$F31,MOD(U$12,7)>1,NOT(COUNTIF(General!$U$13:$U$19,U$12))),$I31,"") | V31: =IF(AND(V$12>=$E31,V$12<=$F31,MOD(V$12,7)>1,NOT(COUNTIF(General!$U$13:$U$19,V$12))),$I31,"") | W31: =IF(AND(W$12>=$E31,W$12<=$F31,MOD(W$12,7)>1,NOT(COUNTIF(General!$U$13:$U$19,W$12))),$I31,"") | X31: =IF(AND(X$12>=$E31,X$12<=$F31,MOD(X$12,7)>1,NOT(COUNTIF(General!$U$13:$U$19,X$12))),$I31,"") | ... FX31: =IF(AND(FX$12>=$E31,FX$12<=$F31,MOD(FX$12,7)>1,NOT(COUNTIF(General!$U$13:$U$19,FX$12))),$I31,"")
A32: 389715 | B32: ファイル圧縮化処理からのsecret_key廃止 | D32: PG | E32: 43810 | F32: =WORKDAY(E32,ROUNDUP(G32/I32,0),General!$U$13:$U$27)-1 -> 43811 | G32: 1.5 | I32: 1 | Q32: =IF(AND(Q$12>=$E32,Q$12<=$F32,MOD(Q$12,7)>1,NOT(COUNTIF(General!$U$13:$U$19,Q$12))),$I32,"") | R32: =IF(AND(R$12>=$E32,R$12<=$F32,MOD(R$12,7)>1,NOT(COUNTIF(General!$U$13:$U$19,R$12))),$I32,"") | S32: =IF(AND(S$12>=$E32,S$12<=$F32,MOD(S$12,7)>1,NOT(COUNTIF(General!$U$13:$U$19,S$12))),$I32,"") | T32: =IF(AND(T$12>=$E32,T$12<=$F32,MOD(T$12,7)>1,NOT(COUNTIF(General!$U$13:$U$19,T$12))),$I32,"") | U32: =IF(AND(U$12>=$E32,U$12<=$F32,MOD(U$12,7)>1,NOT(COUNTIF(General!$U$13:$U$19,U$12))),$I32,"") | V32: =IF(AND(V$12>=$E32,V$12<=$F32,MOD(V$12,7)>1,NOT(COUNTIF(General!$U$13:$U$19,V$12))),$I32,"") | W32: =IF(AND(W$12>=$E32,W$12<=$F32,MOD(W$12,7)>1,NOT(COUNTIF(General!$U$13:$U$19,W$12))),$I32,"") | X32: =IF(AND(X$12>=$E32,X$12<=$F32,MOD(X$12,7)>1,NOT(COUNTIF(General!$U$13:$U$19,X$12))),$I32,"") | ... FX32: =IF(AND(FX$12>=$E32,FX$12<=$F32,MOD(FX$12,7)>1,NOT(COUNTIF(General!$U$13:$U$19,FX$12))),$I32,"")
D33: QA | E33: 43812 | F33: =WORKDAY(E33,ROUNDUP(G33/I33,0),General!$U$13:$U$27)-1 -> 43814 | G33: =G32*0.4 -> 0.6 | I33: 1 | Q33: =IF(AND(Q$12>=$E33,Q$12<=$F33,MOD(Q$12,7)>1,NOT(COUNTIF(General!$U$13:$U$19,Q$12))),$I33,"") | R33: =IF(AND(R$12>=$E33,R$12<=$F33,MOD(R$12,7)>1,NOT(COUNTIF(General!$U$13:$U$19,R$12))),$I33,"") | S33: =IF(AND(S$12>=$E33,S$12<=$F33,MOD(S$12,7)>1,NOT(COUNTIF(General!$U$13:$U$19,S$12))),$I33,"") | T33: =IF(AND(T$12>=$E33,T$12<=$F33,MOD(T$12,7)>1,NOT(COUNTIF(General!$U$13:$U$19,T$12))),$I33,"") | U33: =IF(AND(U$12>=$E33,U$12<=$F33,MOD(U$12,7)>1,NOT(COUNTIF(General!$U$13:$U$19,U$12))),$I33,"") | V33: =IF(AND(V$12>=$E33,V$12<=$F33,MOD(V$12,7)>1,NOT(COUNTIF(General!$U$13:$U$19,V$12))),$I33,"") | W33: =IF(AND(W$12>=$E33,W$12<=$F33,MOD(W$12,7)>1,NOT(COUNTIF(General!$U$13:$U$19,W$12))),$I33,"") | X33: =IF(AND(X$12>=$E33,X$12<=$F33,MOD(X$12,7)>1,NOT(COUNTIF(General!$U$13:$U$19,X$12))),$I33,"") | ... FX33: =IF(AND(FX$12>=$E33,FX$12<=$F33,MOD(FX$12,7)>1,NOT(COUNTIF(General!$U$13:$U$19,FX$12))),$I33,"")
A34: 389718 | B34: ファイルプッシュ処理からのsecret_key廃止 | D34: PG | E34: 43812 | F34: =WORKDAY(E34,ROUNDUP(G34/I34,0),General!$U$13:$U$27)-1 -> 43814 | G34: 1 | I34: 1 | Q34: =IF(AND(Q$12>=$E34,Q$12<=$F34,MOD(Q$12,7)>1,NOT(COUNTIF(General!$U$13:$U$19,Q$12))),$I34,"") | R34: =IF(AND(R$12>=$E34,R$12<=$F34,MOD(R$12,7)>1,NOT(COUNTIF(General!$U$13:$U$19,R$12))),$I34,"") | S34: =IF(AND(S$12>=$E34,S$12<=$F34,MOD(S$12,7)>1,NOT(COUNTIF(General!$U$13:$U$19,S$12))),$I34,"") | T34: =IF(AND(T$12>=$E34,T$12<=$F34,MOD(T$12,7)>1,NOT(COUNTIF(General!$U$13:$U$19,T$12))),$I34,"") | U34: =IF(AND(U$12>=$E34,U$12<=$F34,MOD(U$12,7)>1,NOT(COUNTIF(General!$U$13:$U$19,U$12))),$I34,"") | V34: =IF(AND(V$12>=$E34,V$12<=$F34,MOD(V$12,7)>1,NOT(COUNTIF(General!$U$13:$U$19,V$12))),$I34,"") | W34: =IF(AND(W$12>=$E34,W$12<=$F34,MOD(W$12,7)>1,NOT(COUNTIF(General!$U$13:$U$19,W$12))),$I34,"") | X34: =IF(AND(X$12>=$E34,X$12<=$F34,MOD(X$12,7)>1,NOT(COUNTIF(General!$U$13:$U$19,X$12))),$I34,"") | ... FX34: =IF(AND(FX$12>=$E34,FX$12<=$F34,MOD(FX$12,7)>1,NOT(COUNTIF(General!$U$13:$U$19,FX$12))),$I34,"")
D35: QA | E35: 43815 | F35: =WORKDAY(E35,ROUNDUP(G35/I35,0),General!$U$13:$U$27)-1 -> 43815 | G35: =G34*0.4 -> 0.4 | I35: 1 | Q35: =IF(AND(Q$12>=$E35,Q$12<=$F35,MOD(Q$12,7)>1,NOT(COUNTIF(General!$U$13:$U$19,Q$12))),$I35,"") | R35: =IF(AND(R$12>=$E35,R$12<=$F35,MOD(R$12,7)>1,NOT(COUNTIF(General!$U$13:$U$19,R$12))),$I35,"") | S35: =IF(AND(S$12>=$E35,S$12<=$F35,MOD(S$12,7)>1,NOT(COUNTIF(General!$U$13:$U$19,S$12))),$I35,"") | T35: =IF(AND(T$12>=$E35,T$12<=$F35,MOD(T$12,7)>1,NOT(COUNTIF(General!$U$13:$U$19,T$12))),$I35,"") | U35: =IF(AND(U$12>=$E35,U$12<=$F35,MOD(U$12,7)>1,NOT(COUNTIF(General!$U$13:$U$19,U$12))),$I35,"") | V35: =IF(AND(V$12>=$E35,V$12<=$F35,MOD(V$12,7)>1,NOT(COUNTIF(General!$U$13:$U$19,V$12))),$I35,"") | W35: =IF(AND(W$12>=$E35,W$12<=$F35,MOD(W$12,7)>1,NOT(COUNTIF(General!$U$13:$U$19,W$12))),$I35,"") | X35: =IF(AND(X$12>=$E35,X$12<=$F35,MOD(X$12,7)>1,NOT(COUNTIF(General!$U$13:$U$19,X$12))),$I35,"") | ... FX35: =IF(AND(FX$12>=$E35,FX$12<=$F35,MOD(FX$12,7)>1,NOT(COUNTIF(General!$U$13:$U$19,FX$12))),$I35,"")
A36: 389721 | B36: カード保存処理実装 | D36: PG | E36: 43815 | F36: =WORKDAY(E36,ROUNDUP(G36/I36,0),General!$U$13:$U$27)-1 -> 43817 | G36: 3 | I36: 1 | Q36: =IF(AND(Q$12>=$E36,Q$12<=$F36,MOD(Q$12,7)>1,NOT(COUNTIF(General!$U$13:$U$19,Q$12))),$I36,"") | R36: =IF(AND(R$12>=$E36,R$12<=$F36,MOD(R$12,7)>1,NOT(COUNTIF(General!$U$13:$U$19,R$12))),$I36,"") | S36: =IF(AND(S$12>=$E36,S$12<=$F36,MOD(S$12,7)>1,NOT(COUNTIF(General!$U$13:$U$19,S$12))),$I36,"") | T36: =IF(AND(T$12>=$E36,T$12<=$F36,MOD(T$12,7)>1,NOT(COUNTIF(General!$U$13:$U$19,T$12))),$I36,"") | U36: =IF(AND(U$12>=$E36,U$12<=$F36,MOD(U$12,7)>1,NOT(COUNTIF(General!$U$13:$U$19,U$12))),$I36,"") | V36: =IF(AND(V$12>=$E36,V$12<=$F36,MOD(V$12,7)>1,NOT(COUNTIF(General!$U$13:$U$19,V$12))),$I36,"") | W36: =IF(AND(W$12>=$E36,W$12<=$F36,MOD(W$12,7)>1,NOT(COUNTIF(General!$U$13:$U$19,W$12))),$I36,"") | X36: =IF(AND(X$12>=$E36,X$12<=$F36,MOD(X$12,7)>1,NOT(COUNTIF(General!$U$13:$U$19,X$12))),$I36,"") | ... FX36: =IF(AND(FX$12>=$E36,FX$12<=$F36,MOD(FX$12,7)>1,NOT(COUNTIF(General!$U$13:$U$19,FX$12))),$I36,"")
D37: QA | E37: 43817 | F37: =WORKDAY(E37,ROUNDUP(G37/I37,0),General!$U$13:$U$27)-1 -> 43818 | G37: =G36*0.4 -> 1.2 | I37: 1 | Q37: =IF(AND(Q$12>=$E37,Q$12<=$F37,MOD(Q$12,7)>1,NOT(COUNTIF(General!$U$13:$U$19,Q$12))),$I37,"") | R37: =IF(AND(R$12>=$E37,R$12<=$F37,MOD(R$12,7)>1,NOT(COUNTIF(General!$U$13:$U$19,R$12))),$I37,"") | S37: =IF(AND(S$12>=$E37,S$12<=$F37,MOD(S$12,7)>1,NOT(COUNTIF(General!$U$13:$U$19,S$12))),$I37,"") | T37: =IF(AND(T$12>=$E37,T$12<=$F37,MOD(T$12,7)>1,NOT(COUNTIF(General!$U$13:$U$19,T$12))),$I37,"") | U37: =IF(AND(U$12>=$E37,U$12<=$F37,MOD(U$12,7)>1,NOT(COUNTIF(General!$U$13:$U$19,U$12))),$I37,"") | V37: =IF(AND(V$12>=$E37,V$12<=$F37,MOD(V$12,7)>1,NOT(COUNTIF(General!$U$13:$U$19,V$12))),$I37,"") | W37: =IF(AND(W$12>=$E37,W$12<=$F37,MOD(W$12,7)>1,NOT(COUNTIF(General!$U$13:$U$19,W$12))),$I37,"") | X37: =IF(AND(X$12>=$E37,X$12<=$F37,MOD(X$12,7)>1,NOT(COUNTIF(General!$U$13:$U$19,X$12))),$I37,"") | ... FX37: =IF(AND(FX$12>=$E37,FX$12<=$F37,MOD(FX$12,7)>1,NOT(COUNTIF(General!$U$13:$U$19,FX$12))),$I37,"")
A38: 389727 | B38: CSVファイルへの出力 | D38: PG | E38: 43818 | F38: =WORKDAY(E38,ROUNDUP(G38/I38,0),General!$U$13:$U$27)-1 -> 43818 | G38: 1 | I38: 1 | Q38: =IF(AND(Q$12>=$E38,Q$12<=$F38,MOD(Q$12,7)>1,NOT(COUNTIF(General!$U$13:$U$19,Q$12))),$I38,"") | R38: =IF(AND(R$12>=$E38,R$12<=$F38,MOD(R$12,7)>1,NOT(COUNTIF(General!$U$13:$U$19,R$12))),$I38,"") | S38: =IF(AND(S$12>=$E38,S$12<=$F38,MOD(S$12,7)>1,NOT(COUNTIF(General!$U$13:$U$19,S$12))),$I38,"") | T38: =IF(AND(T$12>=$E38,T$12<=$F38,MOD(T$12,7)>1,NOT(COUNTIF(General!$U$13:$U$19,T$12))),$I38,"") | U38: =IF(AND(U$12>=$E38,U$12<=$F38,MOD(U$12,7)>1,NOT(COUNTIF(General!$U$13:$U$19,U$12))),$I38,"") | V38: =IF(AND(V$12>=$E38,V$12<=$F38,MOD(V$12,7)>1,NOT(COUNTIF(General!$U$13:$U$19,V$12))),$I38,"") | W38: =IF(AND(W$12>=$E38,W$12<=$F38,MOD(W$12,7)>1,NOT(COUNTIF(General!$U$13:$U$19,W$12))),$I38,"") | X38: =IF(AND(X$12>=$E38,X$12<=$F38,MOD(X$12,7)>1,NOT(COUNTIF(General!$U$13:$U$19,X$12))),$I38,"") | ... FX38: =IF(AND(FX$12>=$E38,FX$12<=$F38,MOD(FX$12,7)>1,NOT(COUNTIF(General!$U$13:$U$19,FX$12))),$I38,"")
D39: QA | E39: 43819 | F39: =WORKDAY(E39,ROUNDUP(G39/I39,0),General!$U$13:$U$27)-1 -> 43821 | G39: =G38*0.4 -> 0.4 | I39: 1 | Q39: =IF(AND(Q$12>=$E39,Q$12<=$F39,MOD(Q$12,7)>1,NOT(COUNTIF(General!$U$13:$U$19,Q$12))),$I39,"") | R39: =IF(AND(R$12>=$E39,R$12<=$F39,MOD(R$12,7)>1,NOT(COUNTIF(General!$U$13:$U$19,R$12))),$I39,"") | S39: =IF(AND(S$12>=$E39,S$12<=$F39,MOD(S$12,7)>1,NOT(COUNTIF(General!$U$13:$U$19,S$12))),$I39,"") | T39: =IF(AND(T$12>=$E39,T$12<=$F39,MOD(T$12,7)>1,NOT(COUNTIF(General!$U$13:$U$19,T$12))),$I39,"") | U39: =IF(AND(U$12>=$E39,U$12<=$F39,MOD(U$12,7)>1,NOT(COUNTIF(General!$U$13:$U$19,U$12))),$I39,"") | V39: =IF(AND(V$12>=$E39,V$12<=$F39,MOD(V$12,7)>1,NOT(COUNTIF(General!$U$13:$U$19,V$12))),$I39,"") | W39: =IF(AND(W$12>=$E39,W$12<=$F39,MOD(W$12,7)>1,NOT(COUNTIF(General!$U$13:$U$19,W$12))),$I39,"") | X39: =IF(AND(X$12>=$E39,X$12<=$F39,MOD(X$12,7)>1,NOT(COUNTIF(General!$U$13:$U$19,X$12))),$I39,"") | ... FX39: =IF(AND(FX$12>=$E39,FX$12<=$F39,MOD(FX$12,7)>1,NOT(COUNTIF(General!$U$13:$U$19,FX$12))),$I39,"")
A40: 389730 | B40: DMNO及び一意キーの採番 | D40: PG | E40: 43819 | F40: =WORKDAY(E40,ROUNDUP(G40/I40,0),General!$U$13:$U$27)-1 -> 43821 | G40: 1 | I40: 1 | Q40: =IF(AND(Q$12>=$E40,Q$12<=$F40,MOD(Q$12,7)>1,NOT(COUNTIF(General!$U$13:$U$19,Q$12))),$I40,"") | R40: =IF(AND(R$12>=$E40,R$12<=$F40,MOD(R$12,7)>1,NOT(COUNTIF(General!$U$13:$U$19,R$12))),$I40,"") | S40: =IF(AND(S$12>=$E40,S$12<=$F40,MOD(S$12,7)>1,NOT(COUNTIF(General!$U$13:$U$19,S$12))),$I40,"") | T40: =IF(AND(T$12>=$E40,T$12<=$F40,MOD(T$12,7)>1,NOT(COUNTIF(General!$U$13:$U$19,T$12))),$I40,"") | U40: =IF(AND(U$12>=$E40,U$12<=$F40,MOD(U$12,7)>1,NOT(COUNTIF(General!$U$13:$U$19,U$12))),$I40,"") | V40: =IF(AND(V$12>=$E40,V$12<=$F40,MOD(V$12,7)>1,NOT(COUNTIF(General!$U$13:$U$19,V$12))),$I40,"") | W40: =IF(AND(W$12>=$E40,W$12<=$F40,MOD(W$12,7)>1,NOT(COUNTIF(General!$U$13:$U$19,W$12))),$I40,"") | X40: =IF(AND(X$12>=$E40,X$12<=$F40,MOD(X$12,7)>1,NOT(COUNTIF(General!$U$13:$U$19,X$12))),$I40,"") | ... FX40: =IF(AND(FX$12>=$E40,FX$12<=$F40,MOD(FX$12,7)>1,NOT(COUNTIF(General!$U$13:$U$19,FX$12))),$I40,"")
D41: QA | E41: 43819 | F41: =WORKDAY(E41,ROUNDUP(G41/I41,0),General!$U$13:$U$27)-1 -> 43821 | G41: =G40*0.4 -> 0.4 | I41: 1 | Q41: =IF(AND(Q$12>=$E41,Q$12<=$F41,MOD(Q$12,7)>1,NOT(COUNTIF(General!$U$13:$U$19,Q$12))),$I41,"") | R41: =IF(AND(R$12>=$E41,R$12<=$F41,MOD(R$12,7)>1,NOT(COUNTIF(General!$U$13:$U$19,R$12))),$I41,"") | S41: =IF(AND(S$12>=$E41,S$12<=$F41,MOD(S$12,7)>1,NOT(COUNTIF(General!$U$13:$U$19,S$12))),$I41,"") | T41: =IF(AND(T$12>=$E41,T$12<=$F41,MOD(T$12,7)>1,NOT(COUNTIF(General!$U$13:$U$19,T$12))),$I41,"") | U41: =IF(AND(U$12>=$E41,U$12<=$F41,MOD(U$12,7)>1,NOT(COUNTIF(General!$U$13:$U$19,U$12))),$I41,"") | V41: =IF(AND(V$12>=$E41,V$12<=$F41,MOD(V$12,7)>1,NOT(COUNTIF(General!$U$13:$U$19,V$12))),$I41,"") | W41: =IF(AND(W$12>=$E41,W$12<=$F41,MOD(W$12,7)>1,NOT(COUNTIF(General!$U$13:$U$19,W$12))),$I41,"") | X41: =IF(AND(X$12>=$E41,X$12<=$F41,MOD(X$12,7)>1,NOT(COUNTIF(General!$U$13:$U$19,X$12))),$I41,"") | ... FX41: =IF(AND(FX$12>=$E41,FX$12<=$F41,MOD(FX$12,7)>1,NOT(COUNTIF(General!$U$13:$U$19,FX$12))),$I41,"")
A42: 389742 | B42: サーバーの構築・設定 | D42: PG2 | E42: 43815 | F42: =WORKDAY(E42,ROUNDUP(G42/I42,0),General!$U$13:$U$27)-1 -> 43816 | G42: 2 | I42: 1 | Q42: =IF(AND(Q$12>=$E42,Q$12<=$F42,MOD(Q$12,7)>1,NOT(COUNTIF(General!$U$13:$U$19,Q$12))),$I42,"") | R42: =IF(AND(R$12>=$E42,R$12<=$F42,MOD(R$12,7)>1,NOT(COUNTIF(General!$U$13:$U$19,R$12))),$I42,"") | S42: =IF(AND(S$12>=$E42,S$12<=$F42,MOD(S$12,7)>1,NOT(COUNTIF(General!$U$13:$U$19,S$12))),$I42,"") | T42: =IF(AND(T$12>=$E42,T$12<=$F42,MOD(T$12,7)>1,NOT(COUNTIF(General!$U$13:$U$19,T$12))),$I42,"") | U42: =IF(AND(U$12>=$E42,U$12<=$F42,MOD(U$12,7)>1,NOT(COUNTIF(General!$U$13:$U$19,U$12))),$I42,"") | V42: =IF(AND(V$12>=$E42,V$12<=$F42,MOD(V$12,7)>1,NOT(COUNTIF(General!$U$13:$U$19,V$12))),$I42,"") | W42: =IF(AND(W$12>=$E42,W$12<=$F42,MOD(W$12,7)>1,NOT(COUNTIF(General!$U$13:$U$19,W$12))),$I42,"") | X42: =IF(AND(X$12>=$E42,X$12<=$F42,MOD(X$12,7)>1,NOT(COUNTIF(General!$U$13:$U$19,X$12))),$I42,"") | ... FX42: =IF(AND(FX$12>=$E42,FX$12<=$F42,MOD(FX$12,7)>1,NOT(COUNTIF(General!$U$13:$U$19,FX$12))),$I42,"")
...

Sheet History of changes
E1: WBS SCHEDULE | J1: No: BM-2-901-37
J2: Version: 1.1
J3: Issue Date: 05/04/2021
A4: SUN ASTERISK VIETNAM CO., LTD | J4: ISO/IEC 27001:2013&ISO 9001:2015
A6: HISTORY OF CHANGES
A7: No | B7: Change Item | E7: Description of changes | J7: Change Date
A8: 1 | E8: Update format | J8: 44320

Sheet WBS Schedule
C1: WBS SCHEDULE | R1: No: BM-2-901-37
R2: Version: 1.1
R3: Issue Date: 05/04/2021
A4: SUN ASTERISK VIETNAM CO., LTD | R4: ISO/IEC 27001:2013&ISO 9001:2015
A6: Project Name
A7: Team: | D7: Start | E7: End
A8: Last update: | D8: =MIN(D14:D45) -> 0 | E8: =MAX(E14:E45) -> 0
A9: Updated by: | K9: =IF(K13=TODAY(),"TODAY","") | L9: =IF(L13=TODAY(),"TODAY","") | M9: =IF(M13=TODAY(),"TODAY","") | N9: =IF(N13=TODAY(),"TODAY","") | O9: =IF(O13=TODAY(),"TODAY","") | P9: =IF(P13=TODAY(),"TODAY","") | Q9: =IF(Q13=TODAY(),"TODAY","") | R9: =IF(R13=TODAY(),"TODAY","") | ... CY9: =IF(CY13=TODAY(),"TODAY","")
F12: must fill | H12: must fill | K12: =IF(Month(K13)=Month(L13),"",Month(K13)) | L12: =IF(Month(L13)=Month(K13),"",Month(L13)) | M12: =IF(Month(M13)=Month(L13),"",Month(M13)) -> 1 | N12: =IF(Month(N13)=Month(M13),"",Month(N13)) | O12: =IF(Month(O13)=Month(N13),"",Month(O13)) | P12: =IF(Month(P13)=Month(O13),"",Month(P13)) | Q12: =IF(Month(Q13)=Month(P13),"",Month(Q13)) | R12: =IF(Month(R13)=Month(Q13),"",Month(R13)) | S12: =IF(Month(S13)=Month(R13),"",Month(S13)) | ... CY12: =IF(Month(CY13)=Month(CX13),"",Month(CY13)) -> 4
A13: Story/Screen | B13: Feature | C13: Role | D13: =D7 -> Start | E13: =E7 -> End | F13: Estimate | G13: PIC | H13: Assign | I13: Status | J13: Current point (%) | K13: =D8 -> 0 | L13: =K13+1 -> 1 | M13: =L13+1 -> 2 | N13: =M13+1 -> 3 | O13: =N13+1 -> 4 | P13: =O13+1 -> 5 | Q13: =P13+1 -> 6 | R13: =Q13+1 -> 7 | S13: =R13+1 -> 8 | ... CY13: =CX13+1 -> 92
G14: DN

Sheet CR List
B1: _x0008_Project NewYear Card
B2: Team : サーバ | J2: Start | L2: =MIN(#REF!) -> #REF!
B3: Last update | J3: End | L3: =MAX(#REF!) -> #REF!
B4: Updated by | J4: Fix Bug | L4: 0.3
B5: Total Develop hour | D5: =SUM(Q16:Q42) -> 554 | F5: =D5/160 -> 3.4625 | J5: Unit Test | L5: 0.7
B6: Total test hour | D6: =SUM(P16:P42) -> 193.9 | F6: =D6/160 -> 1.211875 | J6: API Docs | L6: 0.8
B7: 注意:
J9: Intergration Test | L9: 0.7
L10: must fill | M10: (auto) | N10: (auto) | O10: (auto) | Q10: (auto)
A11: ＃ | B11: Screen/Feature | C11: Screen Num | D11: Task | E11: 機能 | F11: Sub-task | G11: 要件概要 | H11: Remark | J11: =J2 -> Start | K11: =J3 -> End | L11: Code | M11: UT | N11: Fix bug | O11: API doc | P11: IT | Q11: Total Develop | R11: SumDev
A12: 1 | B12: 2.Input Sender Information 差出人の情報入力 | C12: 2.15 | D12: Lưu dữ liệu mỗi khi có thay đổi | H12: Giữ input ngay cả khi back trên trình duyệt | L12: 60 | M12: =$L12 * 0.7 -> 42 | N12: =$L12 * 0.3 -> 18 | O12: =L12*$L$6 -> 48 | P12: =$L12 * 0.7 -> 42 | Q12: =SUM($L12:$N12) -> 120
A13: 2 | B13: 3. Edit Design デザイン編集 | C13: 3.18 | D13: Tạo file pdf order info | L13: 40 | M13: =$L13 * 0.7 -> 28 | N13: =$L13 * 0.3 -> 12 | O13: =L13*$L$6 -> 32 | P13: =$L13 * 0.7 -> 28 | Q13: =SUM($L13:$N13) -> 80
A14: 3 | B14: 4. Quản lý master data | C14: 4.1 | D14: Login | L14: 16 | M14: =$L14 * 0.7 -> 11.2 | N14: =$L14 * 0.3 -> 4.8 | O14: =L14*$L$6 -> 12.8 | P14: =$L14 * 0.7 -> 11.2 | Q14: =SUM($L14:$N14) -> 32
C15: 4.2 | D15: Logout | L15: 8 | M15: =$L15 * 0.7 -> 5.6 | N15: =$L15 * 0.3 -> 2.4 | O15: =L15*$L$6 -> 6.4 | P15: =$L15 * 0.7 -> 5.6 | Q15: =SUM($L15:$N15) -> 16
C16: 4.3 | D16: Quản lý sample text types | F16: Danh sách sample text types | L16: 8 | M16: =$L16 * 0.7 -> 5.6 | N16: =$L16 * 0.3 -> 2.4 | O16: =L16*$L$6 -> 6.4 | P16: =$L16 * 0.7 -> 5.6 | Q16: =SUM($L16:$N16) -> 16 | R16: =sum(Q16) -> 16
F17: Thêm sample text type | L17: 4 | M17: =$L17 * 0.7 -> 2.8 | N17: =$L17 * 0.3 -> 1.2 | O17: =L17*$L$6 -> 3.2 | P17: =$L17 * 0.7 -> 2.8 | Q17: =SUM($L17:$N17) -> 8
F18: Sửa sample text type | L18: 4 | M18: =$L18 * 0.7 -> 2.8 | N18: =$L18 * 0.3 -> 1.2 | O18: =L18*$L$6 -> 3.2 | P18: =$L18 * 0.7 -> 2.8 | Q18: =SUM($L18:$N18) -> 8
F19: Xoá sample text type | L19: 4 | M19: =$L19 * 0.7 -> 2.8 | N19: =$L19 * 0.3 -> 1.2 | O19: =L19*$L$6 -> 3.2 | P19: =$L19 * 0.7 -> 2.8 | Q19: =SUM($L19:$N19) -> 8
D20: Quản lý sample texts | F20: Danh sách sample texts filter theo type | L20: 8 | M20: =$L20 * 0.7 -> 5.6 | N20: =$L20 * 0.3 -> 2.4 | O20: =L20*$L$6 -> 6.4 | P20: =$L20 * 0.7 -> 5.6 | Q20: =SUM($L20:$N20) -> 16
F21: Thêm sample text | L21: 4 | M21: =$L21 * 0.7 -> 2.8 | N21: =$L21 * 0.3 -> 1.2 | O21: =L21*$L$6 -> 3.2 | P21: =$L21 * 0.7 -> 2.8 | Q21: =SUM($L21:$N21) -> 8
F22: Sửa sample text | L22: 4 | M22: =$L22 * 0.7 -> 2.8 | N22: =$L22 * 0.3 -> 1.2 | O22: =L22*$L$6 -> 3.2 | P22: =$L22 * 0.7 -> 2.8 | Q22: =SUM($L22:$N22) -> 8
F23: Xoá sample text | L23: 4 | M23: =$L23 * 0.7 -> 2.8 | N23: =$L23 * 0.3 -> 1.2 | O23: =L23*$L$6 -> 3.2 | P23: =$L23 * 0.7 -> 2.8 | Q23: =SUM($L23:$N23) -> 8
C24: 4.4 | D24: Áp dụng lấy sample texts từ database vào trang edit design | L24: 8 | M24: =$L24 * 0.7 -> 5.6 | N24: =$L24 * 0.3 -> 2.4 | O24: =L24*$L$6 -> 6.4 | P24: =$L24 * 0.7 -> 5.6 | Q24: =SUM($L24:$N24) -> 16
C25: 4.5 | D25: Quản lý layouts | F25: Danh sách layouts | L25: 8 | M25: =$L25 * 0.7 -> 5.6 | N25: =$L25 * 0.3 -> 2.4 | O25: =L25*$L$6 -> 6.4 | P25: =$L25 * 0.7 -> 5.6 | Q25: =SUM($L25:$N25) -> 16
F26: Thêm layout | L26: 16 | M26: =$L26 * 0.7 -> 11.2 | N26: =$L26 * 0.3 -> 4.8 | O26: =L26*$L$6 -> 12.8 | P26: =$L26 * 0.7 -> 11.2 | Q26: =SUM($L26:$N26) -> 32
F27: Sửa layout | L27: 8 | M27: =$L27 * 0.7 -> 5.6 | N27: =$L27 * 0.3 -> 2.4 | O27: =L27*$L$6 -> 6.4 | P27: =$L27 * 0.7 -> 5.6 | Q27: =SUM($L27:$N27) -> 16
F28: Xoá layout | L28: 4 | M28: =$L28 * 0.7 -> 2.8 | N28: =$L28 * 0.3 -> 1.2 | O28: =L28*$L$6 -> 3.2 | P28: =$L28 * 0.7 -> 2.8 | Q28: =SUM($L28:$N28) -> 8
C29: 4.6 | D29: Quảy lý fonts | F29: Danh sách fonts | L29: 8 | M29: =$L29 * 0.7 -> 5.6 | N29: =$L29 * 0.3 -> 2.4 | O29: =L29*$L$6 -> 6.4 | P29: =$L29 * 0.7 -> 5.6 | Q29: =SUM($L29:$N29) -> 16
F30: Thêm font | L30: 16 | M30: =$L30 * 0.7 -> 11.2 | N30: =$L30 * 0.3 -> 4.8 | O30: =L30*$L$6 -> 12.8 | P30: =$L30 * 0.7 -> 11.2 | Q30: =SUM($L30:$N30) -> 32
F31: Sửa font | L31: 8 | M31: =$L31 * 0.7 -> 5.6 | N31: =$L31 * 0.3 -> 2.4 | O31: =L31*$L$6 -> 6.4 | P31: =$L31 * 0.7 -> 5.6 | Q31: =SUM($L31:$N31) -> 16
F32: Xoá font | L32: 4 | M32: =$L32 * 0.7 -> 2.8 | N32: =$L32 * 0.3 -> 1.2 | O32: =L32*$L$6 -> 3.2 | P32: =$L32 * 0.7 -> 2.8 | Q32: =SUM($L32:$N32) -> 8
C33: 4.7 | D33: Quản lý validation rules | E33: _x0008_ | F33: Danh sách _x0008_validation rules | L33: 8 | M33: =$L33 * 0.7 -> 5.6 | N33: =$L33 * 0.3 -> 2.4 | O33: =L33*$L$6 -> 6.4 | P33: =$L33 * 0.7 -> 5.6 | Q33: =SUM($L33:$N33) -> 16
F34: Thêm validation rule | L34: 32 | M34: =$L34 * 0.7 -> 22.4 | N34: =$L34 * 0.3 -> 9.6 | O34: =L34*$L$6 -> 25.6 | P34: =$L34 * 0.7 -> 22.4 | Q34: =SUM($L34:$N34) -> 64
F35: Sửa validation rule | L35: 8 | M35: =$L35 * 0.7 -> 5.6 | N35: =$L35 * 0.3 -> 2.4 | O35: =L35*$L$6 -> 6.4 | P35: =$L35 * 0.7 -> 5.6 | Q35: =SUM($L35:$N35) -> 16
F36: Xoá validation rule | L36: 4 | M36: =$L36 * 0.7 -> 2.8 | N36: =$L36 * 0.3 -> 1.2 | O36: =L36*$L$6 -> 3.2 | P36: =$L36 * 0.7 -> 2.8 | Q36: =SUM($L36:$N36) -> 8
C37: 4.8 | D37: Áp dụng validation rules vào input form | L37: 32 | M37: =$L37 * 0.7 -> 22.4 | N37: =$L37 * 0.3 -> 9.6 | O37: =L37*$L$6 -> 25.6 | P37: =$L37 * 0.7 -> 22.4 | Q37: =SUM($L37:$N37) -> 64
A38: 4 | B38: 5. Logging | C38: 5.1 | D38: Logging by php code | E38: Log management | F38: Quản lý logs | L38: 12 | M38: =$L38 * 0.7 -> 8.4 | N38: =$L38 * 0.3 -> 3.6 | O38: =L38*$L$6 -> 9.6 | P38: =$L38 * 0.7 -> 8.4 | Q38: =SUM($L38:$N38) -> 24 | R38: =sum(Q38:Q40) -> 136
F39: Chart | L39: 32 | M39: =$L39 * 0.7 -> 22.4 | N39: =$L39 * 0.3 -> 9.6 | O39: =L39*$L$6 -> 25.6 | P39: =$L39 * 0.7 -> 22.4 | Q39: =SUM($L39:$N39) -> 64
E40: Log user actions | L40: 24 | M40: =$L40 * 0.7 -> 16.8 | N40: =$L40 * 0.3 -> 7.2 | O40: =L40*$L$6 -> 19.2 | P40: =$L40 * 0.7 -> 16.8 | Q40: =SUM($L40:$N40) -> 48
C41: 5.2 | D41: Logging by google analytics | E41: Update log script | L41: 4 | M41: =$L41 * 0.7 -> 2.8 | N41: =$L41 * 0.3 -> 1.2 | O41: =L41*$L$6 -> 3.2 | P41: =$L41 * 0.7 -> 2.8 | Q41: =SUM($L41:$N41) -> 8
...

Sheet Raw of 2019 Only B2C Web開発(Back
B1: _x0008_Project NewYear Card | R1: =countif(R12:R923,"◉") -> 79
B2: Team : サーバ | I2: Start | K2: =MIN(I14:I88) -> 0
B3: Last update | I3: End | K3: =MAX(J14:J88) -> 0
B4: Updated by | I4: Fix Bug | K4: 0.3
B5: Total Develop hour | C5: =SUM(P14:P289) -> 2648 | E5: =C5/160 -> 16.55 | I5: Unit Test | K5: 0.7
B6: Total test hour | C6: =SUM(O14:O289) -> 926.8 | E6: =C6/160 -> 5.7925 | I6: API Docs | K6: 0
B7: 注意:
I9: Intergration Test | K9: 0.7
K10: must fill | L10: (auto) | M10: (auto) | N10: (auto) | P10: (auto)
A11: ＃ | B11: Category | C11: Task | D11: 機能 | E11: Sub-task | F11: 要件概要 | G11: Remark | I11: =I2 -> Start | J11: =I3 -> End | K11: Code | L11: UT | M11: Fix bug | N11: API doc | O11: IT | P11: Total Develop | Q11: Role | R11: Implement or not
B12: WEB
A13: 84 | B13: 編集 | C13: - Tính năng check đồng ý với nội dung edit | D13: ・編集内容の同意チェック機能 | E13: Preview ảnh sản phẩm & đồng ý in bằng checkbox | F13: 仕上がりイメージプレビューで印刷をチェックボックスにて同意 | K13: 16 | L13: =IF(K13>0,K13*$K$5,"") -> 11.2 | M13: =IF(K13>0,K13*$K$4,"") -> 4.8 | O13: =IF(L13>0,K13*$K$9,"") -> 11.2 | P13: =IF(SUM(K13:M13)>0,SUM(K13:M13),"") -> 32 | R13: =vlookup(A13,'機能要件'!$B$3:$K$1000,10,0) -> #REF!
A14: 89 | B14: 編集 | C14: Tính năng tìm kiếm ngoài những chữ Hán thông dụng | D14: 常用漢字外の検索機能 | G14: Xem lại các chữ thường dùng (tần suất/ số lượng chữ hiển thị) ① Tự động show ra các chữ gần giống chữ hán thông dụng đã nhập (AI) ② Truyền đạt bằng text (bao gồm URL của site text tương ứng) ③ Bảng viết tay ④ Upload ảnh | H14: よくある文字の見直し（頻度・表示文字数） ①入力した常用漢字に近い文字を自動で寄せる（AI） ②文字で伝える（該当文字サイトのURL含む) ③手書きパット ④記載写真のアップロード | K14: 24 | L14: 16.8 | M14: 7.2 | O14: 16.8 | P14: 48 | R14: ◉
A15: 91 | B15: 編集 | C15: Tính năng edit tự do | D15: 自由編集機能 | E15: Bố trí button để chỉ những ai muốn tùy ý chỉnh sửa mới bấm được | F15: 自由編集をしたい方のみ押せるボタンを用意 | G15: Sử dụng như tính năng customize, người dùng có thể thực hiện các thao tác chỉnh sửa như nhập text (có thể nhập text dài), phóng to thu nhỏ, chỉnh vị trí... trên màn hình edit Các mục đã nhập trên màn hình edit thông thường sẽ được phản ánh lên màn hình edit tự do | H15: カスタマイズ機能として編集画面で文字入力（長文対応）・拡大縮小・位置など編集操作ができる 通常編集画面で入力した項目は、自由編集画面に反映される | K15: 80 | L15: 56 | M15: 24 | O15: 56 | P15: 160 | R15: ◉
A16: 92 | B16: 編集 | C16: Tính năng alert trên màn hình edit tự do khi có lỗi edit | D16: 自由編集画面にて、編集不具合時のアラート機能 | G16: Tính năng thông báo bằng callout trong các t/h chẳng hạn như chữ bị đè lên nhau | H16: 文字が重なって配置している場合等、吹き出しでお知らせするなどの機能 | K16: 32 | L16: 22.4 | M16: 9.6 | O16: 22.4 | P16: 64 | R16: ◉
A17: 93 | B17: 編集 | C17: Tính năng Back trên màn hình Edit tự do | D17: 自由編集画面にて、戻る機能 | G17: Khác với mũi tên Back của trình duyệt | H17: ブラウザの戻る矢印以外のもの | K17: 16 | L17: 11.2 | M17: 4.8 | O17: 11.2 | P17: 32 | R17: ◉
A18: 96 | C18: Tính năng hiển thị cách sử dụng màn hình edit | D18: 編集画面の使い方の表示機能 | K18: 8 | L18: 5.6 | M18: 2.4 | O18: 5.6 | P18: 16 | R18: ◉
A19: 98 | B19: 年賀状作成 | E19: Có thể xoay (rotate) | F19: 回転に対応する。 | G19: Edit text, ảnh | H19: 配置された文字、画像の編集 | K19: 24 | L19: 16.8 | M19: 7.2 | O19: 16.8 | P19: 48 | R19: ◉
A20: 99 | B20: 年賀状作成 | E20: Có thể thay đổi màu text | F20: 文字色の変更に対応する。 | K20: 24 | L20: 16.8 | M20: 7.2 | O20: 16.8 | P20: 48 | R20: ◉
A21: 100 | B21: 年賀状作成 | E21: Có thể chèn hình ảnh vào | F21: 画像の配置に対応する。 | K21: 24 | L21: 16.8 | M21: 7.2 | O21: 16.8 | P21: 48 | R21: ◉
A22: 101 | B22: 年賀状作成 | E22: Có thể di chuyển | F22: 移動に対応する。 | G22: Edit text, ảnh | H22: 配置された文字、画像の編集 | K22: 24 | L22: 16.8 | M22: 7.2 | O22: 16.8 | P22: 48 | R22: ◉
A23: 102 | B23: 編集 | C23: Tính năng tự động phản ánh mục đã nhập | D23: 入力した項目の自動反映機能 | G23: Từng text nhập vào sẽ tự động hiển thị mà không cần bấm vào button "プレビューを更新/Update preview" | H23: 「プレビューを更新」等を押さなくても、入力文字単位で表示される | K23: 24 | L23: 16.8 | M23: 7.2 | O23: 16.8 | P23: 48 | R23: ◉
A24: 103 | B24: 編集 | C24: Tính năng paint kết quả đã chọn | D24: 選択結果のペイント機能 | G24: Làm kiểu paint thay vì radio button để người dùng dễ dàng nhận biết đâu là cái mình đang chọn | H24: 選択しているものを理解しやすいように、ラジオボタンではなくペイント式にする | K24: 24 | L24: 16.8 | M24: 7.2 | O24: 16.8 | P24: 48 | R24: ◉
A25: 106 | B25: 編集 | C25: Tính năng Edit trên 1 trang | D25: 1ページでの編集機能 | E25: Chọn cá nhân hoặc tổ chức | F25: 個人用・法人用の選択 | K25: 4 | L25: 2.8 | M25: 1.2 | O25: 2.8 | P25: 8 | R25: ◉
A26: 107 | B26: 編集 | E26: Nhập item in ấn | F26: 印刷項目の入力 | G26: Dành cho cá nhân Mã bưu điện/ địa chỉ 1 / địa chỉ 2 / địa chỉ 3 / địa chỉ 4 Tên người gửi / list tên 1 / list tên 2 / list tên 3 / list tên 4 / list tên 5 / list tên 6 / list tên 7 / list tên 8 Với tên, có các mục nhập như: Họ cũ/ tuổi / furigana / bí danh... Nhập số bao gồm SĐT/ Số FAX Email / URL | H26: 個人用 郵便番号・住所１・住所2・住所3・住所４ 差出人名・連名1・連名2・連名3・連名4・連名5・連名6・連名7・連名8 名に対する 旧姓・年齢・ふりがな・雅号等の入力項目 電話・ＦＡＸ番号 表記を含めた 番号入力 Eメール・URL | K26: 24 | L26: 16.8 | M26: 7.2 | O26: 16.8 | P26: 48 | R26: ◉
A27: 109 | B27: 編集 | E27: Các item in ấn khác | F27: その他印刷項目 | G27: Hiển thị Font chữ, đoạn chào hỏi / chỉnh sửa đoạn text mẫu / input free text Upload logo data | H27: 書体・挨拶文の表示・定型文章の修正・フリー文章の入力項目 ロゴデータのアップロード | K27: 16 | L27: 11.2 | M27: 4.8 | O27: 11.2 | P27: 32 | R27: ◉
A28: 110 | B28: 編集 | E28: Hiển thị preview | F28: プレビューの表示 | G28: Phóng to preview Hiển thị cả nhiều design khác | H28: プレビューの拡大 他の複数デザインでも表示 | K28: 16 | L28: 11.2 | M28: 4.8 | O28: 11.2 | P28: 32 | R28: ◉
A29: 113 | B29: 編集 | E29: Tính năng cho viết text ghi chú | F29: 添え書き文対応機能 | K29: 4 | L29: 2.8 | M29: 1.2 | O29: 2.8 | P29: 8 | R29: ◉
A30: 115 | B30: 年賀状作成 | C30: Tính năng chọn text | D30: 文章選択機能 | E30: Người dùng có thể chọn đoạn text mẫu | F30: 定型文の選択に対応する。 | K30: 8 | L30: 5.6 | M30: 2.4 | O30: 5.6 | P30: 16 | R30: ◉
A31: 116 | B31: 年賀状作成 | C31: Tính năng nhập mã bưu điện, địa chỉ | D31: 郵便番号住所入力機能 | E31: Người dùng có thể nhập địa chỉ bằng từ điển zipcode | F31: 郵便番号辞書による住所入力に対応する。 | G31: - Áp dụng cho tất cả các vị trí nhập địa chỉ trong hệ thống này - Sau khi nhập 7 số zipcode (không có dấu hyphen), tự động hiển thị địa chỉ mà không cần bấm button Submit | H31: ・本システム内での住所入力箇所全てで対応する。 ・郵便番号7桁（ハイフンなし）入力後、確定ボタンを押下しなくても、住所表示に対応する。 | K31: 16 | L31: 11.2 | M31: 4.8 | O31: 11.2 | P31: 32 | R31: ◉
A32: 117 | B32: 年賀状作成 | C32: Tính năng chọn layout | D32: レイアウト選択機能 | E32: Người dùng có thể chọn layout mong muốn | F32: 希望のレイアウトを選択できる | K32: 16 | L32: 11.2 | M32: 4.8 | O32: 11.2 | P32: 32 | R32: ◉
A33: 118 | B33: 年賀状作成 | C33: Tính năng tự động thiết lập input mode | D33: 入力モード自動設定機能 | E33: Tự động thiết lập input mode phù hợp với các loại khung input | F33: 自動で、各種入力枠に適した入力モードに対応する。 | G33: Áp dụng cho tất cả các khung input trong hệ thống này Zipcode, mail address... | H33: 本システム内での各種入力枠全てで対応する。 郵便番号、メールアドレス等 | K33: 16 | L33: 11.2 | M33: 4.8 | O33: 11.2 | P33: 32 | R33: ◉
A34: 119 | B34: 年賀状作成 | C34: Tính năng check input | D34: 入力チェック機能 | E34: Có thể hiển thị lỗi cho nội dung input | F34: 入力内容エラー表示に対応する。 | G34: Hiển thị nội dung lỗi ở gần khung input | H34: 入力枠付近にエラー内容を表示する。 | K34: 16 | L34: 11.2 | M34: 4.8 | O34: 11.2 | P34: 32 | R34: ◉
A35: 120 | B35: 年賀状作成 | C35: Tính năng tự động sắp xếp theo layout | D35: レイアウト自動組版機能 | E35: Tự động sắp xếp phần thông tin người gửi & người nhận theo layout | F35: 差出人及び宛名の自動組版に対応する。 | G35: Tự động sắp layout theo tên công ty, địa chỉ | H35: 会社名、住所を元にレイアウト自動組版に対応する。 | K35: 32 | L35: 22.4 | M35: 9.6 | O35: 22.4 | P35: 64 | R35: ◉
A36: 121 | B36: 年賀状作成 | C36: Tính năng Edit layout | D36: レイアウト編集機能 | E36: Có thể phóng to, thu nhỏ | F36: 拡大縮小に対応する。 | G36: Edit text, ảnh | H36: 配置された文字、画像の編集 | K36: 16 | L36: 11.2 | M36: 4.8 | O36: 11.2 | P36: 32 | R36: ◉
A37: 122 | B37: 年賀状作成 | C37: Tính năng preview bản hoàn thiện (image) | D37: 仕上がりイメージプレビュー機能 | E37: Hiển thị kết quả (image) | F37: 仕上がり表示に対応する。 | G37: - Người dùng có thể biết được kích cỡ sau khi hoàn thiện - Người dùng cũng biết được kích cỡ hoàn thiện thực tế trong trường hợp phải cắt 4 bên của bưu thiếp sau khi dán vào nhau | H37: ・仕上がりサイズが分かるようにする。 ・貼り合わせ後、はがき四辺を断裁するケースの実仕上がりサイズも分かる。 | K37: 40 | L37: 28 | M37: 12 | O37: 28 | P37: 80 | R37: ◉
A38: 124 | C38: Tính năng đổi thành sample text (người dùng có thể tự mình chỉnh sửa text) | D38: 見本文章に変更する機能（自分自身で文章を修正できるようにする） | G38: Tính năng đổi thành sample text (người dùng có thể tự mình chỉnh sửa text) | H38: 見本文章に変更する機能（自分自身で文章を修正できるようにする） | K38: 8 | L38: 5.6 | M38: 2.4 | O38: 5.6 | P38: 16 | R38: ◉
A39: 125 | B39: 写真 | C39: Tính năng cho phép upload ảnh | D39: 写真のアップロードができる機能 | K39: 16 | L39: 11.2 | M39: 4.8 | O39: 11.2 | P39: 32 | R39: ◉
A40: 127 | B40: 写真 | C40: Tính năng không cho chọn button Next cho đến khi upload ảnh | D40: 写真をアップロードするまで、進むボタンが選択できない機能 | K40: 8 | L40: 5.6 | M40: 2.4 | O40: 5.6 | P40: 16 | R40: ◉
A41: 128 | B41: 写真 | C41: Tính năng Edit ảnh | D41: 写真の編集機能 | G41: Người dùng có thể chỉnh vị trí ảnh, phóng to, thu nhỏ, chỉnh độ sáng | H41: 写真の位置、拡大縮小、明るさの編集ができる | K41: 32 | L41: 22.4 | M41: 9.6 | O41: 22.4 | P41: 64 | R41: ◉
...

Sheet Copy of (SP) MH nhập thông tin 
B1: 1. Hiển thị mặc định | X1: 2. Khi input | AT1: 3. Hiển thị error/help | BN1: 4. Hiển thị mục "Tổ chức" | CJ1: 5. Hiển thị chuỗi tên | DF1: 6. Hiển thị họ cũ, furigana | EB1: 7. Màn hình edit
B3: 1-1. Ngoại trừ "住所/Địa chỉ", "建物名/Tên tòa nhà" ra, | X3: 2-1. Khi bấm vào button "会員情報で入力/Input bằng | AT3: 3-1. Hiển thị lỗi inline | BN3: 4-1. Khi bấm vào button "+法人項目追加/thêm trường | CJ3: 5-1. Mỗi lần bấm vào button "+連名を追加/thêm chuỗi | DF3: 6-1. Bấm vào button "+旧姓、ふりがなを追加/ | EB3: 7-1. Thay đổi màu text
C4: tất cả đều là trường required | Y4: thông tin thành viên" thì sẽ phản ánh thông tin thành viên | BO4: tổ chức" thì không bắt buộc phải nhập họ tên nữa | CK4: tên" là thêm 1 tên | DG4: Thêm họ cũ, furigana" để thêm trường
B5: 1-2. Hỗ trợ input bằng placeholder | X5: 2-2. Số điện thoại là số halfsize, dù nhập fullsize thì | AT5: 3-2. Không sử dụng realtime alert khi đang input dở | CJ5: 5-2. Bấm butotn "x" để xóa chuỗi tên vừa thêm | EB5: 7-2. Thay đổi cỡ chữ
Y6: cũng tự động chuyển thành halfsize
X7: 2-3. Mã bưu điện là số halfsize, dù nhập fullsize thì cũng | AT7: 3-3. Help text hiển thị theo minh họa dưới đây | EB7: 7-3. Thay đổi font
Y8: tự động chuyển thành halfsize
X9: 2-4. Khi nhập "Mã bưu điện", tự động nhập địa chỉ realtime | EB9: 7-4. Thay đổi căn lề
X10: 2-5. Khi nhập "Email", tự động check tên domain | BN10: Header (chung với phía EC) | EB10: 7-5. Thay đổi text mẫu
EB11: 7-6 . Bố trí ảnh
BN12: ＜ 戻る/Back | BR12: 差出人情報入力/ Nhập thông tin người gửi | CB12: 次へ/Next ＞ | EB12: 7-7. Phóng to, thu nhỏ (vùng text, ảnh)
EB13: 7-8. Di chuyển (vùng text, ảnh)
EB14: 7-9. Xoay (vùng text, ảnh)
BQ15: 会員登録情報で入力/Nhập bằng thông tin đăng ký thành viên | EB15: 7-10. Phóng to, thu nhỏ preview (100%, 125%, 150%, 200%)
EB16: 7-11. Undo (tối đa có thể back lại 10 lần)
EB17: 7-12. Thay đổi design
BQ18: + 法人項目を追加/Thêm trường Tổ chức | EB18: 7-13. Thêm khung nhập free text (tối đa 3 khung)
AC19: Việc nhập chữ ngoại lai thì sao? | EB19: 7-14.Tính năng stamp (nếu không tạo được stamp kiểu hiện đại thì không cần)
EB20: 7-15. Màn hình edit - help page
BP21: 会社名/Tên công ty | BS21: 必須/Required | EB21: 7-16. Hiển thị khung đỏ phạm vi cutting (nếu có thể hiển thị kích thước hoàn thiện cho tất cả design thì không cần)
BP22: 株式会社マイプリント/Công ty cổ phần MYPRINT | EB22: 7-17. Nhập biểu tượng cảm xúc, emoji
BP25: 部署名/Tên phòng ban
B26: Header (chung với phía EC) | X26: Header (chung với phía EC) | AS26: Header (chung với phía EC) | CJ26: Header (chung với phía EC) | DF26: Header (chung với phía EC) | EB26: Header (chung với phía EC)
B28: ＜ 戻る/ Back | F28: 差出人情報入力/ Nhập thông tin người gửi | P28: 次へ /Next ＞ | X28: ＜ 戻る/ Back | AB28: 差出人情報入力/ Nhập thông tin người gửi | AL28: 次へ/ Next ＞ | AS28: ＜ 戻る/Back | AW28: 差出人情報入力 /Nhập thông tin người gửi | BG28: 次へ/Next ＞ | CJ28: ＜ 戻る/Back | CN28: 差出人情報入力/ Nhập thông tin người gửi | CX28: 次へ/Next ＞ | DF28: ＜ 戻る/Back | DJ28: 差出人情報入力/ Nhập thông tin người gửi | DT28: 次へ/Next ＞ | EB28: × | EF28: デザイン編集画面/ Màn hình chỉnh sửa design | EP28: 保存/Save
BP29: 役職/Chức vụ
E31: 会員登録情報で入力/ Nhập bằng thông tin đăng ký thành viên | AA31: 会員登録情報で入力/ Nhập bằng thông tin đăng ký thành viên | AV31: 会員登録情報で入力/Nhập bằng thông tin đăng ký thành viên | CM31: 会員登録情報で入力/Nhập bằng thông tin đăng ký thành viên | DI31: 会員登録情報で入力/Nhập bằng thông tin đăng ký thành viên
BP33: URL
E34: + 法人項目を追加/ Thêm trường Tổ chức | AA34: + 法人項目を追加/ Thêm trường Tổ chức | AV34: + 法人項目を追加/Thêm trường Tổ chức | CM34: + 法人項目を追加/Thêm trường Tổ chức | DI34: + 法人項目を追加/Thêm trường Tổ chức
D37: 姓/Họ | E37: 必須/ Required | K37: 名/Tên | L37: 必須/ Required | Z37: 姓/Họ | AA37: 必須/Required | AG37: 名/Tên | AH37: 必須/Required | AU37: 姓/Họ | AV37: 必須/Required | BB37: 名/Tên | BC37: 必須/Required | BP37: 姓/Họ | BW37: 名/Tên | CL37: 姓/Họ | CM37: 必須/Required | CS37: 名/Tên | CT37: 必須/Required | DH37: 姓/Họ | DI37: 必須/Required | DO37: 名/Tên | DP37: 必須/Required
E41: + 旧姓、ふりがなを追加/ Thêm họ cũ, furigana | AA41: + 旧姓、ふりがなを追加/Thêm họ cũ, furigana | AV41: + 旧姓、ふりがなを追加/Thêm họ cũ, furigana | CM41: + 旧姓、ふりがなを追加/Thêm họ cũ, furigana | DH41: 姓（ふりがな）/Họ (furigana) | DO41: 名（ふりがな）/Tên (furigana)
E44: + 連名を追加/Thêm chuỗi tên | AA44: + 連名を追加/Thêm chuỗi tên | AV44: + 連名を追加/Thêm chuỗi tên | BQ44: + 連名を追加/Thêm chuỗi tên | CM44: + 連名を追加/Thêm chuỗi tên
DO45: 旧姓/Họ cũ
D47: 郵便番号/Mã bưu điện | H47: 必須/ Required | Z47: 郵便番号/Mã bưu điện | AD47: 必須/Required | AU47: 郵便番号/Mã bưu điện | AY47: 必須/Required | BP47: 郵便番号/Mã bưu điện | BT47: 必須/Required | CL47: 別姓の場合のみ姓を入力してください/Chỉ nhập Họ trong trường hợp là Họ khác
D48: 数字7桁/7 ký tự số | Z48: 1000005 | AU48: 1000005 | BP48: 1000005 | CL48: １人目/Người thứ 1
CL49: 姓/Họ | CS49: 名/Tên | DI49: + 旧姓、ふりがなを追加/Thêm họ cũ, furigana
D51: 住所/ Địa chỉ | F51: 必須/ Required | Z51: 住所/Địa chỉ | AB51: 必須/Required | AU51: 住所/Địa chỉ | AW51: 必須/Required | BP51: 住所/Địa chỉ | BR51: 必須/Required
D52: 都道府県/Prefectures | Z52: 東京都/Tokyo | AU52: 東京都/Tokyo | BP52: 東京都/Tokyo | DI52: + 連名を追加/Thêm chuỗi tên
CL53: 2人目/Người thứ 2
CL54: 姓/Họ | CS54: 名/Tên
D55: 市区町村郡/City | Z55: 千代田区丸の内/Marunouchi, quận Chiyoda | BP55: 千代田区丸の内/Marunouchi, quận Chiyoda | DH55: 別姓の場合のみ姓を入力してください/Chỉ nhập Họ trong trường hợp là Họ khác
...

Sheet Copy of (PC) MH nhập thông tin 
B3: Header (chung với phía EC)
B5: 差出人情報入力/Nhập thông tin người gửi
AK7: ▲
W8: 会員登録情報で入力/ Nhập bằng thông tin đăng ký thành viên
W11: + 法人項目を追加/ Thêm trường Tổ chức
V14: 姓/Họ | W14: 必須/Required | AC14: 名/Tên | AD14: 必須/Required
W18: + 連名を追加/Thêm chuỗi tên
V21: 郵便番号/Mã bưu điện | Z21: 必須/Required
V22: 1000005
V25: 住所/Địa chỉ | X25: 必須/Required
V26: 東京都/Tokyo
V29: 千代田区丸の内/Marunouchi, quận Chiyoda
AK31: ▼
V33: プレビューを更新/Update preview
C36: ＜ 戻る/Back | AE36: 次へ/Next ＞
B39: Footer (chung với phía EC)

Sheet General
E1: WBS SCHEDULE | R1: No: BM-2-901-37
R2: Version: 1.1
R3: Issue Date: 05/04/2021
A4: SUN ASTERISK VIETNAM CO., LTD | R4: ISO/IEC 27001:2013&ISO 9001:2015
B6: General
B10: Task status | G10: Member list | K10: Redmine | O10: Role | T10: _x0008_Holiday | W10: Design status
B12: # | C12: Status | D12: Statitics | E12: Description | G12: # | H12: Name | I12: Effort | K12: # | L12: Redmine | M12: Atom | O12: # | P12: Title | Q12: Effort | R12: Description | T12: # | U12: Holiday | V12: Description | W12: # | X12: Title
B13: 1 | C13: New | D13: =COUNTIF(INDIRECT("Planning Dev!"&"N10:N61"),C13) -> 0 | G13: 1 | H13: DN | K13: 1 | O13: 1 | T13: 1
B14: 2 | C14: In Progress | D14: =COUNTIF(INDIRECT("Planning Dev!"&"N10:N61"),C14) -> 0 | G14: 2 | H14: HN | O14: 2 | T14: 2
B15: 3 | C15: Done | D15: =COUNTIF(INDIRECT("Planning Dev!"&"N10:N61"),C15) -> 0 | G15: 3 | H15: HCM | O15: 3 | T15: 3
B16: 4 | C16: Pending | D16: =COUNTIF(INDIRECT("Planning Dev!"&"N10:N61"),C16) -> 0 | G16: 4 | O16: 4 | T16: 4
B17: 5 | C17: Resolved | D17: =COUNTIF(INDIRECT("Planning Dev!"&"N10:N61"),C17) -> 0 | G17: 5 | O17: 5
B18: 6 | D18: =COUNTIF(INDIRECT("Planning Dev!"&"N10:N61"),C18) -> 0 | G18: 6 | O18: 6
B19: 7 | D19: =COUNTIF(INDIRECT("Planning Dev!"&"N10:N61"),C19) -> 0 | G19: 7 | O19: 7
B20: 8 | D20: =COUNTIF(INDIRECT("Planning Dev!"&"N10:N61"),C20) -> 0 | G20: 8 | O20: 8
B21: 9 | D21: =COUNTIF(INDIRECT("Planning Dev!"&"N10:N61"),C21) -> 0 | G21: 9 | O21: 9
B22: 10 | D22: =COUNTIF(INDIRECT("Planning Dev!"&"N10:N61"),C22) -> 0 | G22: 10 | O22: 10
B23: 11 | D23: =COUNTIF(INDIRECT("Planning Dev!"&"N10:N61"),C23) -> 0 | G23: 11 | O23: 11
G24: 12
G25: 13
G26: 14
G27: 15
G28: 16
G29: 17
G30: 18
G31: 19
G32: 20
G33: 21
G34: 22
G35: 23
... G44: 32
B48: Sprint list
B49: # | C49: Sprint | D49: Start Date | E49: End Date | F49: Effort | G49: Status
B50: 1
B51: 2
B52: 3
B53: 4
B54: 5
B55: 6
B56: 7
...
